Workbook

Sheet Home
C2: Climate Risk and Vulnerability Assessment Tool: Communities and Infrastructure Projects
C4: Creating Climate Resilient Communities and Infrastructure
D7: Project Name: | E7: Enter here | Q7: Project Lead: | R7: Enter here
D8: Project Location: | E8: Enter here | Q8: Name of Assessor:
D9: Project Code: | E9: Enter here | Q9: No. of Beneficiaries: | R9: Enter here
H34: This diagram shows that hazards lead to exposure, which, when combined with sensitivity, determines the vulnerability of a system. Adaptive capacity acts as a protective factor, influencing vulnerability and the overall level of risk

Sheet Instructions
B7: AIM:
B8: The objective of the tool is to evaluate the climate risk and vulnerability of communities. The tool assesses how current climate hazards (such as temperature, Precipitation, droughts and floods) impact the broader community. Based on the prevailing risk and vulnerability, the tool explores potential interventions that will improve climate resilience. This tool is focused on assessing the current risk and vulnerability levels for communities. In addition to the assets lens, gender, green infrastructure and the socio-ecological benefits that it provides, is also explored. The tool also uses the updated Intergovernmental Panel on Climate Change (IPCC) methodology, as discussed in detail in the section below.
B12: FRAMEWORK:
B13: In line with the Fifth Assessment Report (AR5) by the Intergovernmental Panel on Climate Change (IPCC), the tool includes the following aspects:
B14: • | C14: Hazard: the occurrence or potential occurrence of a climate-related event (such as rainfall or temperature) and/or a natural or human-induced impact (such as flood or droughts), that has or may cause harm, injury, damage or the loss of a system, species or asset. Exposure: the degree to which a system, species or asset is ‘exposed’, due to its location or presence in a place or setting that is or could be impacted by a climate-related hazard. Sensitivity: the susceptibility of a system, species or asset to climate-related impacts, or the degree to which system, species or asset is or can be directly or indirectly impacted by a climate-related hazard. Adaptive Capacity: the proven or perceived ability of a system, species or asset to respond to existing or potential climate-related impacts and adjust to damage, so as to cope with consequences and take advantage of opportunities. Vulnerability: the inclination of a system, species or asset to be impacted by climate-related hazards, encompassing its sensitivity and its ability to cope or adapt to climate-related impacts. Risk: refers to the potential for (and the likelihood of) adverse climate-related impacts on a system, species or asset, resulting from the interaction of vulnerability, exposure, and hazard.
B16: •
B17: •
B19: •
B21: •
B22: •
B26: The tool relies on several questions that assess hazard, exposure, sensitivity and adaptive capacity. As shown above, the responses to these categories, will enable an assessment of risk and vulnerability will be assessed. Based on the prevalent risk and vulnerability, the tool explores potential response measures that will improve climate resilience by either decreasing sensitivity or increasing adaptive capacity. In addition, whenever possible, measures to decrease exposure will be explored.
B31: HOW TO USE THIS TOOL:
B32: The grey rectangular boxes enable the user to explore through the tool. The boxes will either lead the user to a different place in the same rectanglar tab, or to a new rectanglar tab. Therefore, please click on any grey box to navigate and to complete the tool. The user is required to answer the questions provided under the "Hazard" rectanglar tab, "Exposure" rectanglar tab, "Sensitivity" rectanglar tab, as well as the "Adaptive Capacity" rectanglar tab. The user can access these rectanglar tabs by clicking on the "Hazard", "Exposure", "Sensitivity", and the "Adaptive Capacity" boxes. In these rectanglar tabs, questions are provided for "Hazard", "Exposure", "Sensitivity", and "Adaptive Capacity". The "Output" rectanglar tab leads the user to the "RVAT" rectanglar tab, where the answer to each question are analysed using the framework, assessed and graphed. Specifically, the tool provides outputs for "Vulnerability" and "Risk". Based on the “Risk” output, which incorporates “vulnerability”, the tool provides response options. These can be accessed by clicking on the "Responses" rectanglar tab at the top of your screen, or by clicking the "Responses" rectanglar tab.
B46: USEFUL RESOURCES:
B47: Below is a source to help answer some of the questions:
B48: 1 | C48: WRI - Aqueduct Water Risk Atlas. Link: | L48: http://www.wri.org/resources/maps/aqueduct-water-risk-atlas
B51: ABBREVIATIONS USED
B52: 1. LUI=Land Use Inadiquacy 2. WFI/WFDU=Water for irrigation/Water for domestic use 3. ATF/I=Access to finance/insurance 4. SLUP & C=Safety land use planning and control 5. SWM=Solid waste management 6. LWM=Liquid waste management 6. ATHS=Access to health services 7. ATHE=Access to healthy environment 8. SWD=Storm water drainage 9. PWT=Portable water treatment 10. R & T=Road and transport 11. LC &P=Land cover and permeability 12. NV=Natural Vegetation 13. NWB=Natural water bodies 14. EF=Ecosystem functionality 15. EWS=Early warning systems 16. A & I=Awareness and information 17. EC=Engagement with county community 18. R/RP= Resource/resources planning 19. HFO=Health facilities operations 20. DP=Disaster preparedness 21. DR=Disaster responce 22. PFR=Public finance/recovery grands 23. PFM=Public finanace/maintenance NB: All abbreviations have their full meaning in the comments section.
B55: NOTE: 1. This tool has been developed using MS Excel 2019, and therefore, any verions before 2019 may have limited funcitonality. 2. As this tool uses several macros to enable functionality, the user is required to click on the "Enable macros" button when prompted. 3. To ensure the usability of the tool is maintained, please avoid deleting any rows and columns. As the functionality of the tool is maximised with coding, any modifications of the spreadsheets will render it useless. 4. The tool has default data that depics an ideal informal settlement, amend where applicable only.
U66: Developed for KISIP by:

Sheet Hazard
F7: NOTE: ONCE YOU CLICK THIS BUTTON YOU CANNOT UNDO YOUR ACTIONS
B8: CURRENT HAZARDS | J8: No Selection Done!
B10: Hazard | E10: Question | F10: Comments/Description | G10: Answer? | H10: Add Note On Each Answer | I10: Rating? | J10: List 1 | K10: yes/no is bad
A11: 1 | B11: 1 | C11: Temperature | D11: App or Freq | E11: Are extreme temperatures frequentlly experienced in the settlement? | F11: During the year (across seasons), is temperature higher/lower than usual? | G11: Yes, lower than usual | H11: =IF(OR(G11=$J$11,G11=$J$12,G11=$J$13),$J$9,$J$8) | I11: =IF(G11=$J$11,$K$11,IF(G11=$J$12,$K$12,$K$13)) -> 3 | J11: Yes, higher than usual | K11: 3
A12: =A11+1 -> 2 | D12: Intensity | E12: Are the tempereture intensities increasing? | F12: Over multiple years (i.e. trend), is temperature higher/lower than usual? | G12: No, not really | H12: =IF(OR(G12=$J$11,G12=$J$12,G12=$J$13),$J$9,$J$8) | I12: =IF(G12=$J$11,$K$11,IF(G12=$J$12,$K$12,$K$13)) -> 1 | J12: No, not really | K12: 1
A13: =A12+1 -> 3 | D13: Impact | E13: Are there effects on community members being attributed to extreme temperature? | F13: How often do you experience heat-related effects e.g. heat-related stress, heat srokes, effects on elderly? | G13: No | H13: =IF(OR(G13=$J$16,G13=$J$17,G13=$J$18),$J$9,$J$8) | I13: =IF(G13=$J$16,$K$16,IF(G13=$J$17,$K$17,$K$18)) -> 1 | J13: Yes, lower than usual | K13: 3
I14: =""
A15: =A14+1 -> 1 | B15: 2 | C15: Intense Precipitation | D15: App or Freq | E15: Are heavy rainfall events prevalent in this settlement? | F15: During the year (across seasons), is rainfall higher/lower than usual? | G15: No, not really | H15: =IF(OR(G15=$J$11,G15=$J$12,G15=$J$13),$J$9,$J$8) | I15: =IF(G15=$J$11,$K$11,IF(G15=$J$12,$K$12,$K$13)) -> 1 | J15: List 2 | K15: yes is bad
A16: =A15+1 -> 2 | D16: Intensity | E16: Are rainfall intensities and/or durations increasing? | F16: Over multiple years (i.e. trend), is rainfall higher/lower than usual? | G16: No, not really | H16: =IF(OR(G16=$J$11,G16=$J$12,G16=$J$13),$J$9,$J$8) | I16: =IF(G16=$J$11,$K$11,IF(G16=$J$12,$K$12,$K$13)) -> 1 | J16: Yes | K16: 3
A17: =A16+1 -> 3 | D17: Impact | E17: Are there significant effects on the community being attributed to extreme rainfalls? | F17: Are there rainfall effects, example, destruction of crops, houses and normal daily activities? | G17: No | H17: =IF(OR(G17=$J$16,G17=$J$17,G17=$J$18),$J$9,$J$8) | I17: =IF(G17=$J$16,$K$16,IF(G17=$J$17,$K$17,$K$18)) -> 1 | J17: Sometimes | K17: 2
J18: No | K18: 1
A19: =A18+1 -> 1 | B19: 3 | C19: Droughts | D19: App or Freq | E19: Are droughts frequently experienced in the area? | F19: Do you often experience droughts? | G19: No | H19: =IF(OR(G19=$J$31,G19=$J$32,G19=$J$33),$J$9,$J$8) | I19: =IF(G19=$J$16,$K$16,IF(G19=$J$17,$K$17,$K$18)) -> 1
A20: =A19+1 -> 2 | D20: Timing | E20: If droughts do occur, do they occur at the same time of the year? | F20: Is the timing of droughts consistent? | G20: Yes | H20: =IF(OR(G20=$J$31,G20=$J$32,G20=$J$33),$J$9,$J$8) | I20: =IF(G20=$J$31,$K$31,IF(G20=$J$32,$K$32,$K$33)) -> 1 | J20: List 3 | K20: yes is bad
A21: =A20+1 -> 3 | D21: Intensity | E21: If droughts do occur, is the extent and intensity of the drought changing? | F21: Are droughts getting worse or better? | G21: No change | H21: =IF(OR(G21=$J$26,G21=$J$27,G21=$J$28),$J$9,$J$8) | I21: =IF(G21=$J$26,$K$26,IF(G21=$J$27,$K$27,$K$28)) -> 1 | J21: Often | K21: 3
A22: =A21+1 -> 4 | D22: Impact | E22: Are there significant effects on the community being attributed to droughts? | F22: Is the population affected by droughts, example daily activities, livihood? | G22: No | H22: =IF(OR(G22=$J$31,G22=$J$32,G22=$J$33),$J$9,$J$8) | I22: =IF(G22=$J$16,$K$16,IF(G22=$J$17,$K$17,$K$18)) -> 1 | J22: Sometimes | K22: 2
J23: Not applicable | K23: 1
A24: =A23+1 -> 1 | B24: 4 | C24: Flooding | D24: App or Freq | E24: Are seasonal floods prevalent in in the settlement? | F24: Do you often experience rain floods | G24: No | H24: =IF(OR(G24=$J$16,G24=$J$17,G24=$J$18),$J$9,$J$8) | I24: =IF(G24=$J$16,$K$16,IF(G24=$J$17,$K$17,$K$18)) -> 1
A25: =A24+1 -> 2 | D25: Timing | E25: If seasonal floods do occur, do they occur at the same time of the year? | F25: Is the timing of rain floods consistent? | G25: Yes | H25: =IF(OR(G25=$J$31,G25=$J$32,G25=$J$33),$J$9,$J$8) | I25: =IF(G25=$J$31,$K$31,IF(G25=$J$32,$K$32,$K$33)) -> 1 | J25: List 4 | K25: yes is bad
A26: =A25+1 -> 3 | D26: Intensity | E26: If floods do occur, is the intensity icreasing? | F26: Are rain floods getting worse (more impact/intensity) or better (less impact/intensity)? | G26: Yes, but less than 4 days | H26: =IF(OR(G26=$J$53,G26=$J$54,G26=$J$55),$J$9,$J$8) | I26: =IF(G26=$J$53,$K$53,IF(G26=$J$54,$K$54,$K$55)) -> 1 | J26: Yes, but more | K26: 3
A27: =A26+1 -> 4 | D27: Extent | E27: If floods do occur, is the spatial extent increasing ? | F27: Are rain floods getting worse (more impact/intensity) or better (less impact/intensity)? | G27: Less than half | H27: =IF(OR(G27=$J$58,G27=$J$59,G27=$J$60),$J$9,$J$8) | I27: =IF(G27=$J$58,$K$58,IF(G27=$J$59,$K$59,$K$60)) -> 1 | J27: No change | K27: 1
A28: =A27+1 -> 5 | D28: Impact | E28: Are there significant effects on the community being attributed to seasonal floods? | F28: Is the population affected by rain floods? | G28: Not applicable | H28: =IF(OR(G28=$J$21,G28=$J$22,G28=$J$23),$J$9,$J$8) | I28: =IF(G28=$J$21,$K$21,IF(G28=$J$22,$K$22,$K$23)) -> 1 | J28: Yes, but less | K28: 2
A30: =A29+1 -> 1 | B30: 5 | C30: Flash Floods | D30: App or Freq | E30: Are flash floods prevalent in the settlement? | F30: Do you often experience flash floods? | G30: No | H30: =IF(OR(G30=$J$16,G30=$J$17,G30=$J$18),$J$9,$J$8) | I30: =IF(G30=$J$16,$K$16,IF(G30=$J$17,$K$17,$K$18)) -> 1 | J30: List 5 | K30: No is bad
A31: =A30+1 -> 2 | D31: Timing | E31: If flash floods do occur, do they occur at the same time of the year? | F31: Is the timing of flash floods consistent? | G31: No | H31: =IF(OR(G31=$J$31,G31=$J$32,G31=$J$33),$J$9,$J$8) | I31: =IF(G31=$J$16,$K$16,IF(G31=$J$17,$K$17,$K$18)) -> 1 | J31: Yes | K31: 1
A32: =A31+1 -> 3 | D32: Intensity | E32: If flash floods do occur, is the intensity of the flash floods changing? | F32: Are flash floods getting worse (more impact/intensity) or better (less impact/intensity)? | G32: Yes, but less than 4 days | H32: =IF(OR(G32=$J$53,G32=$J$54,G32=$J$55),$J$9,$J$8) | I32: =IF(G32=$J$53,$K$53,IF(G32=$J$54,$K$54,$K$55)) -> 1 | J32: Sometimes | K32: 2
A33: =A32+1 -> 4 | D33: Extent | E33: If flash floods do occur, is the extent of the flash floods changing? | F33: Are flash floods getting worse (more impact/intensity) or better (less impact/intensity)? | G33: Less than half | H33: =IF(OR(G33=$J$58,G33=$J$59,G33=$J$60),$J$9,$J$8) | I33: =IF(G33=$J$58,$K$58,IF(G33=$J$59,$K$59,$K$60)) -> 1 | J33: No | K33: 3
A34: =A33+1 -> 5 | D34: Impact | E34: Are there significant effects on the community being attributed to flash floods? | F34: Is the population affected by flash floods? | G34: Not applicable | H34: =IF(OR(G34=$J$21,G34=$J$22,G34=$J$23),$J$9,$J$8) | I34: =IF(G34=$J$21,$K$21,IF(G34=$J$22,$K$22,$K$23)) -> 1
J35: List 6 | K35: 3 is bad
A36: =A28+1 -> 6 | B36: 6 | C36: Storms & Upper Winds | D36: App or Freq | E36: Are there frequent storm events experienced in the settlement? | F36: During the year (across seasons), is storms/cyclones higher/lower than usual? | G36: No, not really | H36: =IF(OR(G36=$J$11,G36=$J$12,G36=$J$13),$J$9,$J$8) | I36: =IF(G36=$J$11,$K$11,IF(G36=$J$12,$K$12,$K$13)) -> 1 | J36: Combination of all the three | K36: 3
A37: =A36+1 -> 7 | D37: Intensity | E37: Is there increase in frequency and intensity of storms being noted in the settlement? | F37: Over multiple years (i.e. trend), is storms/cyclones higher/lower than usual? | G37: No, not really | H37: =IF(OR(G37=$J$11,G37=$J$12,G37=$J$13),$J$9,$J$8) | I37: =IF(G37=$J$11,$K$11,IF(G37=$J$12,$K$12,$K$13)) -> 1 | J37: Combination of two | K37: 2
A38: =A37+1 -> 8 | D38: Impact | E38: Are there significant effects on the community being attributed to storms? | F38: Are there storms/cyclones effects, example, destruction of crops, houses and normal daily activities? | G38: No | H38: =IF(OR(G38=$J$16,G38=$J$17,G38=$J$18),$J$9,$J$8) | I38: =IF(G38=$J$16,$K$16,IF(G38=$J$17,$K$17,$K$18)) -> 1 | J38: Only one | K38: 1
A40: =A39+1 -> 1 | B40: 7 | C40: Pollution | D40: App or Freq | E40: Is there pollution experienced in the settlement for land, water or soil? | F40: Is there pollution to land, soil and water or combination of two or all? | G40: Only one | H40: =IF(OR(G40=$J$36,G40=$J$37,G40=$J$38),$J$9,$J$8) | I40: =IF(G40=$J$36,$K$36,IF(G40=$J$37,$K$37,$K$38)) -> 1
A41: =A40+1 -> 2 | D41: Intensity | E41: For the selected above, is there an increase of this pollution being noted in the settlement? | F41: Is the polution aspect increasing or decreasing? | G41: Decrease | H41: =IF(OR(G41=$J$42,G41=$J$43,G41=$J$44),$J$9,$J$8) | I41: =IF(G41=$J$42,$K$42,IF(G41=$J$43,$K$43,$K$44)) -> 1 | J41: List 7 | K41: yes is bad
A42: =A41+1 -> 3 | D42: Impact | E42: Are there significant effects on the community being attributed to this pollution? | F42: Are you impacted by pollution that affects daily activities of the population? | G42: No | H42: =IF(OR(G42=$J$16,G42=$J$17,G42=$J$18),$J$9,$J$8) | I42: =IF(G42=$J$16,$K$16,IF(G42=$J$17,$K$17,$K$18)) -> 1 | J42: Increase | K42: 3
J43: Not applicable | K43: 2
A44: =A43+1 -> 1 | B44: 8 | C44: LUI | D44: Applicability | E44: Is there inadequate use of land in sensitive or risky zones? | F44: Are there unstable soils, high ground water tables, wetland within the settlement? | G44: No | H44: =IF(OR(G44=$J$47,G44=$J$48,G44=$J$49),$J$9,$J$8) | I44: =IF(G44=$J$47,$K$47,IF(G44=$J$48,$K$48,$K$49)) -> 1 | J44: Decrease | K44: 1
A45: =A44+1 -> 2 | D45: Impact | E45: Are significant impacts on people attributed to settling in inadequate or risky areas? | F45: Are adverse imacts directly related to risk zones | G45: No | H45: =IF(OR(G45=$J$16,G45=$J$17,G45=$J$18),$J$9,$J$8) | I45: =IF(G45=$J$16,$K$16,IF(G45=$J$17,$K$17,$K$18)) -> 1
A46: =A45+1 -> 3 | D46: Sensitization | E46: Are people settld in sensitive and risky areas aware of the dangers involved in settling there? | F46: Do the settlers know the dangers and precautions? | G46: No | H46: =IF(OR(G46=$J$31,G46=$J$32,G46=$J$33),$J$9,$J$8) | I46: =IF(G46=$J$16,$K$16,IF(G46=$J$17,$K$17,$K$18)) -> 1 | J46: List 8 | K46: yes is bad
J47: Yes | K47: 3
A48: =A47+1 -> 1 | B48: 9 | C48: Other Factors | D48: Fire/wildfires | E48: How frequent are there fires/wild fires experienced in the area that adversely affect the community? | F48: Is the population impacted by fire in and around your area? | G48: Not applicable | H48: =IF(OR(G48=$J$21,G48=$J$22,G48=$J$23),$J$9,$J$8) | I48: =IF(G48=$J$21,$K$21,IF(G48=$J$22,$K$22,$K$23)) -> 1 | J48: Maybe | K48: 2
A49: =A48+1 -> 2 | D49: Lightning | E49: How frequent is there lightning experienced in the area that adversely affects the community? | F49: Is the population impacted by lightening in and around your area? | G49: Not applicable | H49: =IF(OR(G49=$J$21,G49=$J$22,G49=$J$23),$J$9,$J$8) | I49: =IF(G49=$J$21,$K$21,IF(G49=$J$22,$K$22,$K$23)) -> 1 | J49: No | K49: 1
...

Sheet Exposure
F7: NOTE: ONCE YOU CLICK THIS BUTTON YOU CANNOT UNDO YOUR ACTIONS
B8: CURRENT EXPOSURE | J8: No Selecton Done!
J9: =""
B10: Exposure | E10: Question | F10: Comments/Description | G10: Answer? | H10: Add Note On Each Answer | I10: Rating? | J10: List 1 | K10: yes is bad
A11: 1 | B11: 1 | C11: Livelihoods | D11: Food Security | E11: Do the actual climatic conditions noticeably impact the food production output? | F11: Consider food security at different at different times of the year (i.e. rainy season)? | G11: Not noticed | H11: =IF(OR(G11=$J$11,G11=$J$12,G11=$J$13),$J$9,$J$8) | I11: =IF(G11=$J$11,$K$11,IF(G11=$J$12,$K$12,$K$13)) -> 1 | J11: Severely and often | K11: 3
A12: =A4+1 -> 1 | D12: Grazing/Farm Land | E12: Is grazing land and / or farmland affected by the climate and / or inadequate land use | F12: Consider continued availability of sufficient gras for grazing | G12: Not noticed | H12: =IF(OR(G12=$J$11,G12=$J$12,G12=$J$13),$J$9,$J$8) | I12: =IF(G12=$J$11,$K$11,IF(G12=$J$12,$K$12,$K$13)) -> 1 | J12: Severely and not often | K12: 2
A13: =A5+1 -> 1 | D13: Crops | E13: Are crops adversely impacted by the climate, e.g. by drought, hale, landslides, flooding etc? | F13: Consider protection of crops in view of climate and weather related events | G13: Not noticed | H13: =IF(OR(G13=$J$11,G13=$J$12,G13=$J$13),$J$9,$J$8) | I13: =IF(G13=$J$11,$K$11,IF(G13=$J$12,$K$12,$K$13)) -> 1 | J13: Not noticed | K13: 1
A14: =A3+1 -> 1 | D14: Livestock | E14: Is livestock adversely impacted by the changing climate and severe weather events or by environmental pollution? | F14: Consider capability to maintain health and safety of livestock | G14: Not noticed | H14: =IF(OR(G14=$J$11,G14=$J$12,G14=$J$13),$J$9,$J$8) | I14: =IF(G14=$J$11,$K$11,IF(G14=$J$12,$K$12,$K$13)) -> 1
A15: =A4+1 -> 1 | D15: Fishstock | E15: Is fishstock depleting by the changing climate and severe weather events, ocean warming or environmental pollution? | F15: Consider health and continued availability of fishstock | G15: Not noticed | H15: =IF(OR(G15=$J$11,G15=$J$12,G15=$J$13),$J$9,$J$8) | I15: =IF(G15=$J$11,$K$11,IF(G15=$J$12,$K$12,$K$13)) -> 1
A16: =A5+1 -> 1 | D16: Local commerce | E16: Are floods/extreme temperatures/water shortages noticeably affecting business success? | F16: Consider resilience of SME's | G16: Not noticed | H16: =IF(OR(G16=$J$11,G16=$J$12,G16=$J$13),$J$9,$J$8) | I16: =IF(G16=$J$11,$K$11,IF(G16=$J$12,$K$12,$K$13)) -> 1 | J16: List 2 | K16: yes is bad
A17: =A7+1 -> 1 | D17: Gender | E17: Are men and women equally adversely impacted (if impacted at all) by the challenges resulting from changing climate? | F17: Consider effects of changung climate on gender based activity | G17: Equally affected | H17: =IF(OR(G17=$J$17,G17=$J$18,G17=$J$19),$J$9,$J$8) | I17: =IF(G17=$J$17,$K$17,IF(G17=$J$18,$K$18,$K$19)) -> 1 | J17: Equally affected | K17: 1
A18: =A8+1 -> 1 | D18: Conviviality | E18: Are peace and conviviality adversely impacted due to the challenges resulting from changing climate? | F18: Consider peace in the community | G18: Not noticed | H18: =IF(OR(G18=$J$11,G18=$J$12,G18=$J$13),$J$9,$J$8) | I18: =IF(G18=$J$11,$K$11,IF(G18=$J$12,$K$12,$K$13)) -> 1 | J18: Women more affected | K18: 2
A19: =A9+1 -> 1 | D19: Education | E19: Is there any effeects on the regularity of education cthat result from changing climate and severe weather evants? | F19: Consider continued access to education independent from climate and weather events | G19: No change noticed | H19: =IF(OR(G19=$J$22,G19=$J$23,G19=$J$24),$J$9,$J$8) | I19: =IF(G19=$J$22,$K$22,IF(G19=$J$23,$K$23,$K$24)) -> 1 | J19: Men more affected | K19: 3
A20: =A10+1 -> 1 | D20: WFI/WFDU | E20: Is water availability for uses other than human consumption adversely affected by changing climate and sevee weather events? | F20: Consider access to water for household uses and irrigation | G20: Not noticed | H20: =IF(OR(G20=$J$11,G20=$J$12,G20=$J$13),$J$9,$J$8) | I20: =IF(G20=$J$11,$K$11,IF(G20=$J$12,$K$12,$K$13)) -> 1
A21: =A11+1 -> 2 | D21: ATF/I | E21: Is household financial demand increasing due to the challenges resulting fom changing climate and severe weather events? | F21: Consider changing financial needs due to climate and weather events | G21: Not Noticed | H21: =IF(OR(G21=$J$27,G21=$J$28,G21=$J$29),$J$9,$J$8) | I21: =IF(G21=$J$27,$K$27,IF(G21=$J$28,$K$28,$K$29)) -> 1 | J21: List 3 | K21: Highly is bad
A22: =A21+1 -> 3 | D22: Disaster Events | E22: Have climate related and extreme weather events caused disasters/emergencies that affected the community before | F22: This includes impacts from temperature, rainfall, droughts and/or floods | G22: Not noticed | H22: =IF(OR(G22=$J$11,G22=$J$12,G22=$J$13),$J$9,$J$8) | I22: =IF(G22=$J$11,$K$11,IF(G22=$J$12,$K$12,$K$13)) -> 1 | J22: Regularity highly affected | K22: 3
I23: ="" | J23: Regularity not often disrupted | K23: 2
A24: =A22+1 -> 4 | B24: 2 | C24: Health & Safety | D24: Borne Diseases | E24: Have climate related events and conditions affected larger portions of the community with diseases? | F24: Water-borne diseases include typhoid fever, cholera, leptospirosis and hepatitis A; Vector diseases include malaria, dengue fever, yellow fever, and West Nile Fever | G24: Not noticed | H24: =IF(OR(G24=$J$11,G24=$J$12,G24=$J$13),$J$9,$J$8) | I24: =IF(G24=$J$11,$K$11,IF(G24=$J$12,$K$12,$K$13)) -> 1 | J24: No change noticed | K24: 1
A25: =A21+1 -> 3 | D25: SLUP&C | E25: Have climate related events increased risky conditions for large portions of the community based on their location ? | F25: Consider changes to the safety of housing locations | G25: Not noticed | H25: =IF(OR(G25=$J$11,G25=$J$12,G25=$J$13),$J$9,$J$8) | I25: =IF(G25=$J$11,$K$11,IF(G25=$J$12,$K$12,$K$13)) -> 1
A26: =A22+1 -> 4 | D26: SWM | E26: Is solid waste dumped in uncontrolled manner and locations ? | F26: Consider inconsiderate depositing of solid waste in the public real, inside drainages, manholes, etc | G26: Negligible | H26: =IF(OR(G26=$J$33,G26=$J$34,G26=$J$35),$J$9,$J$8) | I26: =IF(G26=$J$33,$K$33,IF(G26=$J$34,$K$34,$K$35)) -> 1 | J26: List 4 | K26: Largely is bad
A27: =A23+1 -> 1 | D27: LWM | E27: Is liquid waste deposited in uncontrolled manner and locations ? | F27: Consider grey water discharge and open defecatio in the public realm | G27: Negligible | H27: =IF(OR(G27=$J$33,G27=$J$34,G27=$J$35),$J$9,$J$8) | I27: =IF(G27=$J$33,$K$33,IF(G27=$J$34,$K$34,$K$35)) -> 1 | J27: Largely affected | K27: 3
A28: =A24+1 -> 5 | D28: ATHS | E28: Are there adequate health services accessible within the location and to every household? | F28: Consider accessibility, staffing, and quality of health facilities and services | G28: Yes | H28: =IF(OR(G28=$J$38,G28=$J$39,G28=$J$40),$J$9,$J$8) | I28: =IF(G28=$J$38,$K$38,IF(G28=$J$39,$K$39,$K$40)) -> 1 | J28: Not much affected | K28: 2
A29: =A28+1 -> 6 | D29: ATHE | E29: Is the general settlement environment (air, water, soil, etc) perceived as healthy and intact? | F29: Consider perceived cleanliness of air, water and soils, and any measurements of pollution as available | G29: Yes | H29: =IF(OR(G29=$J$38,G29=$J$39,G29=$J$40),$J$9,$J$8) | I29: =IF(G29=$J$38,$K$38,IF(G29=$J$39,$K$39,$K$40)) -> 1 | J29: Not Noticed | K29: 1
I30: =""
A31: =A29+1 -> 7 | B31: 3 | C31: Assets and Utilities | D31: Housing | E31: Are climate related events affecting the safety of homes | F31: Consider changes to the safety of housing structures | G31: Not noticed | H31: =IF(OR(G31=$J$11,G31=$J$12,G31=$J$13),$J$9,$J$8) | I31: =IF(G31=$J$11,$K$11,IF(G31=$J$12,$K$12,$K$13)) -> 1
A32: =A22+1 -> 4 | D32: Public facilities | E32: Are public community facilities impacted by climate hazards | F32: This includes critical facilities, particularly health facilities, schools and essential community services | G32: Not noticed | H32: =IF(OR(G32=$J$11,G32=$J$12,G32=$J$13),$J$9,$J$8) | I32: =IF(G32=$J$11,$K$11,IF(G32=$J$12,$K$12,$K$13)) -> 1 | J32: List 5 | K32: Largely is bad
A33: =A32+1 -> 5 | D33: SWD | E33: Is there absence of functional constructed storm water drainage channels? | F33: This refers to constructed drainages and natural or constructed infiltration areas | G33: Negligible | H33: =IF(OR(G33=$J$33,G33=$J$34,G33=$J$35),$J$9,$J$8) | I33: =IF(G33=$J$33,$K$33,IF(G33=$J$34,$K$34,$K$35)) -> 1 | J33: Predominantly | K33: 3
A34: =A33+1 -> 6 | D34: Sanitary facilities | E34: Are pit latrines and / or open defecation the primary sanitation mode? | F34: This is specific to household sanitation | G34: Negligible | H34: =IF(OR(G34=$J$33,G34=$J$34,G34=$J$35),$J$9,$J$8) | I34: =IF(G34=$J$33,$K$33,IF(G34=$J$34,$K$34,$K$35)) -> 1 | J34: Partially | K34: 2
A35: =A25+1 -> 4 | D35: Sewer lines | E35: Are sewers absent, dysfunctional, exposed to floods, or households not connected? | F35: This refers to the functionality of sewer lines, if any | G35: Negligible | H35: =IF(OR(G35=$J$33,G35=$J$34,G35=$J$35),$J$9,$J$8) | I35: =IF(G35=$J$33,$K$33,IF(G35=$J$34,$K$34,$K$35)) -> 1 | J35: Negligible | K35: 1
A36: =A28+1 -> 6 | D36: Power lines/supply | E36: Is power supply infrastructure exposed to extreme weather events (overhead power lines, location in flood plains etc), or located underground nearby soil extraction areas | F36: This refers to the design and location of power lines to judge its resiliency | G36: Negligible | H36: =IF(OR(G36=$J$33,G36=$J$34,G36=$J$35),$J$9,$J$8) | I36: =IF(G36=$J$33,$K$33,IF(G36=$J$34,$K$34,$K$35)) -> 1
A37: =A36+1 -> 7 | D37: Energy for HH use | E37: Is there access to electricity at HH level | F37: This refers to the prevalent use of charcoal and wood | G37: Negligible | H37: =IF(OR(G37=$J$33,G37=$J$34,G37=$J$35),$J$9,$J$8) | I37: =IF(G37=$J$33,$K$33,IF(G37=$J$34,$K$34,$K$35)) -> 1 | J37: List 6 | K37: No is bad
A38: =A37+1 -> 8 | D38: Water pipes | E38: Are there (functional) water pipes in the settlement ? | F38: This is about availability of piped water supply network | G38: Negligible | H38: =IF(OR(G38=$J$33,G38=$J$34,G38=$J$35),$J$9,$J$8) | I38: =IF(G38=$J$33,$K$33,IF(G38=$J$34,$K$34,$K$35)) -> 1 | J38: Yes | K38: 1
A39: =A38+1 -> 9 | D39: PWT | E39: Have functionality or reliability of potable water treatment facilities serving the area been impacted by climate hazards? | F39: Consider location and protection of water storage of any | G39: Not noticed | H39: =IF(OR(G39=$J$11,G39=$J$12,G39=$J$13),$J$9,$J$8) | I39: =IF(G39=$J$11,$K$11,IF(G39=$J$12,$K$12,$K$13)) -> 1 | J39: Maybe | K39: 2
A40: =A39+1 -> 10 | D40: Water Storage | E40: Is water storage safely located and protected or is water storage impacted by climate events? | F40: Consider location and protection of water teatment facilities relevant to the water supply of the area | G40: Not noticed | H40: =IF(OR(G40=$J$11,G40=$J$12,G40=$J$13),$J$9,$J$8) | I40: =IF(G40=$J$11,$K$11,IF(G40=$J$12,$K$12,$K$13)) -> 1 | J40: No | K40: 3
A41: =A40+1 -> 11 | D41: R & T | E41: Are accessibility / mobility compromised during extreme weather events and roads and transport infrastructure impacted by floods, land slides, high temperaturs, or other climate-induced events? | F41: Consider all weather access to households and critical facilities | G41: Not noticed | H41: =IF(OR(G41=$J$11,G41=$J$12,G41=$J$13),$J$9,$J$8) | I41: =IF(G41=$J$11,$K$11,IF(G41=$J$12,$K$12,$K$13)) -> 1
A42: =A41+1 -> 12 | D42: Communication | E42: Is communication infrastructure in the settlement (fiber optic cables, wireless hotspots, etc) safely located and protected, if any | F42: Consider location and protection of critical commuication infrastructure | G42: Yes | H42: =IF(OR(G42=$J$38,G42=$J$39,G42=$J$40),$J$9,$J$8) | I42: =IF(G42=$J$38,$K$38,IF(G42=$J$39,$K$39,$K$40)) -> 1 | J42: List 7 | K42: Clay is bad
I43: ="" | J43: Clay | K43: 3
A44: =A43+1 -> 1 | B44: 4 | C44: Potable water | D44: Access | E44: Is potable water accessible at all times, or scarcities often being faced? | F44: This refers to water needed for drinking, its safety and quantity | G44: Negligible | H44: =IF(OR(G44=$J$33,G44=$J$34,G44=$J$35),$J$9,$J$8) | I44: =IF(G44=$J$33,$K$33,IF(G44=$J$34,$K$34,$K$35)) -> 1 | J44: Sand | K44: 2
A45: =A44+1 -> 2 | D45: Scarcities | E45: is potable water access impacted by severe climate related events, e.g. flooding, drought? | F45: This refers to water needed for drinking, its safety and quantity | G45: Not noticed | H45: =IF(OR(G45=$J$11,G45=$J$12,G45=$J$13),$J$9,$J$8) | I45: =IF(G45=$J$11,$K$11,IF(G45=$J$12,$K$12,$K$13)) -> 1 | J45: Loam | K45: 1
A46: =A45+1 -> 3 | D46: Quality | E46: Is the quality of the potable water accessible to the community adequate | F46: This refers to water needed for drinking, its safety and quantity | G46: Yes | H46: =IF(OR(G46=$J$38,G46=$J$39,G46=$J$40),$J$9,$J$8) | I46: =IF(G46=$J$38,$K$38,IF(G46=$J$39,$K$39,$K$40)) -> 1
...

Sheet Sensitivity
F7: NOTE: ONCE YOU CLICK THIS BUTTON YOU CANNOT UNDO YOUR ACTIONS
B8: CURRENT SENSITIVITY | J8: No Selecton Done!
J9: =""
B10: Sensitivity | E10: Question | F10: Comments/Description | G10: Answer? | H10: Add Note On Each Answer | I10: Rating? | J10: List 1 | K10: yes is bad
A11: 1 | B11: 1 | C11: Livelihoods | D11: Food Security | E11: Are access and cost of food changing with extreme weather events? | F11: Consider food security at different at different times of the year (i.e. rainy season)? | G11: Not noticed | H11: =IF(OR(G11=$J$11,G11=$J$12,G11=$J$13),$J$9,$J$8) | I11: =IF(G11=$J$11,$K$11,IF(G11=$J$12,$K$12,$K$13)) -> 1 | J11: Severely and often | K11: 3
A12: =A4+1 -> 1 | D12: Grazing/Farm Land | E12: Is grazing land getting scarcer or more distant | F12: Consider availability of pasture to feed livestock | G12: No | H12: =IF(OR(G12=$J$63,G12=$J$64,G12=$J$65),$J$9,$J$8) | I12: =IF(G12=$J$63,$K$63,IF(G12=$J$64,$K$64,$K$65)) -> 1 | J12: Severely and not often | K12: 2
A13: =A5+1 -> 1 | D13: Crops | E13: Are most households dependent on subsistance farming (crops) for food (not buying)? | F13: Consider dependency on subsistence agriculture for majority of households | G13: Low Dependancy | H13: =IF(OR(G13=$J$17,G13=$J$18,G13=$J$19),$J$9,$J$8) | I13: =IF(G13=$J$17,$K$17,IF(G13=$J$18,$K$18,$K$19)) -> 1 | J13: Not noticed | K13: 1
A14: =A3+1 -> 1 | D14: Livestock | E14: Are most households dependent on own livestock for food (not buying)? | F14: Consider dependency on own livestock keeping for majority of households | G14: Low Dependancy | H14: =IF(OR(G14=$J$17,G14=$J$18,G14=$J$19),$J$9,$J$8) | I14: =IF(G14=$J$17,$K$17,IF(G14=$J$18,$K$18,$K$19)) -> 1
A15: =A4+1 -> 1 | D15: Fishstock | E15: Are most households dependent on fishing for food (not buying)? | F15: Consider dependency on fishing for majority of households | G15: Low Dependancy | H15: =IF(OR(G15=$J$17,G15=$J$18,G15=$J$19),$J$9,$J$8) | I15: =IF(G15=$J$17,$K$17,IF(G15=$J$18,$K$18,$K$19)) -> 1
A16: =A5+1 -> 1 | D16: Local commerce | E16: Are extreme weather events interrupting secure livelihood, business and incomes for large portions of the communityand lead to economically precarious situations ? | F16: Consider dependency on economic activities that are sensitive to climate hazards and severe weather | G16: Low Dependancy | H16: =IF(OR(G16=$J$17,G16=$J$18,G16=$J$19),$J$9,$J$8) | I16: =IF(G16=$J$17,$K$17,IF(G16=$J$18,$K$18,$K$19)) -> 1 | J16: List 2 | K16: yes is bad
A17: =A7+1 -> 1 | D17: Gender | E17: Are women highly dependent on undertaking business inside the settlement? | F17: Consider location of the income generaing activity and sensitivity to climae related hazard | G17: Low Dependancy | H17: =IF(OR(G17=$J$17,G17=$J$18,G17=$J$19),$J$9,$J$8) | I17: =IF(G17=$J$17,$K$17,IF(G17=$J$18,$K$18,$K$19)) -> 1 | J17: Most Residents Concerned | K17: 3
A18: =A8+1 -> 1 | D18: Conviviality | E18: Do resource scarcities that result from cilmate related events or conditions frequently lead to conflicts within the community/or with other communities? | F18: Consider conflict and dispute raised due to climate related hazards | G18: Not noticed | H18: =IF(OR(G18=$J$22,G18=$J$23,G18=$J$24),$J$9,$J$8) | I18: =IF(G18=$J$22,$K$22,IF(G18=$J$23,$K$23,$K$24)) -> 1 | J18: Half Residents Concerned | K18: 2
A19: =A9+1 -> 1 | D19: Education | E19: Are large percentages of children frequently unable to reach/attend school due to climate related and severe weather events? | F19: Consider dependency of education services on climate conditions | G19: Low Dependancy | H19: =IF(OR(G19=$J$17,G19=$J$18,G19=$J$19),$J$9,$J$8) | I19: =IF(G19=$J$17,$K$17,IF(G19=$J$18,$K$18,$K$19)) -> 1 | J19: Low Dependancy | K19: 1
A20: =A10+1 -> 1 | D20: WFI/WFDU | E20: Are there water scarcities often being faced that negatively impact farming, livestock keeping and business? | F20: Consider dependency of access to water on climate conditions | G20: Not noticed | H20: =IF(OR(G20=$J$22,G20=$J$23,G20=$J$24),$J$9,$J$8) | I20: =IF(G20=$J$22,$K$22,IF(G20=$J$23,$K$23,$K$24)) -> 1
A21: =A11+1 -> 2 | D21: ATF/I | E21: Does the community have access to financial services, health insurance and disaster risk insurance? | F21: Consider financial buffers for periods of interrupted income or effects on health | G21: Almost Nobody Has | H21: =IF(OR(G21=$J$27,G21=$J$28,G21=$J$29),$J$9,$J$8) | I21: =IF(G21=$J$27,$K$27,IF(G21=$J$28,$K$28,$K$29)) -> 1 | J21: List 3 | K21: Severe is bad
D22: Disaster Events | E22: How would the impact of climate related disaster be rated, if it were to occur ? | F22: This includes impacts from temperature, rainfall, droughts and/or floods | G22: Not noticed | H22: =IF(OR(G22=$J$53,G22=$J$54,G22=$J$55),$J$9,$J$8) | I22: =IF(G22=$J$53,$K$53,IF(G22=$J$54,$K$54,$K$55)) -> 1 | J22: Severe Problem | K22: 3
J23: Still Okay | K23: 2
A24: =A22+1 -> 1 | B24: 2 | C24: Health & Safety | D24: Borne Diseases | E24: Are health incidences increasing and may be related to the impact of changing extreme weather events? | F24: Compare in relation to the past | G24: Few Residents Concerned | H24: =IF(OR(G24=$J$33,G24=$J$34,G24=$J$35),$J$9,$J$8) | I24: =IF(G24=$J$33,$K$33,IF(G24=$J$34,$K$34,$K$35)) -> 1 | J24: Not noticed | K24: 1
A25: =A21+1 -> 3 | D25: SLUP&C | E25: Are safety incidences increasing and may be related to the impact of changes of extreme weather events? | F25: Compare in relation to the past | G25: Few Residents Concerned | H25: =IF(OR(G25=$J$33,G25=$J$34,G25=$J$35),$J$9,$J$8) | I25: =IF(G25=$J$33,$K$33,IF(G25=$J$34,$K$34,$K$35)) -> 1
A26: =A22+1 -> 1 | D26: SWM | E26: Is solid waste adequately managed, and unmanaged waste is not increasing the adverse impacts of severe weather events ? | F26: Consider mitigation efforts for solid waste not to block drainages and water infiltraion capacities | G26: Yes | H26: =IF(OR(G26=$J$43,G26=$J$44,G26=$J$45),$J$9,$J$8) | I26: =IF(G26=$J$43,$K$43,IF(G26=$J$44,$K$44,$K$45)) -> 1 | J26: List 4 | K26: Largely is bad
A27: =A23+1 -> 1 | D27: LWM | E27: Is untreated waste water released into the environment from industries or domestic uses ? | F27: Consider floodwaters mobilizing faecal sludges and other pollutants | G27: Not noticed | H27: =IF(OR(G27=$J$22,G27=$J$23,G27=$J$24),$J$9,$J$8) | I27: =IF(G27=$J$22,$K$22,IF(G27=$J$23,$K$23,$K$24)) -> 1 | J27: Most Residents Have | K27: 3
A28: =A24+1 -> 2 | D28: ATHS | E28: Are health services inaccessible or dysfunctional during climate related and severe weather events? | F28: Consider uninterrupted health services | G28: Not noticed | H28: =IF(OR(G28=$J$22,G28=$J$23,G28=$J$24),$J$9,$J$8) | I28: =IF(G28=$J$22,$K$22,IF(G28=$J$23,$K$23,$K$24)) -> 1 | J28: Half Residents Have | K28: 2
A29: =A28+1 -> 3 | D29: ATHE | E29: Are there common sources of pollution that originate from human activity? | F29: Consider prevalence of use of biomass for cooking, waste burning and indoor use of pesticides, and industrial pollution | G29: Not noticed | H29: =IF(OR(G29=$J$22,G29=$J$23,G29=$J$24),$J$9,$J$8) | I29: =IF(G29=$J$22,$K$22,IF(G29=$J$23,$K$23,$K$24)) -> 1 | J29: Almost Nobody Has | K29: 1
A31: =A29+1 -> 4 | B31: 3 | C31: Assets and Utilities | D31: Housing | E31: Are foundations stable, walls protected from moisture and roof fixtures adequate? | F31: Consider protection of biult structures | G31: Not noticed | H31: =IF(OR(G31=$J$22,G31=$J$23,G31=$J$24),$J$9,$J$8) | I31: =IF(G31=$J$22,$K$22,IF(G31=$J$23,$K$23,$K$24)) -> 1
A32: =A22+1 -> 1 | D32: Public facilities | E32: Are public facilities inaccessible or dysfunctional due to climate related and severe weather events? | F32: Consider all weather accessibility and operations of public services | G32: Not noticed | H32: =IF(OR(G32=$J$22,G32=$J$23,G32=$J$24),$J$9,$J$8) | I32: =IF(G32=$J$22,$K$22,IF(G32=$J$23,$K$23,$K$24)) -> 1 | J32: List 5 | K32: Largely is bad
A33: =A32+1 -> 2 | D33: SWD | E33: Are drainages under-dimensioned or incomplete? | F33: Consider drainage overflows or faulty outlet designs | G33: Not noticed | H33: =IF(OR(G33=$J$22,G33=$J$23,G33=$J$24),$J$9,$J$8) | I33: =IF(G33=$J$22,$K$22,IF(G33=$J$23,$K$23,$K$24)) -> 1 | J33: Most Residents Concerned | K33: 3
A34: =A33+1 -> 3 | D34: Sanitary facilities | E34: Are sanitation facilities often submerged in water and feaces carried by flood and storm water ? | F34: This is specific to household sanitation | G34: Not noticed | H34: =IF(OR(G34=$J$22,G34=$J$23,G34=$J$24),$J$9,$J$8) | I34: =IF(G34=$J$22,$K$22,IF(G34=$J$23,$K$23,$K$24)) -> 1 | J34: Half Residents Concerned | K34: 2
A35: =A25+1 -> 4 | D35: Sewer lines | E35: Are there sewer lines existing, which are however under-dimensioned (overflowing) or stagnant (e.g. from water shortage)? | F35: Assess functionality of sewers if any | G35: Not noticed | H35: =IF(OR(G35=$J$22,G35=$J$23,G35=$J$24),$J$9,$J$8) | I35: =IF(G35=$J$22,$K$22,IF(G35=$J$23,$K$23,$K$24)) -> 1 | J35: Few Residents Concerned | K35: 1
A36: =A28+1 -> 3 | D36: Power lines/supply | E36: is energy supply regularly impacted / interrupted in relation to extreme weather events? | F36: Consider reliability of power supply from grid | G36: Not noticed | H36: =IF(OR(G36=$J$22,G36=$J$23,G36=$J$24),$J$9,$J$8) | I36: =IF(G36=$J$22,$K$22,IF(G36=$J$23,$K$23,$K$24)) -> 1
A37: =A36+1 -> 4 | D37: Energy for HH use | E37: Do most HHs depend on biomass for cooking | F37: Consider household connections and reliability of supply | G37: Not noticed | H37: =IF(OR(G37=$J$22,G37=$J$23,G37=$J$24),$J$9,$J$8) | I37: =IF(G37=$J$22,$K$22,IF(G37=$J$23,$K$23,$K$24)) -> 1 | J37: List 6 | K37: No is bad
A38: =A37+1 -> 5 | D38: Water pipes | E38: are water pipes functional during and after extreme weather events? | F38: Consider resiliency of water pipes network | G38: Not noticed | H38: =IF(OR(G38=$J$22,G38=$J$23,G38=$J$24),$J$9,$J$8) | I38: =IF(G38=$J$22,$K$22,IF(G38=$J$23,$K$23,$K$24)) -> 1 | J38: Largely | K38: 3
A39: =A38+1 -> 6 | D39: PWT | E39: is water treatment of piped water ensured at all times ? | F39: Consider safety of piped water | G39: Not noticed | H39: =IF(OR(G39=$J$22,G39=$J$23,G39=$J$24),$J$9,$J$8) | I39: =IF(G39=$J$22,$K$22,IF(G39=$J$23,$K$23,$K$24)) -> 1 | J39: Moderate | K39: 2
A40: =A39+1 -> 7 | D40: Water Storage | E40: Does the community rely on water storage infrastructure | F40: Consider use of water storage to bridge unreliable supply | G40: Not noticed | H40: =IF(OR(G40=$J$53,G40=$J$54,G40=$J$55),$J$9,$J$8) | I40: =IF(G40=$J$53,$K$53,IF(G40=$J$54,$K$54,$K$55)) -> 1 | J40: Partially | K40: 1
A41: =A40+1 -> 8 | D41: R & T | E41: Is there a high density of road network ? | F41: Assess proportion of roads network and potentilly destabilized soils | G41: Not noticed | H41: =IF(OR(G41=$J$53,G41=$J$54,G41=$J$55),$J$9,$J$8) | I41: =IF(G41=$J$53,$K$53,IF(G41=$J$54,$K$54,$K$55)) -> 1
A42: =A41+1 -> 9 | D42: Communication | E42: is communication reliability an issue during/after extreme weather events ? | F42: Consider reliability of communication networks | G42: Not noticed | H42: =IF(OR(G42=$J$22,G42=$J$23,G42=$J$24),$J$9,$J$8) | I42: =IF(G42=$J$22,$K$22,IF(G42=$J$23,$K$23,$K$24)) -> 1 | J42: List 7 | K42: Clay is bad
J43: Yes | K43: 1
A44: =A43+1 -> 1 | B44: 4 | C44: Potable water | D44: Access | E44: is access to water impacted by changing climate and extreme weather events? | F44: This refers to water for drinking | G44: Not noticed | H44: =IF(OR(G44=$J$53,G44=$J$54,G44=$J$55),$J$9,$J$8) | I44: =IF(G44=$J$53,$K$53,IF(G44=$J$54,$K$54,$K$55)) -> 1 | J44: No | K44: 3
A45: =A44+1 -> 2 | D45: Scarcities | E45: is water supply regularly impacted / interrupted in relation to extreme weather events? | F45: This refers to water for drinking | G45: Not noticed | H45: =IF(OR(G45=$J$53,G45=$J$54,G45=$J$55),$J$9,$J$8) | I45: =IF(G45=$J$53,$K$53,IF(G45=$J$54,$K$54,$K$55)) -> 1 | J45: Not Applicable | K45: 2
A46: =A45+1 -> 3 | D46: Quality | E46: is water quality impacted by changing climate and extreme weather events? | F46: This refers to water for drinking | G46: Not noticed | H46: =IF(OR(G46=$J$53,G46=$J$54,G46=$J$55),$J$9,$J$8) | I46: =IF(G46=$J$53,$K$53,IF(G46=$J$54,$K$54,$K$55)) -> 1
J47: List 8 | K47: Yes is bad
...

Sheet Adaptive Capacity
F7: NOTE: ONCE YOU CLICK THIS BUTTON YOU CANNOT UNDO YOUR ACTIONS
B8: CURRENT ADAPTIVE CAPACITY | J8: No Selecton Done!
J9: =""
B10: Adaptive Capacity | E10: Question | F10: Comments/Description | G10: Answer? | H10: Add Note On Each Answer | I10: Rating? | J10: List 1 | K10: no is bad
A11: 1 | B11: 1 | C11: Livelihoods | D11: Food Security | E11: Are there adequate areas formally available to practice urban agriculture | F11: Consider provisions in LPLUDP's and Community Development Plans | G11: Yes | H11: =IF(OR(G11=$J$11,G11=$J$12,G11=$J$13),$J$9,$J$8) | I11: =IF(G11=$J$11,$K$11,IF(G11=$J$12,$K$12,$K$13)) -> 3 | J11: No | K11: 1
D12: Grazing/Farm Land | E12: Are there adequate areas formally available for grazing | F12: Consider provisions in LPLUDP's and Community Development Plans | G12: Yes | H12: =IF(OR(G12=$J$11,G12=$J$12,G12=$J$13),$J$9,$J$8) | I12: =IF(G12=$J$11,$K$11,IF(G12=$J$12,$K$12,$K$13)) -> 3 | J12: Sometimes | K12: 2
A13: =A5+1 -> 1 | D13: Crops | E13: Are there mechanims to diversify crops, share unaffected crops and farming locations, and store harvest to protect it? | F13: Consider crop protection from weather events and capacity to diversify crops | G13: Yes | H13: =IF(OR(G13=$J$17,G13=$J$18,G13=$J$19),$J$9,$J$8) | I13: =IF(G13=$J$17,$K$17,IF(G13=$J$18,$K$18,$K$19)) -> 3 | J13: Yes | K13: 3
A14: =A3+1 -> 1 | D14: Livestock | E14: Are there adequate areas identofied and mechanisms to timely rescue and relocate animals to minimise imact from hazards | F14: Consider provisions in LPLUDP's, Community Development Plans and Evacuation Plans | G14: Yes | H14: =IF(OR(G14=$J$17,G14=$J$18,G14=$J$19),$J$9,$J$8) | I14: =IF(G14=$J$17,$K$17,IF(G14=$J$18,$K$18,$K$19)) -> 3
A15: =A4+1 -> 1 | D15: Fishstock | E15: Are there meachnisms that prevent overfishing (monitoring, net size regulations…) and support fishermen with alternatives, such as fish farming | F15: Consider provisions in LPLUDP's and Community Development Plans | G15: Yes | H15: =IF(OR(G15=$J$11,G15=$J$12,G15=$J$13),$J$9,$J$8) | I15: =IF(G15=$J$11,$K$11,IF(G15=$J$12,$K$12,$K$13)) -> 3
A16: =A5+1 -> 1 | D16: Local commerce | E16: Are there diverse economic opportunities in the area? | F16: Consider mixed uses opportunities and access to small business units | G16: Yes | H16: =IF(OR(G16=$J$11,G16=$J$12,G16=$J$13),$J$9,$J$8) | I16: =IF(G16=$J$11,$K$11,IF(G16=$J$12,$K$12,$K$13)) -> 3 | J16: List 2 | K16: no is bad
A17: =A7+1 -> 1 | D17: Gender | E17: Are there mechanisms to ensure privacy, safety and access to reproductve health care for women at all times? | F17: Consider access to health care services and DRM plans | G17: Yes | H17: =IF(OR(G17=$J$11,G17=$J$12,G17=$J$13),$J$9,$J$8) | I17: =IF(G17=$J$11,$K$11,IF(G17=$J$12,$K$12,$K$13)) -> 3 | J17: No | K17: 1
A18: =A8+1 -> 1 | D18: Conviviality | E18: Is there a mechanism to mitigate disputes over diminuished resources before escalation? | F18: Consider activities and capacities of SEC's, GRC's, Environmental and Land Courts (ELC), and public awareness and information | G18: Yes | H18: =IF(OR(G18=$J$11,G18=$J$12,G18=$J$13),$J$9,$J$8) | I18: =IF(G18=$J$11,$K$11,IF(G18=$J$12,$K$12,$K$13)) -> 3 | J18: Yes | K18: 3
A19: =A9+1 -> 1 | D19: Education | E19: Are there mechanisms for children to receive education at all times? | F19: Consider access to education, DRM plans, and provisions to ensure protection of schools from hazards | G19: Yes | H19: =IF(OR(G19=$J$11,G19=$J$12,G19=$J$13),$J$9,$J$8) | I19: =IF(G19=$J$11,$K$11,IF(G19=$J$12,$K$12,$K$13)) -> 3 | J19: Unknown | K19: 2
A20: =A10+1 -> 1 | D20: WFI/WFDU | E20: Are there provisions to harvest and store rain and surface water for irrigation during dry periods? | F20: Consider rain and surface water harvesting and storage available to subsistence farmers | G20: Yes | H20: =IF(OR(G20=$J$11,G20=$J$12,G20=$J$13),$J$9,$J$8) | I20: =IF(G20=$J$11,$K$11,IF(G20=$J$12,$K$12,$K$13)) -> 3
A21: =A11+1 -> 2 | D21: ATF/I | E21: Are most households health insured and insured for cases of disaster ? | F21: Consider rate of health insurance and provisions to help accsess disaster insurance | G21: Yes | H21: =IF(OR(G21=$J$11,G21=$J$12,G21=$J$13),$J$9,$J$8) | I21: =IF(G21=$J$11,$K$11,IF(G21=$J$12,$K$12,$K$13)) -> 3 | J21: List 3 | K21: no is bad
D22: Disaster Events | E22: Is the community aware of the evacuation routes and evacuation centers, and trained for cases of disaster? | F22: Consider availability and awareness of evacuaiotn plans and response mechanisms | G22: Yes | H22: =IF(OR(G22=$J$11,G22=$J$12,G22=$J$13),$J$9,$J$8) | I22: =IF(G22=$J$11,$K$11,IF(G22=$J$12,$K$12,$K$13)) -> 3 | J22: No | K22: 1
J23: Unknown | K23: 2
A24: =A22+1 -> 1 | B24: 2 | C24: Health & Safety | D24: Borne Diseases | E24: Are communities supported to protect and keep healthy during climate related hazards or extreme weather events? | F24: Consider provisions in Community Development Plans, budgets and awareness and information | G24: Yes | H24: =IF(OR(G24=$J$11,G24=$J$12,G24=$J$13),$J$9,$J$8) | I24: =IF(G24=$J$11,$K$11,IF(G24=$J$12,$K$12,$K$13)) -> 3 | J24: Yes | K24: 3
A25: =A21+1 -> 3 | D25: SLUP&C | E25: Is land use planning and enforcement functional and awareness raised about areas at risk? | F25: Consider public awareness of hazardous zones | G25: Yes | H25: =IF(OR(G25=$J$17,G25=$J$18,G25=$J$19),$J$9,$J$8) | I25: =IF(G25=$J$17,$K$17,IF(G25=$J$18,$K$18,$K$19)) -> 3
A26: =A22+1 -> 1 | D26: SWM | E26: Is there effective solid waste management ? | F26: Consider SWM plans and functionality of SWM | G26: Yes | H26: =IF(OR(G26=$J$11,G26=$J$12,G26=$J$13),$J$9,$J$8) | I26: =IF(G26=$J$11,$K$11,IF(G26=$J$12,$K$12,$K$13)) -> 3
A27: =A23+1 -> 1 | D27: LWM | E27: Is there adequate sanitation that is not vulnerable to severe weather events ? | F27: Sanitation solutions respond to the hydrological conditions and are resilient | G27: Yes | H27: =IF(OR(G27=$J$11,G27=$J$12,G27=$J$13),$J$9,$J$8) | I27: =IF(G27=$J$11,$K$11,IF(G27=$J$12,$K$12,$K$13)) -> 3
A28: =A24+1 -> 2 | D28: ATHS | E28: Is there a mechanism that maintains or immediately recovers access to health services when adversely affected ? | F28: Consider DRM plans, evacuaiton plans, and disaster response times and recovery budgets | G28: Yes | H28: =IF(OR(G28=$J$17,G28=$J$18,G28=$J$19),$J$9,$J$8) | I28: =IF(G28=$J$17,$K$17,IF(G28=$J$18,$K$18,$K$19)) -> 3
A29: =A28+1 -> 3 | D29: ATHE | E29: Is the county holding industrial polluters accountable ? | F29: Consider enforcement of environmental regulatioons | G29: Yes | H29: =IF(OR(G29=$J$11,G29=$J$12,G29=$J$13),$J$9,$J$8) | I29: =IF(G29=$J$11,$K$11,IF(G29=$J$12,$K$12,$K$13)) -> 3
A31: =A29+1 -> 4 | B31: 3 | C31: Assets and Utilities | D31: Housing | E31: Is there access to a reinstatement program or mechanism for damaged or lost shelter for affected community members ? | F31: Consider access to finance for home recovery after disaster | G31: Yes | H31: =IF(OR(G31=$J$22,G31=$J$23,G31=$J$24),$J$9,$J$8) | I31: =IF(G31=$J$22,$K$22,IF(G31=$J$23,$K$23,$K$24)) -> 3
A32: =A22+1 -> 1 | D32: Public facilities | E32: Is here a mechanism that maintains or immediately recovers access to critical public services when adversely affected ? | F32: Consider immediate recovery of critical infrastucture | G32: Yes | H32: =IF(OR(G32=$J$17,G32=$J$18,G32=$J$19),$J$9,$J$8) | I32: =IF(G32=$J$17,$K$17,IF(G32=$J$18,$K$18,$K$19)) -> 3
A33: =A32+1 -> 2 | D33: SWD | E33: Are storm water flows fully planned and managed from source up to outlet/for the whole watershed/including use of natural infiltration? | F33: Consider storm water management planning based on location based hydrological assessment | G33: Yes | H33: =IF(OR(G33=$J$17,G33=$J$18,G33=$J$19),$J$9,$J$8) | I33: =IF(G33=$J$17,$K$17,IF(G33=$J$18,$K$18,$K$19)) -> 3
A34: =A33+1 -> 3 | D34: Sanitary facilities | E34: Are sanitary facilities adequate and properly designed in respect of ground water protection? | F34: This is specific to household sanitation; consider techncial assistance to ensure adequacy | G34: Yes | H34: =IF(OR(G34=$J$17,G34=$J$18,G34=$J$19),$J$9,$J$8) | I34: =IF(G34=$J$17,$K$17,IF(G34=$J$18,$K$18,$K$19)) -> 3
A35: =A25+1 -> 4 | D35: Sewer lines | E35: Are sewers properly designed in respect of ground water protection and fit for the local situaiton (and capability to connect)? | F35: Consider adequate infrastucture planning based on location based hydrological assessment | G35: Yes | H35: =IF(OR(G35=$J$17,G35=$J$18,G35=$J$19),$J$9,$J$8) | I35: =IF(G35=$J$17,$K$17,IF(G35=$J$18,$K$18,$K$19)) -> 3
A36: =A28+1 -> 3 | D36: Power lines/supply | E36: Are there means to continously maintain the functionality of the most critical services and to provide access to energy, such as hospitals? | F36: Consider immediate recovery of critical infrastucture | G36: Yes | H36: =IF(OR(G36=$J$17,G36=$J$18,G36=$J$19),$J$9,$J$8) | I36: =IF(G36=$J$17,$K$17,IF(G36=$J$18,$K$18,$K$19)) -> 3
A37: =A36+1 -> 4 | D37: Energy for HH use | E37: Are there programs that facilitate access to alternative, green and renewable sources of energy for lighting and cooking ? | F37: Consider grid and solar kits | G37: Yes | H37: =IF(OR(G37=$J$17,G37=$J$18,G37=$J$19),$J$9,$J$8) | I37: =IF(G37=$J$17,$K$17,IF(G37=$J$18,$K$18,$K$19)) -> 3
A38: =A37+1 -> 5 | D38: Water pipes | E38: Are water pipes properly planned and the layout and access points fit for the local situation? | F38: Consider adequate infrastucture planning based on location based hydrological assessment | G38: Yes | H38: =IF(OR(G38=$J$17,G38=$J$18,G38=$J$19),$J$9,$J$8) | I38: =IF(G38=$J$17,$K$17,IF(G38=$J$18,$K$18,$K$19)) -> 3
A39: =A38+1 -> 6 | D39: PWT | E39: Is the relevant water treatment facility protected from hazards by the provider? | F39: Consider infrastructure protection measures | G39: Yes | H39: =IF(OR(G39=$J$17,G39=$J$18,G39=$J$19),$J$9,$J$8) | I39: =IF(G39=$J$17,$K$17,IF(G39=$J$18,$K$18,$K$19)) -> 3
A40: =A39+1 -> 7 | D40: Water Storage | E40: Is water storage available, protected from hazards ? | F40: Consider availability of water storage and its protetcton | G40: Yes | H40: =IF(OR(G40=$J$17,G40=$J$18,G40=$J$19),$J$9,$J$8) | I40: =IF(G40=$J$17,$K$17,IF(G40=$J$18,$K$18,$K$19)) -> 3
A41: =A40+1 -> 8 | D41: R & T | E41: Is the settlement accessible in all weather conditions (access to/and within)? | F41: Consider adequate infrastucture planning based on location based hydrological assessment | G41: Yes | H41: =IF(OR(G41=$J$22,G41=$J$23,G41=$J$24),$J$9,$J$8) | I41: =IF(G41=$J$22,$K$22,IF(G41=$J$23,$K$23,$K$24)) -> 3
A42: =A41+1 -> 9 | D42: Communication | E42: Is access to communication ensured in all weather conditions ? | F42: Consider adequate infrastucture planning based on location based hydrological assessment | G42: Yes | H42: =IF(OR(G42=$J$22,G42=$J$23,G42=$J$24),$J$9,$J$8) | I42: =IF(G42=$J$22,$K$22,IF(G42=$J$23,$K$23,$K$24)) -> 3
A44: =A43+1 -> 1 | B44: 4 | C44: Potable water | D44: Access | E44: Are there provisions to ensure access to water in the case of emergencies/scarcities? | F44: This includes prepositioning of water for drinking | G44: Yes | H44: =IF(OR(G44=$J$22,G44=$J$23,G44=$J$24),$J$9,$J$8) | I44: =IF(G44=$J$22,$K$22,IF(G44=$J$23,$K$23,$K$24)) -> 3
A45: =A44+1 -> 2 | D45: Scarcities | E45: Are there provisions to ensure sufficient quantities of water in dry seasons / during interruted water supply ? | F45: This includes prepositioning of water for drinking | G45: Yes | H45: =IF(OR(G45=$J$11,G45=$J$12,G45=$J$13),$J$9,$J$8) | I45: =IF(G45=$J$11,$K$11,IF(G45=$J$12,$K$12,$K$13)) -> 3
A46: =A45+1 -> 3 | D46: Quality | E46: Are there provisions to ensure drinking water quality ? | F46: This includes prepositioning of water for drinking | G46: Yes | H46: =IF(OR(G46=$J$22,G46=$J$23,G46=$J$24),$J$9,$J$8) | I46: =IF(G46=$J$22,$K$22,IF(G46=$J$23,$K$23,$K$24)) -> 3
A48: =A47+1 -> 1 | B48: 5 | C48: EBS | D48: Soil | E48: Are geological assessments provenly considered in land use planning and engineeing designs? | F48: Consider adequate planning and design based on location based assessment | G48: Yes | H48: =IF(OR(G48=$J$22,G48=$J$23,G48=$J$24),$J$9,$J$8) | I48: =IF(G48=$J$22,$K$22,IF(G48=$J$23,$K$23,$K$24)) -> 3
A49: =A48+1 -> 2 | D49: LC & P | E49: Is sufficient permeability considered in the settlement plans as part of storm water management and infiltration ? | F49: Consider areas that allow for infiltration | G49: Yes | H49: =IF(OR(G49=$J$22,G49=$J$23,G49=$J$24),$J$9,$J$8) | I49: =IF(G49=$J$22,$K$22,IF(G49=$J$23,$K$23,$K$24)) -> 3
...

Sheet RVAT_Output
C5: To view a synthesis of all the responses, click on the tabs below:
C10: To view the output of the risk and vulnerability assessment, click on the tabs below:
X27: +
B30: HAZARD
B32: CURRENT
B33: The table below illustrates the current climate hazards | AE33: The graph below illustrates the current climate hazards
C36: =C190 -> Temperature | D36: =D190 -> App or Freq | I36: =L190 -> Intensity | S36: =U190 -> Impact
C37: =C191 -> Intense Precipitation | D37: =D191 -> App or Freq | I37: =L191 -> Intensity | S37: =U191 -> Impact
C38: =C192 -> Droughts | D38: =D192 -> App or Freq | G38: =I192 -> Timing | N38: =Q192 -> Intensity | U38: =X192 -> Impact
C39: =C193 -> Flooding | D39: =D193 -> App or Freq | G39: =G193 -> Timing | L39: =M193 -> Intensity | Q39: =S193 -> Extent | X39: =X193 -> Impact
C40: =C194 -> Flash Floods | D40: =D194 -> App or Freq | G40: =G194 -> Timing | L40: =M194 -> Intensity | Q40: =S194 -> Extent | X40: =X194 -> Impact
C41: =C195 -> Storms & Upper Winds | D41: =D195 -> App or Freq | I41: =L195 -> Intensity | S41: =U195 -> Impact
C42: =C196 -> Pollution | D42: =D196 -> App or Freq | I42: =L196 -> Intensity | S42: =U196 -> Impact
C43: =C197 -> LUI | D43: =D197 -> Applicability | I43: =L197 -> Impact | S43: =U197 -> Sensitization
C44: =C208 -> Other Factors | D44: =D198 -> Fire/wildfires | F44: =G198 -> Lightning | H44: =K198 -> Snow | K44: =N198 -> Hail | M44: =Q198 -> EA or VA | Q44: =X198 -> Soil Extraction | V44: =Y198 -> Deforestation | Y44: =Z198 -> Ubarnization
H46: Legend: | K46: Low | N46: Medium | R46: High
B50: EXPOSURE
B52: CURRENT | AD52: The graph below illustrates the current levels of exposure
B53: The table below illustrates the current levels of exposure
C55: =B210 -> Livelihoods | D55: =C210 -> Food Security | E55: =D210 -> Grazing/Farm Land | G55: =F210 -> Crops | I55: =H210 -> Livestock | L55: =K210 -> Fishstock | O55: =N210 -> Local commerce | S55: =R210 -> Gender | W55: =U210 -> Conviviality | Y55: =X210 -> Education | Z55: =Y210 -> WFI/WFDU | AA55: =Z210 -> ATF/I | AB55: =AA210 -> Disaster Events
C56: =B211 -> Health & Safety | D56: =C211 -> Borne Diseases | G56: =D211 -> SLUP&C | L56: =G211 -> SWM | S56: =L211 -> LWM | Y56: =R211 -> ATHS | AA56: =Y211 -> ATHE
C57: =B212 -> Assets and Utilities | D57: =C212 -> Housing | E57: =D212 -> Public facilities | G57: =F212 -> SWD | I57: =H212 -> Sanitary facilities | L57: =K212 -> Sewer lines | O57: =N212 -> Power lines/supply | S57: =R212 -> Energy for HH use | W57: =U212 -> Water pipes | Y57: =X212 -> PWT | Z57: =Y212 -> Water Storage | AA57: =Z212 -> R & T | AB57: =AA212 -> Communication
C58: =B213 -> Potable water | D58: =C213 -> Access | K58: =J213 -> Scarcities | Y58: =X213 -> Quality
C59: =B214 -> EBS | D59: =C214 -> Soil | F59: =D214 -> LC & P | I59: =G214 -> NV | M59: =J214 -> Wetland | R59: =M214 -> Biodiversity | W59: =R214 -> NWB | Y59: =X214 -> Sea | Z59: =Y214 -> EF | AA59: =Z214 -> Land use | AB59: =AA214 -> Topography
C60: =B215 -> Institutions | D60: =C215 -> EWS | F60: =D215 -> A & I | I60: =G215 -> EC | L60: =K215 -> R/RP | P60: =O215 -> HFO | X60: =V215 -> DP | Z60: =Y215 -> DR | AA60: =Z215 -> PFR | AB60: =AA215 -> PFM
H63: Legend: | K63: Low | N63: Medium | R63: High
B66: SENSITIVITY
B68: CURRENT | AD68: The graph below illustrates the current levels of sensitivity
B69: The table below illustrates the current levels of sensitivity
C71: =B225 -> Livelihoods | D71: =C225 -> Food Security | E71: =D225 -> Grazing/Farm Land | G71: =F225 -> Crops | I71: =H225 -> Livestock | L71: =K225 -> Fishstock | O71: =N225 -> Local commerce | S71: =R225 -> Gender | W71: =U225 -> Conviviality | Y71: =X225 -> Education | Z71: =Y225 -> WFI/WFDU | AA71: =Z225 -> ATF/I | AB71: =AA225 -> Disaster Events
C72: =B226 -> Health & Safety | D72: =C226 -> Borne Diseases | G72: =D226 -> SLUP&C | L72: =G226 -> SWM | S72: =L226 -> LWM | Y72: =R226 -> ATHS | AA72: =Y226 -> ATHE
C73: =B227 -> Assets and Utilities | D73: =C227 -> Housing | E73: =D227 -> Public facilities | G73: =F227 -> SWD | I73: =H227 -> Sanitary facilities | L73: =K227 -> Sewer lines | O73: =N227 -> Power lines/supply | S73: =R227 -> Energy for HH use | W73: =U227 -> Water pipes | Y73: =X227 -> PWT | Z73: =Y227 -> Water Storage | AA73: =Z227 -> R & T | AB73: =AA227 -> Communication
C74: =B228 -> Potable water | D74: =C228 -> Access | K74: =J228 -> Scarcities | Y74: =X228 -> Quality
C75: =B229 -> EBS | D75: =C229 -> Soil | F75: =D229 -> LC & P | I75: =G229 -> NV | M75: =J229 -> Wetland | R75: =M229 -> Biodiversity | W75: =R229 -> NWB | Y75: =X229 -> Sea | Z75: =Y229 -> EF | AA75: =Z229 -> Land use | AB75: =AA229 -> Topography
C76: =B230 -> Institutions | D76: =C230 -> EWS | F76: =D230 -> A & I | I76: =G230 -> EC | L76: =K230 -> R/RP | P76: =O230 -> HFO | X76: =V230 -> DP | Z76: =Y230 -> DR | AA76: =Z230 -> PFR | AB76: =AA230 -> PFM
H79: Legend: | K79: Low | N79: Medium | R79: High
B82: ADAPTIVE CAPACITY
