Workbook

Sheet Guidelines
B4: Informal Settlement Vulnerability Assessment Tool
D6: Vulnurability Ratings Per Settlement
B9: Project Name: | C9: Enter here | G9: Project Lead: | H9: Enter here
B10: Project Location: | C10: Enter here | G10: Name of Assessor: | H10: Enter here
B11: Project Code: | C11: Enter here | G11: No. of Beneficiaries: | H11: Enter here
B13: AIM:
B14: The objective of the tool is to evaluate the vulnerability of informal settlements using geographical attributes. It assesses how hazards such as temperature,rainfall, droughts,soil erotion, land slides, food insecurity, pollution,moisture content and floods rates each informal settlement to assist in prioritization during improvement plans.
B17: HOW TO USE THIS TOOL:
B18: The table below shows how geographic attributes quantified for each in a scale of 1 to 3 that represents low-medium and high respectively. For ones having more than 3, the condition is considered extreme. This tables values can be changed ONLY IF deliberated, no individual decision is allowed for change. IF NO CHANGE IS REQUIRED, NO CHANGE ALLOWED. In the output section, the role is to chose on the specifics of geographic attributes ONLY, anything else will be populated atomatically. Color codes in the outpu section are; RED for HIGH score, AMBER for MEDIUM score, GREEN for LOW score, BLACK for no data has been entered. To identify ratings per settlemnt, filter by color in the total core section to generate a list of setttlments hat requires attention in order of priority.
C20: Temperature | D20: Rainfall | E20: Drought | F20: Soil Erosion | G20: Land Slide | H20: Food Insecurity | I20: Pollution | J20: Moisture Content | K20: Flash Floods | L20: Flooding
B21: Af>Tropical | C21: 3 | D21: 2 | E21: 1 | F21: 1 | G21: 1 | H21: 2 | I21: 2 | J21: 3 | K21: 1 | L21: 1
B22: Am> Tropical | C22: 2 | D22: 2 | E22: 2 | F22: 1 | G22: 1 | H22: 2 | I22: 2 | J22: 3 | K22: 1 | L22: 1
B23: Aw> Tropical | C23: 2 | D23: 2 | E23: 2 | F23: 2 | G23: 2 | H23: 2 | I23: 2 | J23: 2 | K23: 2 | L23: 2
B24: BSh> Arid | C24: 3 | D24: 1 | E24: 3 | F24: 2 | G24: 2 | H24: 2 | I24: 2 | J24: 2 | K24: 1 | L24: 1
B25: BSk> Arid | C25: 3 | D25: 1 | E25: 3 | F25: 2 | G25: 2 | H25: 2 | I25: 2 | J25: 2 | K25: 1 | L25: 1
B26: BWh> Arid | C26: 3 | D26: 1 | E26: 3 | F26: 2 | G26: 2 | H26: 2 | I26: 2 | J26: 2 | K26: 1 | L26: 1
B27: Cfa> Temperate | C27: 2 | D27: 3 | E27: 2 | F27: 2 | G27: 2 | H27: 2 | I27: 2 | J27: 2 | K27: 3 | L27: 2
B28: Cfb> Temperate | C28: 2 | D28: 3 | E28: 2 | F28: 2 | G28: 2 | H28: 2 | I28: 2 | J28: 2 | K28: 2 | L28: 2
B29: Csb> Temperate | C29: 2 | D29: 3 | E29: 2 | F29: 2 | G29: 2 | H29: 2 | I29: 2 | J29: 2 | K29: 2 | L29: 2
B30: Cwa> Temperate | C30: 2 | D30: 3 | E30: 2 | F30: 2 | G30: 2 | H30: 2 | I30: 2 | J30: 2 | K30: 3 | L30: 3
B31: Cwb> Temperate | C31: 2 | D31: 3 | E31: 2 | F31: 2 | G31: 2 | H31: 2 | I31: 2 | J31: 2 | K31: 2 | L31: 2
B32: Select here | C32: 0 | D32: 0 | E32: 0 | F32: 0 | G32: 0 | H32: 0 | I32: 0 | J32: 0 | K32: 0 | L32: 0
... B54: Select here | C54: 0 | D54: 0 | E54: 0 | F54: 0 | G54: 0 | H54: 0 | I54: 0 | J54: 0 | K54: 0 | L54: 0
B56: USEFUL RESOURCES:
B57: The data source for generation of geograhic attributes | E57: Link | F57: http://apps.rcmrd.org:8081/geonetwork/srv/eng/catalog.search#/home
F58: https://www.gloh2o.org/koppen/
B59: NOTE: 1. This tool has been developed using MS Excel 2019, and therefore, any verions before 2019 may have limited funcitonality. 2. As this tool uses several macros to enable functionality, the user is required to click on the "Enable macros" button when prompted. 3. To ensure the usability of the tool is maintained, please avoid deleting any rows and columns. As the functionality of the tool is maximised with coding, any modifications of the spreadsheets will render it useless.

Sheet Output
A1: County Code | B1: County | C1: Settlement | D1: Latitude | E1: Longitude | F1: Main Attributes | G1: Attributes/Exposure | H1: LEGEND | I1: Temperature | J1: Rainfall | K1: Drought | L1: Soil Erosion | M1: Land Slide | N1: Food Insecuriy | O1: Pollution | P1: Moisture Content | Q1: Flash Floods | R1: Flooding | T1: Total Score | U1: LEGEND | EI1: Temperature | EJ1: Rainfall | EK1: Drought | EL1: Soil Erotion | EM1: Land Slide | EN1: Food Insecurity | EO1: Pollution | EP1: Moisture Content | EQ1: Flash Floods | ER1: Flooding | ES1: Total Score
A2: 004 | B2: Tana River | C2: Chewani | D2: -1.438854° | E2: 40.023396° | F2: Climate Region | G2: BSh> Arid | H2: LOW | I2: =FE2 -> 13 | J2: =FF2 -> 13 | K2: =FG2 -> 13 | L2: =FH2 -> 12 | M2: =FI2 -> 11 | N2: =FJ2 -> 13 | O2: =FK2 -> 12 | P2: =FL2 -> 12 | ... R2: =FN2 -> 13 | T2: =$FO$2 -> 125 | U2: LOW | EH2: Af>Tropical | EI2: =Guidelines!C21 -> 3 | EJ2: =Guidelines!D21 -> 2 | EK2: =Guidelines!E21 -> 1 | EL2: =Guidelines!F21 -> 1 | EM2: =Guidelines!G21 -> 1 | EN2: =Guidelines!H21 -> 2 | EO2: =Guidelines!I21 -> 2 | EP2: =Guidelines!J21 -> 3 | ... ER2: =Guidelines!L21 -> 1 | ES2: 30 | EU2: =IF(G2=EH2,EI2,IF(G2=EH3,EI3,IF(G2=EH4,EI4,IF(G2=EH5,EI5,IF(G2=EH6,EI6,IF(G2=EH7,EI7,IF(G2=EH8,EI8,IF(G2=EH9,EI9,IF(G2=EH10,EI10,IF(G2=EH11,EI11,IF(G2=EH12,EI12,EI13))))))))))) -> 3 | EV2: =IF(G2=EH2,EJ2,IF(G2=EH3,EJ3,IF(G2=EH4,EJ4,IF(G2=EH5,EJ5,IF(G2=EH6,EJ6,IF(G2=EH7,EJ7,IF(G2=EH8,EJ8,IF(G2=EH9,EJ9,IF(G2=EH10,EJ10,IF(G2=EH11,EJ11,IF(G2=EH12,EJ12,EJ13))))))))))) -> 1 | EW2: =IF(G2=EH2,EK2,IF(G2=EH3,EK3,IF(G2=EH4,EK4,IF(G2=EH5,EK5,IF(G2=EH6,EK6,IF(G2=EH7,EK7,IF(G2=EH8,EK8,IF(G2=EH9,EK9,IF(G2=EH10,EK10,IF(G2=EH11,EK11,IF(G2=EH12,EK12,EK13))))))))))) -> 3 | EX2: =IF(G2=EH2,EL2,IF(G2=EH3,EL3,IF(G2=EH4,EL4,IF(G2=EH5,EL5,IF(G2=EH6,EL6,IF(G2=EH7,EL7,IF(G2=EH8,EL8,IF(G2=EH9,EL9,IF(G2=EH10,EL10,IF(G2=EH11,EL11,IF(G2=EH12,EL12,EL13))))))))))) -> 2 | EY2: =IF(G2=EH2,EM2,IF(G2=EH3,EM3,IF(G2=EH4,EM4,IF(G2=EH5,EM5,IF(G2=EH6,EM6,IF(G2=EH7,EM7,IF(G2=EH8,EM8,IF(G2=EH9,EM9,IF(G2=EH10,EM10,IF(G2=EH11,EM11,IF(G2=EH12,EM12,EM13))))))))))) -> 2 | EZ2: =IF(G2=EH2,EN2,IF(G2=EH3,EN3,IF(G2=EH4,EN4,IF(G2=EH5,EN5,IF(G2=EH6,EN6,IF(G2=EH7,EN7,IF(G2=EH8,EN8,IF(G2=EH9,EN9,IF(G2=EH10,EN10,IF(G2=EH11,EN11,IF(G2=EH12,EN12,EN13))))))))))) -> 2 | FA2: =IF(G2=EH2,EO2,IF(G2=EH3,EO3,IF(G2=EH4,EO4,IF(G2=EH5,EO5,IF(G2=EH6,EO6,IF(G2=EH7,EO7,IF(G2=EH8,EO8,IF(G2=EH9,EO9,IF(G2=EH10,EO10,IF(G2=EH11,EO11,IF(G2=EH12,EO12,EO13))))))))))) -> 2 | FB2: =IF(G2=EH2,EP2,IF(G2=EH3,EP3,IF(G2=EH4,EP4,IF(G2=EH5,EP5,IF(G2=EH6,EP6,IF(G2=EH7,EP7,IF(G2=EH8,EP8,IF(G2=EH9,EP9,IF(G2=EH10,EP10,IF(G2=EH11,EP11,IF(G2=EH12,EP12,EP13))))))))))) -> 2 | FC2: =IF(G2=EH2,EQ2,IF(G2=EH3,EQ3,IF(G2=EH4,EQ4,IF(G2=EH5,EQ5,IF(G2=EH6,EQ6,IF(G2=EH7,EQ7,IF(G2=EH8,EQ8,IF(G2=EH9,EQ9,IF(G2=EH10,EQ10,IF(G2=EH11,EQ11,IF(G2=EH12,EQ12,EQ13))))))))))) -> 1 | FD2: =IF(G2=EH2,ER2,IF(G2=EH3,ER3,IF(G2=EH4,ER4,IF(G2=EH5,ER5,IF(G2=EH6,ER6,IF(G2=EH7,ER7,IF(G2=EH8,ER8,IF(G2=EH9,ER9,IF(G2=EH10,ER10,IF(G2=EH11,ER11,IF(G2=EH12,ER12,ER13))))))))))) -> 1 | FE2: =EU2+EU3+EU4+EU5+EU6+EU7 -> 13 | FF2: =EV2+EV3+EV4+EV5+EV6+EV7 -> 13 | FG2: =EW2+EW3+EW4+EW5+EW6+EW7 -> 13 | FH2: =EX2+EX3+EX4+EX5+EX6+EX7 -> 12 | FI2: =EY2+EY3+EY4+EY5+EY6+EY7 -> 11 | FJ2: =EZ2+EZ3+EZ4+EZ5+EZ6+EZ7 -> 13 | FK2: =FA2+FA3+FA4+FA5+FA6+FA7 -> 12 | FL2: =FB2+FB3+FB4+FB5+FB6+FB7 -> 12 | ... FN2: =FD2+FD3+FD4+FD5+FD6+FD7 -> 13 | FO2: =SUM(FE2:FN2) -> 125
F3: Soil Type | G3: Sand | EH3: Am> Tropical | EI3: =Guidelines!C22 -> 2 | EJ3: =Guidelines!D22 -> 2 | EK3: =Guidelines!E22 -> 2 | EL3: =Guidelines!F22 -> 1 | EM3: =Guidelines!G22 -> 1 | EN3: =Guidelines!H22 -> 2 | EO3: =Guidelines!I22 -> 2 | EP3: =Guidelines!J22 -> 3 | ... ER3: =Guidelines!L22 -> 1 | EU3: =IF(G3=EH14,EI14,IF(G3=EH15,EI15,IF(G3=EH16,EI16,IF(G3=EH17,EI17,EI18)))) -> 3 | EV3: =IF(G3=EH14,EJ14,IF(G3=EH15,EJ15,IF(G3=EH16,EJ16,IF(G3=EH17,EJ17,EJ18)))) -> 2 | EW3: =IF(G3=EH14,EK14,IF(G3=EH15,EK15,IF(G3=EH16,EK16,IF(G3=EH17,EK17,EK18)))) -> 3 | EX3: =IF(G3=EH14,EL14,IF(G3=EH15,EL15,IF(G3=EH16,EL16,IF(G3=EH17,EL17,EL18)))) -> 2 | EY3: =IF(G3=EH14,EM14,IF(G3=EH15,EM15,IF(G3=EH16,EM16,IF(G3=EH17,EM17,EM18)))) -> 1 | EZ3: =IF(G3=EH14,EN14,IF(G3=EH15,EN15,IF(G3=EH16,EN16,IF(G3=EH17,EN17,EN18)))) -> 3 | FA3: =IF(G3=EH14,EO14,IF(G3=EH15,EO15,IF(G3=EH16,EO16,IF(G3=EH17,EO17,EO18)))) -> 1 | FB3: =IF(G3=EH14,EP14,IF(G3=EH15,EP15,IF(G3=EH16,EP16,IF(G3=EH17,EP17,EP18)))) -> 3 | FC3: =IF(G3=EH14,EQ14,IF(G3=EH15,EQ15,IF(G3=EH16,EQ16,IF(G3=EH17,EQ17,EQ18)))) -> 1 | FD3: =IF(G3=EH14,ER14,IF(G3=EH15,ER15,IF(G3=EH16,ER16,IF(G3=EH17,ER17,ER18)))) -> 1 | FO3: =SUM(FE3:FN3) -> 0
F4: Land Cover | G4: Agricultural Land | H4: MEDIUM | U4: MEDIUM | EH4: Aw> Tropical | EI4: =Guidelines!C23 -> 2 | EJ4: =Guidelines!D23 -> 2 | EK4: =Guidelines!E23 -> 2 | EL4: =Guidelines!F23 -> 2 | EM4: =Guidelines!G23 -> 2 | EN4: =Guidelines!H23 -> 2 | EO4: =Guidelines!I23 -> 2 | EP4: =Guidelines!J23 -> 2 | ... ER4: =Guidelines!L23 -> 2 | EU4: =IF(G4=EH19,EI19,IF(G4=EH20,EI20,IF(G4=EH21,EI21,IF(G4=EH22,EI22,EI23)))) -> 2 | EV4: =IF(G4=EH19,EJ19,IF(G4=EH20,EJ20,IF(G4=EH21,EJ21,IF(G4=EH22,EJ22,EJ23)))) -> 2 | EW4: =IF(G4=EH19,EK19,IF(G4=EH20,EK20,IF(G4=EH21,EK21,IF(G4=EH22,EK22,EK23)))) -> 2 | EX4: =IF(G4=EH19,EL19,IF(G4=EH20,EL20,IF(G4=EH21,EL21,IF(G4=EH22,EL22,EL23)))) -> 2 | EY4: =IF(G4=EH19,EM19,IF(G4=EH20,EM20,IF(G4=EH21,EM21,IF(G4=EH22,EM22,EM23)))) -> 2 | EZ4: =IF(G4=EH19,EN19,IF(G4=EH20,EN20,IF(G4=EH21,EN21,IF(G4=EH22,EN22,EN23)))) -> 2 | FA4: =IF(G4=EH19,EO19,IF(G4=EH20,EO20,IF(G4=EH21,EO21,IF(G4=EH22,EO22,EO23)))) -> 2 | FB4: =IF(G4=EH19,EP19,IF(G4=EH20,EP20,IF(G4=EH21,EP21,IF(G4=EH22,EP22,EP23)))) -> 2 | FC4: =IF(G4=EH19,EQ19,IF(G4=EH20,EQ20,IF(G4=EH21,EQ21,IF(G4=EH22,EQ22,EQ23)))) -> 2 | FD4: =IF(G4=EH19,ER19,IF(G4=EH20,ER20,IF(G4=EH21,ER21,IF(G4=EH22,ER22,ER23)))) -> 2 | FO4: =SUM(FE4:FN4) -> 0
F5: Altitude | G5: <750 | EH5: BSh> Arid | EI5: =Guidelines!C24 -> 3 | EJ5: =Guidelines!D24 -> 1 | EK5: =Guidelines!E24 -> 3 | EL5: =Guidelines!F24 -> 2 | EM5: =Guidelines!G24 -> 2 | EN5: =Guidelines!H24 -> 2 | EO5: =Guidelines!I24 -> 2 | EP5: =Guidelines!J24 -> 2 | ... ER5: =Guidelines!L24 -> 1 | EU5: =IF(G5=EH24,EI24,IF(G5=EH25,EI25,IF(G5=EH26,EI26,EI27))) -> 2 | EV5: =IF(G5=EH24,EJ24,IF(G5=EH25,EJ25,IF(G5=EH26,EJ26,EJ27))) -> 3 | EW5: =IF(G5=EH24,EK24,IF(G5=EH25,EK25,IF(G5=EH26,EK26,EK27))) -> 3 | EX5: =IF(G5=EH24,EL24,IF(G5=EH25,EL25,IF(G5=EH26,EL26,EL27))) -> 2 | EY5: =IF(G5=EH24,EM24,IF(G5=EH25,EM25,IF(G5=EH26,EM26,EM27))) -> 2 | EZ5: =IF(G5=EH24,EN24,IF(G5=EH25,EN25,IF(G5=EH26,EN26,EN27))) -> 2 | FA5: =IF(G5=EH24,EO24,IF(G5=EH25,EO25,IF(G5=EH26,EO26,EO27))) -> 3 | FB5: =IF(G5=EH24,EP24,IF(G5=EH25,EP25,IF(G5=EH26,EP26,EP27))) -> 2 | FC5: =IF(G5=EH24,EQ24,IF(G5=EH25,EQ25,IF(G5=EH26,EQ26,EQ27))) -> 3 | FD5: =IF(G5=EH24,ER24,IF(G5=EH25,ER25,IF(G5=EH26,ER26,ER27))) -> 3 | FO5: =SUM(FE5:FN5) -> 0
F6: Proximity to Major River | G6: <2000 | H6: HIGH | U6: HIGH | EH6: BSk> Arid | EI6: =Guidelines!C25 -> 3 | EJ6: =Guidelines!D25 -> 1 | EK6: =Guidelines!E25 -> 3 | EL6: =Guidelines!F25 -> 2 | EM6: =Guidelines!G25 -> 2 | EN6: =Guidelines!H25 -> 2 | EO6: =Guidelines!I25 -> 2 | EP6: =Guidelines!J25 -> 2 | ... ER6: =Guidelines!L25 -> 1 | EU6: =IF(G6=EH28,EI28,IF(G6=EH29,EI29,IF(G6=EH30,EI30,EI31))) -> 2 | EV6: =IF(G6=EH28,EJ28,IF(G6=EH29,EJ29,IF(G6=EH30,EJ30,EJ31))) -> 3 | EW6: =IF(G6=EH28,EK28,IF(G6=EH29,EK29,IF(G6=EH30,EK30,EK31))) -> 1 | EX6: =IF(G6=EH28,EL28,IF(G6=EH29,EL29,IF(G6=EH30,EL30,EL31))) -> 2 | EY6: =IF(G6=EH28,EM28,IF(G6=EH29,EM29,IF(G6=EH30,EM30,EM31))) -> 2 | EZ6: =IF(G6=EH28,EN28,IF(G6=EH29,EN29,IF(G6=EH30,EN30,EN31))) -> 2 | FA6: =IF(G6=EH28,EO28,IF(G6=EH29,EO29,IF(G6=EH30,EO30,EO31))) -> 2 | FB6: =IF(G6=EH28,EP28,IF(G6=EH29,EP29,IF(G6=EH30,EP30,EP31))) -> 2 | FC6: =IF(G6=EH28,EQ28,IF(G6=EH29,EQ29,IF(G6=EH30,EP30,EQ31))) -> 3 | FD6: =IF(G6=EH28,ER28,IF(G6=EH29,ER29,IF(G6=EH30,ER30,ER31))) -> 3 | FO6: =SUM(FE6:FN6) -> 0
F7: Proximity to Flood Plain | G7: <4500 | EH7: BWh> Arid | EI7: =Guidelines!C26 -> 3 | EJ7: =Guidelines!D26 -> 1 | EK7: =Guidelines!E26 -> 3 | EL7: =Guidelines!F26 -> 2 | EM7: =Guidelines!G26 -> 2 | EN7: =Guidelines!H26 -> 2 | EO7: =Guidelines!I26 -> 2 | EP7: =Guidelines!J26 -> 2 | ... ER7: =Guidelines!L26 -> 1 | EU7: =IF(G7=EH32,EI32,IF(G7=EH33,EI33,IF(G7=EH34,EI34,EI35))) -> 1 | EV7: =IF(G7=EH32,EJ32,IF(G7=EH33,EJ33,IF(G7=EH34,EJ34,EJ35))) -> 2 | EW7: =IF(G7=EH32,EK32,IF(G7=EH33,EK33,IF(G7=EH34,EK34,EK35))) -> 1 | EX7: =IF(G7=EH32,EL32,IF(G7=EH33,EL33,IF(G7=EH34,EL34,EL35))) -> 2 | EY7: =IF(G7=EH32,EM32,IF(G7=EH33,EM33,IF(G7=EH34,EM34,EM35))) -> 2 | EZ7: =IF(G7=EH32,EN32,IF(G7=EH33,EN33,IF(G7=EH34,EN34,EN35))) -> 2 | FA7: =IF(G7=EH32,EO32,IF(G7=EH33,EO33,IF(G7=EH34,EO34,EO35))) -> 2 | FB7: =IF(G7=EH32,EP32,IF(G7=EH33,EP33,IF(G7=EH34,EP34,EP35))) -> 1 | FC7: =IF(G7=EH32,EQ32,IF(G7=EH33,EQ33,IF(G7=EH34,EQ34,EQ35))) -> 3 | FD7: =IF(G7=EH32,ER32,IF(G7=EH33,ER33,IF(G7=EH34,ER34,ER35))) -> 3 | FO7: =SUM(FE7:FN7) -> 0
A8: County Code | B8: County | C8: Settlement | D8: Latitude | E8: Longitude | F8: Main Attributes | G8: Attributes | H8: LEGEND | I8: Temperature | J8: Rainfall | K8: Drought | L8: Soil Erotion | M8: Land Slide | N8: Food Insecuriy | O8: Pollution | P8: Moisture Content | Q8: Flash Floods | R8: Flooding | T8: Total Score | U8: LEGEND | EH8: Cfa> Temperate | EI8: =Guidelines!C27 -> 2 | EJ8: =Guidelines!D27 -> 3 | EK8: =Guidelines!E27 -> 2 | EL8: =Guidelines!F27 -> 2 | EM8: =Guidelines!G27 -> 2 | EN8: =Guidelines!H27 -> 2 | EO8: =Guidelines!I27 -> 2 | EP8: =Guidelines!J27 -> 2 | ... ER8: =Guidelines!L27 -> 2 | FO8: =SUM(FE8:FN8) -> 0
A9: 004 | B9: Tana River | C9: Mororo | D9: -0.467828° | E9: 39.633706° | F9: Climate Region | G9: BWh> Arid | H9: LOW | I9: =FE9 -> 11 | J9: =FF9 -> 15 | K9: =FG9 -> 11 | L9: =FH9 -> 12 | M9: =FI9 -> 12 | N9: =FJ9 -> 11 | O9: =FK9 -> 13 | P9: =FL9 -> 11 | ... R9: =FN9 -> 14 | T9: =$FO$9 -> 124 | U9: LOW | EH9: Cfb> Temperate | EI9: =Guidelines!C28 -> 2 | EJ9: =Guidelines!D28 -> 3 | EK9: =Guidelines!E28 -> 2 | EL9: =Guidelines!F28 -> 2 | EM9: =Guidelines!G28 -> 2 | EN9: =Guidelines!H28 -> 2 | EO9: =Guidelines!I28 -> 2 | EP9: =Guidelines!J28 -> 2 | ... ER9: =Guidelines!L28 -> 2 | EU9: =IF(G9=EH2,EI2,IF(G9=EH3,EI3,IF(G9=EH4,EI4,IF(G9=EH5,EI5,IF(G9=EH6,EI6,IF(G9=EH7,EI7,IF(G9=EH8,EI8,IF(G9=EH9,EI9,IF(G9=EH10,EI10,IF(G9=EH11,EI11,IF(G9=EH12,EI12,EI13))))))))))) -> 3 | EV9: =IF(G9=EH2,EJ2,IF(G9=EH3,EJ3,IF(G9=EH4,EJ4,IF(G9=EH5,EJ5,IF(G9=EH6,EJ6,IF(G9=EH7,EJ7,IF(G9=EH8,EJ8,IF(G9=EH9,EJ9,IF(G9=EH10,EJ10,IF(G9=EH11,EJ11,IF(G9=EH12,EJ12,EJ13))))))))))) -> 1 | EW9: =IF(G9=EH2,EK2,IF(G9=EH3,EK3,IF(G9=EH4,EK4,IF(G9=EH5,EK5,IF(G9=EH6,EK6,IF(G9=EH7,EK7,IF(G9=EH8,EK8,IF(G9=EH9,EK9,IF(G9=EH10,EK10,IF(G9=EH11,EK11,IF(G9=EH12,EK12,EK13))))))))))) -> 3 | EX9: =IF(G9=EH2,EL2,IF(G9=EH3,EL3,IF(G9=EH4,EL4,IF(G9=EH5,EL5,IF(G9=EH6,EL6,IF(G9=EH7,EL7,IF(G9=EH8,EL8,IF(G9=EH9,EL9,IF(G9=EH10,EL10,IF(G9=EH11,EL11,IF(G9=EH12,EL12,EL13))))))))))) -> 2 | EY9: =IF(G9=EH2,EM2,IF(G9=EH3,EM3,IF(G9=EH4,EM4,IF(G9=EH5,EM5,IF(G9=EH6,EM6,IF(G9=EH7,EM7,IF(G9=EH8,EM8,IF(G9=EH9,EM9,IF(G9=EH10,EM10,IF(G9=EH11,EM11,IF(G9=EH12,EM12,EM13))))))))))) -> 2 | EZ9: =IF(G9=EH2,EN2,IF(G9=EH3,EN3,IF(G9=EH4,EN4,IF(G9=EH5,EN5,IF(G9=EH6,EN6,IF(G9=EH7,EN7,IF(G9=EH8,EN8,IF(G9=EH9,EN9,IF(G9=EH10,EN10,IF(G9=EH11,EN11,IF(G9=EH12,EN12,EN13))))))))))) -> 2 | FA9: =IF(G9=EH2,EO2,IF(G9=EH3,EO3,IF(G9=EH4,EO4,IF(G9=EH5,EO5,IF(G9=EH6,EO6,IF(G9=EH7,EO7,IF(G9=EH8,EO8,IF(G9=EH9,EO9,IF(G9=EH10,EO10,IF(G9=EH11,EO11,IF(G9=EH12,EO12,EO13))))))))))) -> 2 | FB9: =IF(G9=EH2,EP2,IF(G9=EH3,EP3,IF(G9=EH4,EP4,IF(G9=EH5,EP5,IF(G9=EH6,EP6,IF(G9=EH7,EP7,IF(G9=EH8,EP8,IF(G9=EH9,EP9,IF(G9=EH10,EP10,IF(G9=EH11,EP11,IF(G9=EH12,EP12,EP13))))))))))) -> 2 | FC9: =IF(G9=EH2,EQ2,IF(G9=EH3,EQ3,IF(G9=EH4,EQ4,IF(G9=EH5,EQ5,IF(G9=EH6,EQ6,IF(G9=EH7,EQ7,IF(G9=EH8,EQ8,IF(G9=EH9,EQ9,IF(G9=EH10,EQ10,IF(G9=EH11,EQ11,IF(G9=EH12,EQ12,EQ13))))))))))) -> 1 | FD9: =IF(G9=EH2,ER2,IF(G9=EH3,ER3,IF(G9=EH4,ER4,IF(G9=EH5,ER5,IF(G9=EH6,ER6,IF(G9=EH7,ER7,IF(G9=EH8,ER8,IF(G9=EH9,ER9,IF(G9=EH10,ER10,IF(G9=EH11,ER11,IF(G9=EH12,ER12,ER13))))))))))) -> 1 | FE9: =EU9+EU10+EU11+EU12+EU13+EU14 -> 11 | FF9: =EV9+EV10+EV11+EV12+EV13+EV14 -> 15 | FG9: =EW9+EW10+EW11+EW12+EW13+EW14 -> 11 | FH9: =EX9+EX10+EX11+EX12+EX13+EX14 -> 12 | FI9: =EY9+EY10+EY11+EY12+EY13+EY14 -> 12 | FJ9: =EZ9+EZ10+EZ11+EZ12+EZ13+EZ14 -> 11 | FK9: =FA9+FA10+FA11+FA12+FA13+FA14 -> 13 | FL9: =FB9+FB10+FB11+FB12+FB13+FB14 -> 11 | ... FN9: =FD9+FD10+FD11+FD12+FD13+FD14 -> 14 | FO9: =SUM(FE9:FN9) -> 124
F10: Soil Type | G10: Clay | EH10: Csb> Temperate | EI10: =Guidelines!C29 -> 2 | EJ10: =Guidelines!D29 -> 3 | EK10: =Guidelines!E29 -> 2 | EL10: =Guidelines!F29 -> 2 | EM10: =Guidelines!G29 -> 2 | EN10: =Guidelines!H29 -> 2 | EO10: =Guidelines!I29 -> 2 | EP10: =Guidelines!J29 -> 2 | ... ER10: =Guidelines!L29 -> 2 | EU10: =IF(G10=EH14,EI14,IF(G10=EH15,EI15,IF(G10=EH16,EI16,IF(G10=EH17,EI17,EI18)))) -> 2 | EV10: =IF(G10=EH14,EJ14,IF(G10=EH15,EJ15,IF(G10=EH16,EJ16,IF(G10=EH17,EJ17,EJ18)))) -> 3 | EW10: =IF(G10=EH14,EK14,IF(G10=EH15,EK15,IF(G10=EH16,EK16,IF(G10=EH17,EK17,EK18)))) -> 2 | EX10: =IF(G10=EH14,EL14,IF(G10=EH15,EL15,IF(G10=EH16,EL16,IF(G10=EH17,EL17,EL18)))) -> 3 | EY10: =IF(G10=EH14,EM14,IF(G10=EH15,EM15,IF(G10=EH16,EM16,IF(G10=EH17,EM17,EM18)))) -> 3 | EZ10: =IF(G10=EH14,EN14,IF(G10=EH15,EN15,IF(G10=EH16,EN16,IF(G10=EH17,EN17,EN18)))) -> 2 | FA10: =IF(G10=EH14,EO14,IF(G10=EH15,EO15,IF(G10=EH16,EO16,IF(G10=EH17,EO17,EO18)))) -> 2 | FB10: =IF(G10=EH14,EP14,IF(G10=EH15,EP15,IF(G10=EH16,EP16,IF(G10=EH17,EP17,EP18)))) -> 1 | FC10: =IF(G10=EH14,EQ14,IF(G10=EH15,EQ15,IF(G10=EH16,EQ16,IF(G10=EH17,EQ17,EQ18)))) -> 3 | FD10: =IF(G10=EH14,ER14,IF(G10=EH15,ER15,IF(G10=EH16,ER16,IF(G10=EH17,ER17,ER18)))) -> 3 | FO10: =SUM(FE10:FN10) -> 0
F11: Land Cover | G11: Natural Terrestrial Vegetation | H11: MEDIUM | U11: MEDIUM | EH11: Cwa> Temperate | EI11: =Guidelines!C30 -> 2 | EJ11: =Guidelines!D30 -> 3 | EK11: =Guidelines!E30 -> 2 | EL11: =Guidelines!F30 -> 2 | EM11: =Guidelines!G30 -> 2 | EN11: =Guidelines!H30 -> 2 | EO11: =Guidelines!I30 -> 2 | EP11: =Guidelines!J30 -> 2 | ... ER11: =Guidelines!L30 -> 3 | EU11: =IF(G11=EH19,EI19,IF(G11=EH20,EI20,IF(G11=EH21,EI21,IF(G11=EH22,EI22,EI23)))) -> 1 | EV11: =IF(G11=EH19,EJ19,IF(G11=EH20,EJ20,IF(G11=EH21,EJ21,IF(G11=EH22,EJ22,EJ23)))) -> 3 | EW11: =IF(G11=EH19,EK19,IF(G11=EH20,EK20,IF(G11=EH21,EK21,IF(G11=EH22,EK22,EK23)))) -> 1 | EX11: =IF(G11=EH19,EL19,IF(G11=EH20,EL20,IF(G11=EH21,EL21,IF(G11=EH22,EL22,EL23)))) -> 1 | EY11: =IF(G11=EH19,EM19,IF(G11=EH20,EM20,IF(G11=EH21,EM21,IF(G11=EH22,EM22,EM23)))) -> 1 | EZ11: =IF(G11=EH19,EN19,IF(G11=EH20,EN20,IF(G11=EH21,EN21,IF(G11=EH22,EN22,EN23)))) -> 1 | FA11: =IF(G11=EH19,EO19,IF(G11=EH20,EO20,IF(G11=EH21,EO21,IF(G11=EH22,EO22,EO23)))) -> 2 | FB11: =IF(G11=EH19,EP19,IF(G11=EH20,EP20,IF(G11=EH21,EP21,IF(G11=EH22,EP22,EP23)))) -> 3 | FC11: =IF(G11=EH19,EQ19,IF(G11=EH20,EQ20,IF(G11=EH21,EQ21,IF(G11=EH22,EQ22,EQ23)))) -> 1 | FD11: =IF(G11=EH19,ER19,IF(G11=EH20,ER20,IF(G11=EH21,ER21,IF(G11=EH22,ER22,ER23)))) -> 1 | FO11: =SUM(FE11:FN11) -> 0
F12: Altitude | G12: <750 | EH12: Cwb> Temperate | EI12: =Guidelines!C31 -> 2 | EJ12: =Guidelines!D31 -> 3 | EK12: =Guidelines!E31 -> 2 | EL12: =Guidelines!F31 -> 2 | EM12: =Guidelines!G31 -> 2 | EN12: =Guidelines!H31 -> 2 | EO12: =Guidelines!I31 -> 2 | EP12: =Guidelines!J31 -> 2 | ... ER12: =Guidelines!L31 -> 2 | EU12: =IF(G12=EH24,EI24,IF(G12=EH25,EI25,IF(G12=EH26,EI26,EI27))) -> 2 | EV12: =IF(G12=EH24,EJ24,IF(G12=EH25,EJ25,IF(G12=EH26,EJ26,EJ27))) -> 3 | EW12: =IF(G12=EH24,EK24,IF(G12=EH25,EK25,IF(G12=EH26,EK26,EK27))) -> 3 | EX12: =IF(G12=EH24,EL24,IF(G12=EH25,EL25,IF(G12=EH26,EL26,EL27))) -> 2 | EY12: =IF(G12=EH24,EM24,IF(G12=EH25,EM25,IF(G12=EH26,EM26,EM27))) -> 2 | EZ12: =IF(G12=EH24,EN24,IF(G12=EH25,EN25,IF(G12=EH26,EN26,EN27))) -> 2 | FA12: =IF(G12=EH24,EO24,IF(G12=EH25,EO25,IF(G12=EH26,EO26,EO27))) -> 3 | FB12: =IF(G12=EH24,EP24,IF(G12=EH25,EP25,IF(G12=EH26,EP26,EP27))) -> 2 | FC12: =IF(G12=EH24,EQ24,IF(G12=EH25,EQ25,IF(G12=EH26,EQ26,EQ27))) -> 3 | FD12: =IF(G12=EH24,ER24,IF(G12=EH25,ER25,IF(G12=EH26,ER26,ER27))) -> 3 | FO12: =SUM(FE12:FN12) -> 0
F13: Proximity to Major River | G13: <2000 | H13: HIGH | U13: HIGH | EH13: Select here | EI13: =Guidelines!C32 -> 0 | EJ13: =Guidelines!D32 -> 0 | EK13: =Guidelines!E32 -> 0 | EL13: =Guidelines!F32 -> 0 | EM13: =Guidelines!G32 -> 0 | EN13: =Guidelines!H32 -> 0 | EO13: =Guidelines!I32 -> 0 | EP13: =Guidelines!J32 -> 0 | ... ER13: =Guidelines!L32 -> 0 | EU13: =IF(G13=EH28,EI28,IF(G13=EH29,EI29,IF(G13=EH30,EI30,EI31))) -> 2 | EV13: =IF(G13=EH28,EJ28,IF(G13=EH29,EJ29,IF(G13=EH30,EJ30,EJ31))) -> 3 | EW13: =IF(G13=EH28,EK28,IF(G13=EH29,EK29,IF(G13=EH30,EK30,EK31))) -> 1 | EX13: =IF(G13=EH28,EL28,IF(G13=EH29,EL29,IF(G13=EH30,EL30,EL31))) -> 2 | EY13: =IF(G13=EH28,EM28,IF(G13=EH29,EM29,IF(G13=EH30,EM30,EM31))) -> 2 | EZ13: =IF(G13=EH28,EN28,IF(G13=EH29,EN29,IF(G13=EH30,EN30,EN31))) -> 2 | FA13: =IF(G13=EH28,EO28,IF(G13=EH29,EO29,IF(G13=EH30,EO30,EO31))) -> 2 | FB13: =IF(G13=EH28,EP28,IF(G13=EH29,EP29,IF(G13=EH30,EP30,EP31))) -> 2 | FC13: =IF(G13=EH28,EQ28,IF(G13=EH29,EQ29,IF(G13=EH30,EP30,EQ31))) -> 3 | FD13: =IF(G13=EH28,ER28,IF(G13=EH29,ER29,IF(G13=EH30,ER30,ER31))) -> 3 | FO13: =SUM(FE13:FN13) -> 0
F14: Proximity to Flood Plain | G14: <4500 | EH14: Clay | EI14: =Guidelines!C33 -> 2 | EJ14: =Guidelines!D33 -> 3 | EK14: =Guidelines!E33 -> 2 | EL14: =Guidelines!F33 -> 3 | EM14: =Guidelines!G33 -> 3 | EN14: =Guidelines!H33 -> 2 | EO14: =Guidelines!I33 -> 2 | EP14: =Guidelines!J33 -> 1 | ... ER14: =Guidelines!L33 -> 3 | EU14: =IF(G14=EH32,EI32,IF(G14=EH33,EI33,IF(G14=EH34,EI34,EI35))) -> 1 | EV14: =IF(G14=EH32,EJ32,IF(G14=EH33,EJ33,IF(G14=EH34,EJ34,EJ35))) -> 2 | EW14: =IF(G14=EH32,EK32,IF(G14=EH33,EK33,IF(G14=EH34,EK34,EK35))) -> 1 | EX14: =IF(G14=EH32,EL32,IF(G14=EH33,EL33,IF(G14=EH34,EL34,EL35))) -> 2 | EY14: =IF(G14=EH32,EM32,IF(G14=EH33,EM33,IF(G14=EH34,EM34,EM35))) -> 2 | EZ14: =IF(G14=EH32,EN32,IF(G14=EH33,EN33,IF(G14=EH34,EN34,EN35))) -> 2 | FA14: =IF(G14=EH32,EO32,IF(G14=EH33,EO33,IF(G14=EH34,EO34,EO35))) -> 2 | FB14: =IF(G14=EH32,EP32,IF(G14=EH33,EP33,IF(G14=EH34,EP34,EP35))) -> 1 | FC14: =IF(G14=EH32,EQ32,IF(G14=EH33,EQ33,IF(G14=EH34,EQ34,EQ35))) -> 3 | FD14: =IF(G14=EH32,ER32,IF(G14=EH33,ER33,IF(G14=EH34,ER34,ER35))) -> 3 | FO14: =SUM(FE14:FN14) -> 0
A15: County Code | B15: County | C15: Settlement | D15: Latitude | E15: Longitude | F15: Main Attributes | G15: Attributes | H15: LEGEND | I15: Temperature | J15: Rainfall | K15: Drought | L15: Soil Erotion | M15: Land Slide | N15: Food Insecuriy | O15: Pollution | P15: Moisture Content | Q15: Flash Floods | R15: Flooding | T15: Total Score | U15: LEGEND | EH15: Sand | EI15: =Guidelines!C34 -> 3 | EJ15: =Guidelines!D34 -> 2 | EK15: =Guidelines!E34 -> 3 | EL15: =Guidelines!F34 -> 2 | EM15: =Guidelines!G34 -> 1 | EN15: =Guidelines!H34 -> 3 | EO15: =Guidelines!I34 -> 1 | EP15: =Guidelines!J34 -> 3 | ... ER15: =Guidelines!L34 -> 1 | FO15: =SUM(FE15:FN15) -> 0
A16: 022 | B16: Kiambu | C16: Dagoretti Ruthimiti | D16: -1.284724° | E16: 36.690681° | F16: Climate Region | G16: Aw> Tropical | H16: LOW | I16: =FE16 -> 11 | J16: =FF16 -> 14 | K16: =FG16 -> 9 | L16: =FH16 -> 11 | M16: =FI16 -> 11 | N16: =FJ16 -> 10 | O16: =FK16 -> 11 | P16: =FL16 -> 10 | ... R16: =FN16 -> 15 | T16: =$FO$16 -> 117 | U16: LOW | EH16: Loam | EI16: =Guidelines!C35 -> 2 | EJ16: =Guidelines!D35 -> 2 | EK16: =Guidelines!E35 -> 2 | EL16: =Guidelines!F35 -> 2 | EM16: =Guidelines!G35 -> 2 | EN16: =Guidelines!H35 -> 1 | EO16: =Guidelines!I35 -> 2 | EP16: =Guidelines!J35 -> 2 | ... ER16: =Guidelines!L35 -> 1 | EU16: =IF(G16=EH2,EI2,IF(G16=EH3,EI3,IF(G16=EH4,EI4,IF(G16=EH5,EI5,IF(G16=EH6,EI6,IF(G16=EH7,EI7,IF(G16=EH8,EI8,IF(G16=EH9,EI9,IF(G16=EH10,EI10,IF(G16=EH11,EI11,IF(G16=EH12,EI12,EI13))))))))))) -> 2 | EV16: =IF(G16=EH2,EJ2,IF(G16=EH3,EJ3,IF(G16=EH4,EJ4,IF(G16=EH5,EJ5,IF(G16=EH6,EJ6,IF(G16=EH7,EJ7,IF(G16=EH8,EJ8,IF(G16=EH9,EJ9,IF(G16=EH10,EJ10,IF(G16=EH11,EJ11,IF(G16=EH12,EJ12,EJ13))))))))))) -> 2 | EW16: =IF(G16=EH2,EK2,IF(G16=EH3,EK3,IF(G16=EH4,EK4,IF(G16=EH5,EK5,IF(G16=EH6,EK6,IF(G16=EH7,EK7,IF(G16=EH8,EK8,IF(G16=EH9,EK9,IF(G16=EH10,EK10,IF(G16=EH11,EK11,IF(G16=EH12,EK12,EK13))))))))))) -> 2 | EX16: =IF(G16=EH2,EL2,IF(G16=EH3,EL3,IF(G16=EH4,EL4,IF(G16=EH5,EL5,IF(G16=EH6,EL6,IF(G16=EH7,EL7,IF(G16=EH8,EL8,IF(G16=EH9,EL9,IF(G16=EH10,EL10,IF(G16=EH11,EL11,IF(G16=EH12,EL12,EL13))))))))))) -> 2 | EY16: =IF(G16=EH2,EM2,IF(G16=EH3,EM3,IF(G16=EH4,EM4,IF(G16=EH5,EM5,IF(G16=EH6,EM6,IF(G16=EH7,EM7,IF(G16=EH8,EM8,IF(G16=EH9,EM9,IF(G16=EH10,EM10,IF(G16=EH11,EM11,IF(G16=EH12,EM12,EM13))))))))))) -> 2 | EZ16: =IF(G16=EH2,EN2,IF(G16=EH3,EN3,IF(G16=EH4,EN4,IF(G16=EH5,EN5,IF(G16=EH6,EN6,IF(G16=EH7,EN7,IF(G16=EH8,EN8,IF(G16=EH9,EN9,IF(G16=EH10,EN10,IF(G16=EH11,EN11,IF(G16=EH12,EN12,EN13))))))))))) -> 2 | FA16: =IF(G16=EH2,EO2,IF(G16=EH3,EO3,IF(G16=EH4,EO4,IF(G16=EH5,EO5,IF(G16=EH6,EO6,IF(G16=EH7,EO7,IF(G16=EH8,EO8,IF(G16=EH9,EO9,IF(G16=EH10,EO10,IF(G16=EH11,EO11,IF(G16=EH12,EO12,EO13))))))))))) -> 2 | FB16: =IF(G16=EH2,EP2,IF(G16=EH3,EP3,IF(G16=EH4,EP4,IF(G16=EH5,EP5,IF(G16=EH6,EP6,IF(G16=EH7,EP7,IF(G16=EH8,EP8,IF(G16=EH9,EP9,IF(G16=EH10,EP10,IF(G16=EH11,EP11,IF(G16=EH12,EP12,EP13))))))))))) -> 2 | FC16: =IF(G16=EH2,EQ2,IF(G16=EH3,EQ3,IF(G16=EH4,EQ4,IF(G16=EH5,EQ5,IF(G16=EH6,EQ6,IF(G16=EH7,EQ7,IF(G16=EH8,EQ8,IF(G16=EH9,EQ9,IF(G16=EH10,EQ10,IF(G16=EH11,EQ11,IF(G16=EH12,EQ12,EQ13))))))))))) -> 2 | FD16: =IF(G16=EH2,ER2,IF(G16=EH3,ER3,IF(G16=EH4,ER4,IF(G16=EH5,ER5,IF(G16=EH6,ER6,IF(G16=EH7,ER7,IF(G16=EH8,ER8,IF(G16=EH9,ER9,IF(G16=EH10,ER10,IF(G16=EH11,ER11,IF(G16=EH12,ER12,ER13))))))))))) -> 2 | FE16: =EU16+EU17+EU18+EU19+EU20+EU21 -> 11 | FF16: =EV16+EV17+EV18+EV19+EV20+EV21 -> 14 | FG16: =EW16+EW17+EW18+EW19+EW20+EW21 -> 9 | FH16: =EX16+EX17+EX18+EX19+EX20+EX21 -> 11 | FI16: =EY16+EY17+EY18+EY19+EY20+EY21 -> 11 | FJ16: =EZ16+EZ17+EZ18+EZ19+EZ20+EZ21 -> 10 | FK16: =FA16+FA17+FA18+FA19+FA20+FA21 -> 11 | FL16: =FB16+FB17+FB18+FB19+FB20+FB21 -> 10 | ... FN16: =FD16+FD17+FD18+FD19+FD20+FD21 -> 15 | FO16: =SUM(FE16:FN16) -> 117
F17: Soil Type | G17: Clay | EH17: Rock | EI17: =Guidelines!C36 -> 2 | EJ17: =Guidelines!D36 -> 2 | EK17: =Guidelines!E36 -> 3 | EL17: =Guidelines!F36 -> 1 | EM17: =Guidelines!G36 -> 1 | EN17: =Guidelines!H36 -> 3 | EO17: =Guidelines!I36 -> 1 | EP17: =Guidelines!J36 -> 1 | ... ER17: =Guidelines!L36 -> 3 | EU17: =IF(G17=EH14,EI14,IF(G17=EH15,EI15,IF(G17=EH16,EI16,IF(G17=EH17,EI17,EI18)))) -> 2 | EV17: =IF(G17=EH14,EJ14,IF(G17=EH15,EJ15,IF(G17=EH16,EJ16,IF(G17=EH17,EJ17,EJ18)))) -> 3 | EW17: =IF(G17=EH14,EK14,IF(G17=EH15,EK15,IF(G17=EH16,EK16,IF(G17=EH17,EK17,EK18)))) -> 2 | EX17: =IF(G17=EH14,EL14,IF(G17=EH15,EL15,IF(G17=EH16,EL16,IF(G17=EH17,EL17,EL18)))) -> 3 | EY17: =IF(G17=EH14,EM14,IF(G17=EH15,EM15,IF(G17=EH16,EM16,IF(G17=EH17,EM17,EM18)))) -> 3 | EZ17: =IF(G17=EH14,EN14,IF(G17=EH15,EN15,IF(G17=EH16,EN16,IF(G17=EH17,EN17,EN18)))) -> 2 | FA17: =IF(G17=EH14,EO14,IF(G17=EH15,EO15,IF(G17=EH16,EO16,IF(G17=EH17,EO17,EO18)))) -> 2 | FB17: =IF(G17=EH14,EP14,IF(G17=EH15,EP15,IF(G17=EH16,EP16,IF(G17=EH17,EP17,EP18)))) -> 1 | FC17: =IF(G17=EH14,EQ14,IF(G17=EH15,EQ15,IF(G17=EH16,EQ16,IF(G17=EH17,EQ17,EQ18)))) -> 3 | FD17: =IF(G17=EH14,ER14,IF(G17=EH15,ER15,IF(G17=EH16,ER16,IF(G17=EH17,ER17,ER18)))) -> 3 | FO17: =SUM(FE17:FN17) -> 0
F18: Land Cover | G18: Water-bodies | H18: MEDIUM | U18: MEDIUM | EH18: Select here | EI18: =Guidelines!C37 -> 0 | EJ18: =Guidelines!D37 -> 0 | EK18: =Guidelines!E37 -> 0 | EL18: =Guidelines!F37 -> 0 | EM18: =Guidelines!G37 -> 0 | EN18: =Guidelines!H37 -> 0 | EO18: =Guidelines!I37 -> 0 | EP18: =Guidelines!J37 -> 0 | ... ER18: =Guidelines!L37 -> 0 | EU18: =IF(G18=EH19,EI19,IF(G18=EH20,EI20,IF(G18=EH21,EI21,IF(G18=EH22,EI22,EI23)))) -> 2 | EV18: =IF(G18=EH19,EJ19,IF(G18=EH20,EJ20,IF(G18=EH21,EJ21,IF(G18=EH22,EJ22,EJ23)))) -> 3 | EW18: =IF(G18=EH19,EK19,IF(G18=EH20,EK20,IF(G18=EH21,EK21,IF(G18=EH22,EK22,EK23)))) -> 2 | EX18: =IF(G18=EH19,EL19,IF(G18=EH20,EL20,IF(G18=EH21,EL21,IF(G18=EH22,EL22,EL23)))) -> 1 | EY18: =IF(G18=EH19,EM19,IF(G18=EH20,EM20,IF(G18=EH21,EM21,IF(G18=EH22,EM22,EM23)))) -> 1 | EZ18: =IF(G18=EH19,EN19,IF(G18=EH20,EN20,IF(G18=EH21,EN21,IF(G18=EH22,EN22,EN23)))) -> 1 | FA18: =IF(G18=EH19,EO19,IF(G18=EH20,EO20,IF(G18=EH21,EO21,IF(G18=EH22,EO22,EO23)))) -> 2 | FB18: =IF(G18=EH19,EP19,IF(G18=EH20,EP20,IF(G18=EH21,EP21,IF(G18=EH22,EP22,EP23)))) -> 3 | FC18: =IF(G18=EH19,EQ19,IF(G18=EH20,EQ20,IF(G18=EH21,EQ21,IF(G18=EH22,EQ22,EQ23)))) -> 3 | FD18: =IF(G18=EH19,ER19,IF(G18=EH20,ER20,IF(G18=EH21,ER21,IF(G18=EH22,ER22,ER23)))) -> 3 | FO18: =SUM(FE18:FN18) -> 0
F19: Altitude | G19: >1800 | EH19: Bare Land | EI19: =Guidelines!C38 -> 3 | EJ19: =Guidelines!D38 -> 1 | EK19: =Guidelines!E38 -> 3 | EL19: =Guidelines!F38 -> 3 | EM19: =Guidelines!G38 -> 3 | EN19: =Guidelines!H38 -> 3 | EO19: =Guidelines!I38 -> 3 | EP19: =Guidelines!J38 -> 1 | ... ER19: =Guidelines!L38 -> 3 | EU19: =IF(G19=EH24,EI24,IF(G19=EH25,EI25,IF(G19=EH26,EI26,EI27))) -> 2 | EV19: =IF(G19=EH24,EJ24,IF(G19=EH25,EJ25,IF(G19=EH26,EJ26,EJ27))) -> 1 | EW19: =IF(G19=EH24,EK24,IF(G19=EH25,EK25,IF(G19=EH26,EK26,EK27))) -> 1 | EX19: =IF(G19=EH24,EL24,IF(G19=EH25,EL25,IF(G19=EH26,EL26,EL27))) -> 1 | EY19: =IF(G19=EH24,EM24,IF(G19=EH25,EM25,IF(G19=EH26,EM26,EM27))) -> 1 | EZ19: =IF(G19=EH24,EN24,IF(G19=EH25,EN25,IF(G19=EH26,EN26,EN27))) -> 1 | FA19: =IF(G19=EH24,EO24,IF(G19=EH25,EO25,IF(G19=EH26,EO26,EO27))) -> 1 | FB19: =IF(G19=EH24,EP24,IF(G19=EH25,EP25,IF(G19=EH26,EP26,EP27))) -> 1 | FC19: =IF(G19=EH24,EQ24,IF(G19=EH25,EQ25,IF(G19=EH26,EQ26,EQ27))) -> 1 | FD19: =IF(G19=EH24,ER24,IF(G19=EH25,ER25,IF(G19=EH26,ER26,ER27))) -> 1 | FO19: =SUM(FE19:FN19) -> 0
F20: Proximity to Major River | G20: <2000 | H20: HIGH | U20: HIGH | EH20: Natural Terrestrial Vegetation | EI20: =Guidelines!C39 -> 1 | EJ20: =Guidelines!D39 -> 3 | EK20: =Guidelines!E39 -> 1 | EL20: =Guidelines!F39 -> 1 | EM20: =Guidelines!G39 -> 1 | EN20: =Guidelines!H39 -> 1 | EO20: =Guidelines!I39 -> 2 | EP20: =Guidelines!J39 -> 3 | ... ER20: =Guidelines!L39 -> 1 | EU20: =IF(G20=EH28,EI28,IF(G20=EH29,EI29,IF(G20=EH30,EI30,EI31))) -> 2 | EV20: =IF(G20=EH28,EJ28,IF(G20=EH29,EJ29,IF(G20=EH30,EJ30,EJ31))) -> 3 | EW20: =IF(G20=EH28,EK28,IF(G20=EH29,EK29,IF(G20=EH30,EK30,EK31))) -> 1 | EX20: =IF(G20=EH28,EL28,IF(G20=EH29,EL29,IF(G20=EH30,EL30,EL31))) -> 2 | EY20: =IF(G20=EH28,EM28,IF(G20=EH29,EM29,IF(G20=EH30,EM30,EM31))) -> 2 | EZ20: =IF(G20=EH28,EN28,IF(G20=EH29,EN29,IF(G20=EH30,EN30,EN31))) -> 2 | FA20: =IF(G20=EH28,EO28,IF(G20=EH29,EO29,IF(G20=EH30,EO30,EO31))) -> 2 | FB20: =IF(G20=EH28,EP28,IF(G20=EH29,EP29,IF(G20=EH30,EP30,EP31))) -> 2 | FC20: =IF(G20=EH28,EQ28,IF(G20=EH29,EQ29,IF(G20=EH30,EP30,EQ31))) -> 3 | FD20: =IF(G20=EH28,ER28,IF(G20=EH29,ER29,IF(G20=EH30,ER30,ER31))) -> 3 | FO20: =SUM(FE20:FN20) -> 0
F21: Proximity to Flood Plain | G21: <4500 | EH21: Agricultural Land | EI21: =Guidelines!C40 -> 2 | EJ21: =Guidelines!D40 -> 2 | EK21: =Guidelines!E40 -> 2 | EL21: =Guidelines!F40 -> 2 | EM21: =Guidelines!G40 -> 2 | EN21: =Guidelines!H40 -> 2 | EO21: =Guidelines!I40 -> 2 | EP21: =Guidelines!J40 -> 2 | ... ER21: =Guidelines!L40 -> 2 | EU21: =IF(G21=EH32,EI32,IF(G21=EH33,EI33,IF(G21=EH34,EI34,EI35))) -> 1 | EV21: =IF(G21=EH32,EJ32,IF(G21=EH33,EJ33,IF(G21=EH34,EJ34,EJ35))) -> 2 | EW21: =IF(G21=EH32,EK32,IF(G21=EH33,EK33,IF(G21=EH34,EK34,EK35))) -> 1 | EX21: =IF(G21=EH32,EL32,IF(G21=EH33,EL33,IF(G21=EH34,EL34,EL35))) -> 2 | EY21: =IF(G21=EH32,EM32,IF(G21=EH33,EM33,IF(G21=EH34,EM34,EM35))) -> 2 | EZ21: =IF(G21=EH32,EN32,IF(G21=EH33,EN33,IF(G21=EH34,EN34,EN35))) -> 2 | FA21: =IF(G21=EH32,EO32,IF(G21=EH33,EO33,IF(G21=EH34,EO34,EO35))) -> 2 | FB21: =IF(G21=EH32,EP32,IF(G21=EH33,EP33,IF(G21=EH34,EP34,EP35))) -> 1 | FC21: =IF(G21=EH32,EQ32,IF(G21=EH33,EQ33,IF(G21=EH34,EQ34,EQ35))) -> 3 | FD21: =IF(G21=EH32,ER32,IF(G21=EH33,ER33,IF(G21=EH34,ER34,ER35))) -> 3 | FO21: =SUM(FE21:FN21) -> 0
A22: County Code | B22: County | C22: Settlement | D22: Latitude | E22: Longitude | F22: Main Attributes | G22: Attributes | H22: LEGEND | I22: Temperature | J22: Rainfall | K22: Drought | L22: Soil Erotion | M22: Land Slide | N22: Food Insecuriy | O22: Pollution | P22: Moisture Content | Q22: Flash Floods | R22: Flooding | T22: Total Score | U22: LEGEND | EH22: Water-bodies | EI22: =Guidelines!C41 -> 2 | EJ22: =Guidelines!D41 -> 3 | EK22: =Guidelines!E41 -> 2 | EL22: =Guidelines!F41 -> 1 | EM22: =Guidelines!G41 -> 1 | EN22: =Guidelines!H41 -> 1 | EO22: =Guidelines!I41 -> 2 | EP22: =Guidelines!J41 -> 3 | ... ER22: =Guidelines!L41 -> 3 | FO22: =SUM(FE22:FN22) -> 0
A23: 032 | B23: Nakuru | C23: Crater Lake Nakuru | D23: -0.759838° | E23: 36.235599° | F23: Climate Region | G23: Cfb> Temperate | H23: LOW | I23: =FE23 -> 11 | J23: =FF23 -> 14 | K23: =FG23 -> 9 | L23: =FH23 -> 10 | M23: =FI23 -> 9 | N23: =FJ23 -> 11 | O23: =FK23 -> 10 | P23: =FL23 -> 12 | ... R23: =FN23 -> 11 | T23: =$FO$23 -> 108 | U23: LOW | EH23: Select here | EI23: =Guidelines!C42 -> 0 | EJ23: =Guidelines!D42 -> 0 | EK23: =Guidelines!E42 -> 0 | EL23: =Guidelines!F42 -> 0 | EM23: =Guidelines!G42 -> 0 | EN23: =Guidelines!H42 -> 0 | EO23: =Guidelines!I42 -> 0 | EP23: =Guidelines!J42 -> 0 | ... ER23: =Guidelines!L42 -> 0 | EU23: =IF(G23=EH2,EI2,IF(G23=EH3,EI3,IF(G23=EH4,EI4,IF(G23=EH5,EI5,IF(G23=EH6,EI6,IF(G23=EH7,EI7,IF(G23=EH8,EI8,IF(G23=EH9,EI9,IF(G23=EH10,EI10,IF(G23=EH11,EI11,IF(G23=EH12,EI12,EI13))))))))))) -> 2 | EV23: =IF(G23=EH2,EJ2,IF(G23=EH3,EJ3,IF(G23=EH4,EJ4,IF(G23=EH5,EJ5,IF(G23=EH6,EJ6,IF(G23=EH7,EJ7,IF(G23=EH8,EJ8,IF(G23=EH9,EJ9,IF(G23=EH10,EJ10,IF(G23=EH11,EJ11,IF(G23=EH12,EJ12,EJ13))))))))))) -> 3 | EW23: =IF(G23=EH2,EK2,IF(G23=EH3,EK3,IF(G23=EH4,EK4,IF(G23=EH5,EK5,IF(G23=EH6,EK6,IF(G23=EH7,EK7,IF(G23=EH8,EK8,IF(G23=EH9,EK9,IF(G23=EH10,EK10,IF(G23=EH11,EK11,IF(G23=EH12,EK12,EK13))))))))))) -> 2 | EX23: =IF(G23=EH2,EL2,IF(G23=EH3,EL3,IF(G23=EH4,EL4,IF(G23=EH5,EL5,IF(G23=EH6,EL6,IF(G23=EH7,EL7,IF(G23=EH8,EL8,IF(G23=EH9,EL9,IF(G23=EH10,EL10,IF(G23=EH11,EL11,IF(G23=EH12,EL12,EL13))))))))))) -> 2 | EY23: =IF(G23=EH2,EM2,IF(G23=EH3,EM3,IF(G23=EH4,EM4,IF(G23=EH5,EM5,IF(G23=EH6,EM6,IF(G23=EH7,EM7,IF(G23=EH8,EM8,IF(G23=EH9,EM9,IF(G23=EH10,EM10,IF(G23=EH11,EM11,IF(G23=EH12,EM12,EM13))))))))))) -> 2 | EZ23: =IF(G23=EH2,EN2,IF(G23=EH3,EN3,IF(G23=EH4,EN4,IF(G23=EH5,EN5,IF(G23=EH6,EN6,IF(G23=EH7,EN7,IF(G23=EH8,EN8,IF(G23=EH9,EN9,IF(G23=EH10,EN10,IF(G23=EH11,EN11,IF(G23=EH12,EN12,EN13))))))))))) -> 2 | FA23: =IF(G23=EH2,EO2,IF(G23=EH3,EO3,IF(G23=EH4,EO4,IF(G23=EH5,EO5,IF(G23=EH6,EO6,IF(G23=EH7,EO7,IF(G23=EH8,EO8,IF(G23=EH9,EO9,IF(G23=EH10,EO10,IF(G23=EH11,EO11,IF(G23=EH12,EO12,EO13))))))))))) -> 2 | FB23: =IF(G23=EH2,EP2,IF(G23=EH3,EP3,IF(G23=EH4,EP4,IF(G23=EH5,EP5,IF(G23=EH6,EP6,IF(G23=EH7,EP7,IF(G23=EH8,EP8,IF(G23=EH9,EP9,IF(G23=EH10,EP10,IF(G23=EH11,EP11,IF(G23=EH12,EP12,EP13))))))))))) -> 2 | FC23: =IF(G23=EH2,EQ2,IF(G23=EH3,EQ3,IF(G23=EH4,EQ4,IF(G23=EH5,EQ5,IF(G23=EH6,EQ6,IF(G23=EH7,EQ7,IF(G23=EH8,EQ8,IF(G23=EH9,EQ9,IF(G23=EH10,EQ10,IF(G23=EH11,EQ11,IF(G23=EH12,EQ12,EQ13))))))))))) -> 2 | FD23: =IF(G23=EH2,ER2,IF(G23=EH3,ER3,IF(G23=EH4,ER4,IF(G23=EH5,ER5,IF(G23=EH6,ER6,IF(G23=EH7,ER7,IF(G23=EH8,ER8,IF(G23=EH9,ER9,IF(G23=EH10,ER10,IF(G23=EH11,ER11,IF(G23=EH12,ER12,ER13))))))))))) -> 2 | FE23: =EU23+EU24+EU25+EU26+EU27+EU28 -> 11 | FF23: =EV23+EV24+EV25+EV26+EV27+EV28 -> 14 | FG23: =EW23+EW24+EW25+EW26+EW27+EW28 -> 9 | FH23: =EX23+EX24+EX25+EX26+EX27+EX28 -> 10 | FI23: =EY23+EY24+EY25+EY26+EY27+EY28 -> 9 | FJ23: =EZ23+EZ24+EZ25+EZ26+EZ27+EZ28 -> 11 | FK23: =FA23+FA24+FA25+FA26+FA27+FA28 -> 10 | FL23: =FB23+FB24+FB25+FB26+FB27+FB28 -> 12 | ... FN23: =FD23+FD24+FD25+FD26+FD27+FD28 -> 11 | FO23: =SUM(FE23:FN23) -> 108
F24: Soil Type | G24: Sand | EH24: <750 | EI24: =Guidelines!C43 -> 2 | EJ24: =Guidelines!D43 -> 3 | EK24: =Guidelines!E43 -> 3 | EL24: =Guidelines!F43 -> 2 | EM24: =Guidelines!G43 -> 2 | EN24: =Guidelines!H43 -> 2 | EO24: =Guidelines!I43 -> 3 | EP24: =Guidelines!J43 -> 2 | ... ER24: =Guidelines!L43 -> 3 | EU24: =IF(G24=EH14,EI14,IF(G24=EH15,EI15,IF(G24=EH16,EI16,IF(G24=EH17,EI17,EI18)))) -> 3 | EV24: =IF(G24=EH14,EJ14,IF(G24=EH15,EJ15,IF(G24=EH16,EJ16,IF(G24=EH17,EJ17,EJ18)))) -> 2 | EW24: =IF(G24=EH14,EK14,IF(G24=EH15,EK15,IF(G24=EH16,EK16,IF(G24=EH17,EK17,EK18)))) -> 3 | EX24: =IF(G24=EH14,EL14,IF(G24=EH15,EL15,IF(G24=EH16,EL16,IF(G24=EH17,EL17,EL18)))) -> 2 | EY24: =IF(G24=EH14,EM14,IF(G24=EH15,EM15,IF(G24=EH16,EM16,IF(G24=EH17,EM17,EM18)))) -> 1 | EZ24: =IF(G24=EH14,EN14,IF(G24=EH15,EN15,IF(G24=EH16,EN16,IF(G24=EH17,EN17,EN18)))) -> 3 | FA24: =IF(G24=EH14,EO14,IF(G24=EH15,EO15,IF(G24=EH16,EO16,IF(G24=EH17,EO17,EO18)))) -> 1 | FB24: =IF(G24=EH14,EP14,IF(G24=EH15,EP15,IF(G24=EH16,EP16,IF(G24=EH17,EP17,EP18)))) -> 3 | FC24: =IF(G24=EH14,EQ14,IF(G24=EH15,EQ15,IF(G24=EH16,EQ16,IF(G24=EH17,EQ17,EQ18)))) -> 1 | FD24: =IF(G24=EH14,ER14,IF(G24=EH15,ER15,IF(G24=EH16,ER16,IF(G24=EH17,ER17,ER18)))) -> 1 | FO24: =SUM(FE24:FN24) -> 0
F25: Land Cover | G25: Natural Terrestrial Vegetation | H25: MEDIUM | U25: MEDIUM | EH25: Between 751-1800 | EI25: =Guidelines!C44 -> 1 | EJ25: =Guidelines!D44 -> 2 | EK25: =Guidelines!E44 -> 2 | EL25: =Guidelines!F44 -> 3 | EM25: =Guidelines!G44 -> 3 | EN25: =Guidelines!H44 -> 2 | EO25: =Guidelines!I44 -> 2 | EP25: =Guidelines!J44 -> 2 | ... ER25: =Guidelines!L44 -> 1 | EU25: =IF(G25=EH19,EI19,IF(G25=EH20,EI20,IF(G25=EH21,EI21,IF(G25=EH22,EI22,EI23)))) -> 1 | EV25: =IF(G25=EH19,EJ19,IF(G25=EH20,EJ20,IF(G25=EH21,EJ21,IF(G25=EH22,EJ22,EJ23)))) -> 3 | EW25: =IF(G25=EH19,EK19,IF(G25=EH20,EK20,IF(G25=EH21,EK21,IF(G25=EH22,EK22,EK23)))) -> 1 | EX25: =IF(G25=EH19,EL19,IF(G25=EH20,EL20,IF(G25=EH21,EL21,IF(G25=EH22,EL22,EL23)))) -> 1 | EY25: =IF(G25=EH19,EM19,IF(G25=EH20,EM20,IF(G25=EH21,EM21,IF(G25=EH22,EM22,EM23)))) -> 1 | EZ25: =IF(G25=EH19,EN19,IF(G25=EH20,EN20,IF(G25=EH21,EN21,IF(G25=EH22,EN22,EN23)))) -> 1 | FA25: =IF(G25=EH19,EO19,IF(G25=EH20,EO20,IF(G25=EH21,EO21,IF(G25=EH22,EO22,EO23)))) -> 2 | FB25: =IF(G25=EH19,EP19,IF(G25=EH20,EP20,IF(G25=EH21,EP21,IF(G25=EH22,EP22,EP23)))) -> 3 | FC25: =IF(G25=EH19,EQ19,IF(G25=EH20,EQ20,IF(G25=EH21,EQ21,IF(G25=EH22,EQ22,EQ23)))) -> 1 | FD25: =IF(G25=EH19,ER19,IF(G25=EH20,ER20,IF(G25=EH21,ER21,IF(G25=EH22,ER22,ER23)))) -> 1 | FO25: =SUM(FE25:FN25) -> 0
F26: Altitude | G26: >1800 | EH26: >1800 | EI26: =Guidelines!C45 -> 2 | EJ26: =Guidelines!D45 -> 1 | EK26: =Guidelines!E45 -> 1 | EL26: =Guidelines!F45 -> 1 | EM26: =Guidelines!G45 -> 1 | EN26: =Guidelines!H45 -> 1 | EO26: =Guidelines!I45 -> 1 | EP26: =Guidelines!J45 -> 1 | ... ER26: =Guidelines!L45 -> 1 | EU26: =IF(G26=EH24,EI24,IF(G26=EH25,EI25,IF(G26=EH26,EI26,EI27))) -> 2 | EV26: =IF(G26=EH24,EJ24,IF(G26=EH25,EJ25,IF(G26=EH26,EJ26,EJ27))) -> 1 | EW26: =IF(G26=EH24,EK24,IF(G26=EH25,EK25,IF(G26=EH26,EK26,EK27))) -> 1 | EX26: =IF(G26=EH24,EL24,IF(G26=EH25,EL25,IF(G26=EH26,EL26,EL27))) -> 1 | EY26: =IF(G26=EH24,EM24,IF(G26=EH25,EM25,IF(G26=EH26,EM26,EM27))) -> 1 | EZ26: =IF(G26=EH24,EN24,IF(G26=EH25,EN25,IF(G26=EH26,EN26,EN27))) -> 1 | FA26: =IF(G26=EH24,EO24,IF(G26=EH25,EO25,IF(G26=EH26,EO26,EO27))) -> 1 | FB26: =IF(G26=EH24,EP24,IF(G26=EH25,EP25,IF(G26=EH26,EP26,EP27))) -> 1 | FC26: =IF(G26=EH24,EQ24,IF(G26=EH25,EQ25,IF(G26=EH26,EQ26,EQ27))) -> 1 | FD26: =IF(G26=EH24,ER24,IF(G26=EH25,ER25,IF(G26=EH26,ER26,ER27))) -> 1 | FO26: =SUM(FE26:FN26) -> 0
F27: Proximity to Major River | G27: <2000 | H27: HIGH | U27: HIGH | EH27: Select here | EI27: =Guidelines!C46 -> 0 | EJ27: =Guidelines!D46 -> 0 | EK27: =Guidelines!E46 -> 0 | EL27: =Guidelines!F46 -> 0 | EM27: =Guidelines!G46 -> 0 | EN27: =Guidelines!H46 -> 0 | EO27: =Guidelines!I46 -> 0 | EP27: =Guidelines!J46 -> 0 | ... ER27: =Guidelines!L46 -> 0 | EU27: =IF(G27=EH28,EI28,IF(G27=EH29,EI29,IF(G27=EH30,EI30,EI31))) -> 2 | EV27: =IF(G27=EH28,EJ28,IF(G27=EH29,EJ29,IF(G27=EH30,EJ30,EJ31))) -> 3 | EW27: =IF(G27=EH28,EK28,IF(G27=EH29,EK29,IF(G27=EH30,EK30,EK31))) -> 1 | EX27: =IF(G27=EH28,EL28,IF(G27=EH29,EL29,IF(G27=EH30,EL30,EL31))) -> 2 | EY27: =IF(G27=EH28,EM28,IF(G27=EH29,EM29,IF(G27=EH30,EM30,EM31))) -> 2 | EZ27: =IF(G27=EH28,EN28,IF(G27=EH29,EN29,IF(G27=EH30,EN30,EN31))) -> 2 | FA27: =IF(G27=EH28,EO28,IF(G27=EH29,EO29,IF(G27=EH30,EO30,EO31))) -> 2 | FB27: =IF(G27=EH28,EP28,IF(G27=EH29,EP29,IF(G27=EH30,EP30,EP31))) -> 2 | FC27: =IF(G27=EH28,EQ28,IF(G27=EH29,EQ29,IF(G27=EH30,EP30,EQ31))) -> 3 | FD27: =IF(G27=EH28,ER28,IF(G27=EH29,ER29,IF(G27=EH30,ER30,ER31))) -> 3 | FO27: =SUM(FE27:FN27) -> 0
F28: Proximity to Flood Plain | G28: <4500 | EH28: <2000 | EI28: =Guidelines!C47 -> 2 | EJ28: =Guidelines!D47 -> 3 | EK28: =Guidelines!E47 -> 1 | EL28: =Guidelines!F47 -> 2 | EM28: =Guidelines!G47 -> 2 | EN28: =Guidelines!H47 -> 2 | EO28: =Guidelines!I47 -> 2 | EP28: =Guidelines!J47 -> 2 | ... ER28: =Guidelines!L47 -> 3 | EU28: =IF(G28=EH32,EI32,IF(G28=EH33,EI33,IF(G28=EH34,EI34,EI35))) -> 1 | EV28: =IF(G28=EH32,EJ32,IF(G28=EH33,EJ33,IF(G28=EH34,EJ34,EJ35))) -> 2 | EW28: =IF(G28=EH32,EK32,IF(G28=EH33,EK33,IF(G28=EH34,EK34,EK35))) -> 1 | EX28: =IF(G28=EH32,EL32,IF(G28=EH33,EL33,IF(G28=EH34,EL34,EL35))) -> 2 | EY28: =IF(G28=EH32,EM32,IF(G28=EH33,EM33,IF(G28=EH34,EM34,EM35))) -> 2 | EZ28: =IF(G28=EH32,EN32,IF(G28=EH33,EN33,IF(G28=EH34,EN34,EN35))) -> 2 | FA28: =IF(G28=EH32,EO32,IF(G28=EH33,EO33,IF(G28=EH34,EO34,EO35))) -> 2 | FB28: =IF(G28=EH32,EP32,IF(G28=EH33,EP33,IF(G28=EH34,EP34,EP35))) -> 1 | FC28: =IF(G28=EH32,EQ32,IF(G28=EH33,EQ33,IF(G28=EH34,EQ34,EQ35))) -> 3 | FD28: =IF(G28=EH32,ER32,IF(G28=EH33,ER33,IF(G28=EH34,ER34,ER35))) -> 3 | FO28: =SUM(FE28:FN28) -> 0
A29: County Code | B29: County | C29: Settlement | D29: Latitude | E29: Longitude | F29: Main Attributes | G29: Attributes | H29: LEGEND | I29: Temperature | J29: Rainfall | K29: Drought | L29: Soil Erotion | M29: Land Slide | N29: Food Insecuriy | O29: Pollution | P29: Moisture Content | Q29: Flash Floods | R29: Flooding | T29: Total Score | U29: LEGEND | EH29: Between 2001-5999 | EI29: =Guidelines!C48 -> 2 | EJ29: =Guidelines!D48 -> 2 | EK29: =Guidelines!E48 -> 2 | EL29: =Guidelines!F48 -> 2 | EM29: =Guidelines!G48 -> 2 | EN29: =Guidelines!H48 -> 2 | EO29: =Guidelines!I48 -> 2 | EP29: =Guidelines!J48 -> 2 | ... ER29: =Guidelines!L48 -> 2 | FO29: =SUM(FE29:FN29) -> 0
A30: 012 | B30: Meru | C30: Mjini | D30: 0.049487° | E30: 37.653833° | F30: Climate Region | G30: Af>Tropical | H30: LOW | I30: =FE30 -> 12 | J30: =FF30 -> 13 | K30: =FG30 -> 10 | L30: =FH30 -> 14 | M30: =FI30 -> 14 | N30: =FJ30 -> 13 | O30: =FK30 -> 13 | P30: =FL30 -> 10 | ... R30: =FN30 -> 14 | T30: =$FO$30 -> 129 | U30: LOW | EH30: >6000 | EI30: =Guidelines!C49 -> 1 | EJ30: =Guidelines!D49 -> 1 | EK30: =Guidelines!E49 -> 3 | EL30: =Guidelines!F49 -> 1 | EM30: =Guidelines!G49 -> 1 | EN30: =Guidelines!H49 -> 1 | EO30: =Guidelines!I49 -> 1 | EP30: =Guidelines!J49 -> 1 | ... ER30: =Guidelines!L49 -> 1 | EU30: =IF(G30=EH2,EI2,IF(G30=EH3,EI3,IF(G30=EH4,EI4,IF(G30=EH5,EI5,IF(G30=EH6,EI6,IF(G30=EH7,EI7,IF(G30=EH8,EI8,IF(G30=EH9,EI9,IF(G30=EH10,EI10,IF(G30=EH11,EI11,IF(G30=EH12,EI12,EI13))))))))))) -> 3 | EV30: =IF(G30=EH2,EJ2,IF(G30=EH3,EJ3,IF(G30=EH4,EJ4,IF(G30=EH5,EJ5,IF(G30=EH6,EJ6,IF(G30=EH7,EJ7,IF(G30=EH8,EJ8,IF(G30=EH9,EJ9,IF(G30=EH10,EJ10,IF(G30=EH11,EJ11,IF(G30=EH12,EJ12,EJ13))))))))))) -> 2 | EW30: =IF(G30=EH2,EK2,IF(G30=EH3,EK3,IF(G30=EH4,EK4,IF(G30=EH5,EK5,IF(G30=EH6,EK6,IF(G30=EH7,EK7,IF(G30=EH8,EK8,IF(G30=EH9,EK9,IF(G30=EH10,EK10,IF(G30=EH11,EK11,IF(G30=EH12,EK12,EK13))))))))))) -> 1 | EX30: =IF(G30=EH2,EL2,IF(G30=EH3,EL3,IF(G30=EH4,EL4,IF(G30=EH5,EL5,IF(G30=EH6,EL6,IF(G30=EH7,EL7,IF(G30=EH8,EL8,IF(G30=EH9,EL9,IF(G30=EH10,EL10,IF(G30=EH11,EL11,IF(G30=EH12,EL12,EL13))))))))))) -> 1 | EY30: =IF(G30=EH2,EM2,IF(G30=EH3,EM3,IF(G30=EH4,EM4,IF(G30=EH5,EM5,IF(G30=EH6,EM6,IF(G30=EH7,EM7,IF(G30=EH8,EM8,IF(G30=EH9,EM9,IF(G30=EH10,EM10,IF(G30=EH11,EM11,IF(G30=EH12,EM12,EM13))))))))))) -> 1 | EZ30: =IF(G30=EH2,EN2,IF(G30=EH3,EN3,IF(G30=EH4,EN4,IF(G30=EH5,EN5,IF(G30=EH6,EN6,IF(G30=EH7,EN7,IF(G30=EH8,EN8,IF(G30=EH9,EN9,IF(G30=EH10,EN10,IF(G30=EH11,EN11,IF(G30=EH12,EN12,EN13))))))))))) -> 2 | FA30: =IF(G30=EH2,EO2,IF(G30=EH3,EO3,IF(G30=EH4,EO4,IF(G30=EH5,EO5,IF(G30=EH6,EO6,IF(G30=EH7,EO7,IF(G30=EH8,EO8,IF(G30=EH9,EO9,IF(G30=EH10,EO10,IF(G30=EH11,EO11,IF(G30=EH12,EO12,EO13))))))))))) -> 2 | FB30: =IF(G30=EH2,EP2,IF(G30=EH3,EP3,IF(G30=EH4,EP4,IF(G30=EH5,EP5,IF(G30=EH6,EP6,IF(G30=EH7,EP7,IF(G30=EH8,EP8,IF(G30=EH9,EP9,IF(G30=EH10,EP10,IF(G30=EH11,EP11,IF(G30=EH12,EP12,EP13))))))))))) -> 3 | FC30: =IF(G30=EH2,EQ2,IF(G30=EH3,EQ3,IF(G30=EH4,EQ4,IF(G30=EH5,EQ5,IF(G30=EH6,EQ6,IF(G30=EH7,EQ7,IF(G30=EH8,EQ8,IF(G30=EH9,EQ9,IF(G30=EH10,EQ10,IF(G30=EH11,EQ11,IF(G30=EH12,EQ12,EQ13))))))))))) -> 1 | FD30: =IF(G30=EH2,ER2,IF(G30=EH3,ER3,IF(G30=EH4,ER4,IF(G30=EH5,ER5,IF(G30=EH6,ER6,IF(G30=EH7,ER7,IF(G30=EH8,ER8,IF(G30=EH9,ER9,IF(G30=EH10,ER10,IF(G30=EH11,ER11,IF(G30=EH12,ER12,ER13))))))))))) -> 1 | FE30: =EU30+EU31+EU32+EU33+EU34+EU35 -> 12 | FF30: =EV30+EV31+EV32+EV33+EV34+EV35 -> 13 | FG30: =EW30+EW31+EW32+EW33+EW34+EW35 -> 10 | FH30: =EX30+EX31+EX32+EX33+EX34+EX35 -> 14 | FI30: =EY30+EY31+EY32+EY33+EY34+EY35 -> 14 | FJ30: =EZ30+EZ31+EZ32+EZ33+EZ34+EZ35 -> 13 | FK30: =FA30+FA31+FA32+FA33+FA34+FA35 -> 13 | FL30: =FB30+FB31+FB32+FB33+FB34+FB35 -> 10 | ... FN30: =FD30+FD31+FD32+FD33+FD34+FD35 -> 14 | FO30: =SUM(FE30:FN30) -> 129
F31: Soil Type | G31: Clay | EH31: Select here | EI31: =Guidelines!C50 -> 0 | EJ31: =Guidelines!D50 -> 0 | EK31: =Guidelines!E50 -> 0 | EL31: =Guidelines!F50 -> 0 | EM31: =Guidelines!G50 -> 0 | EN31: =Guidelines!H50 -> 0 | EO31: =Guidelines!I50 -> 0 | EP31: =Guidelines!J50 -> 0 | ... ER31: =Guidelines!L50 -> 0 | EU31: =IF(G31=EH14,EI14,IF(G31=EH15,EI15,IF(G31=EH16,EI16,IF(G31=EH17,EI17,EI18)))) -> 2 | EV31: =IF(G31=EH14,EJ14,IF(G31=EH15,EJ15,IF(G31=EH16,EJ16,IF(G31=EH17,EJ17,EJ18)))) -> 3 | EW31: =IF(G31=EH14,EK14,IF(G31=EH15,EK15,IF(G31=EH16,EK16,IF(G31=EH17,EK17,EK18)))) -> 2 | EX31: =IF(G31=EH14,EL14,IF(G31=EH15,EL15,IF(G31=EH16,EL16,IF(G31=EH17,EL17,EL18)))) -> 3 | EY31: =IF(G31=EH14,EM14,IF(G31=EH15,EM15,IF(G31=EH16,EM16,IF(G31=EH17,EM17,EM18)))) -> 3 | EZ31: =IF(G31=EH14,EN14,IF(G31=EH15,EN15,IF(G31=EH16,EN16,IF(G31=EH17,EN17,EN18)))) -> 2 | FA31: =IF(G31=EH14,EO14,IF(G31=EH15,EO15,IF(G31=EH16,EO16,IF(G31=EH17,EO17,EO18)))) -> 2 | FB31: =IF(G31=EH14,EP14,IF(G31=EH15,EP15,IF(G31=EH16,EP16,IF(G31=EH17,EP17,EP18)))) -> 1 | FC31: =IF(G31=EH14,EQ14,IF(G31=EH15,EQ15,IF(G31=EH16,EQ16,IF(G31=EH17,EQ17,EQ18)))) -> 3 | FD31: =IF(G31=EH14,ER14,IF(G31=EH15,ER15,IF(G31=EH16,ER16,IF(G31=EH17,ER17,ER18)))) -> 3 | FO31: =SUM(FE31:FN31) -> 0
F32: Land Cover | G32: Bare Land | H32: MEDIUM | U32: MEDIUM | EH32: <4500 | EI32: =Guidelines!C51 -> 1 | EJ32: =Guidelines!D51 -> 2 | EK32: =Guidelines!E51 -> 1 | EL32: =Guidelines!F51 -> 2 | EM32: =Guidelines!G51 -> 2 | EN32: =Guidelines!H51 -> 2 | EO32: =Guidelines!I51 -> 2 | EP32: =Guidelines!J51 -> 1 | ... ER32: =Guidelines!L51 -> 3 | EU32: =IF(G32=EH19,EI19,IF(G32=EH20,EI20,IF(G32=EH21,EI21,IF(G32=EH22,EI22,EI23)))) -> 3 | EV32: =IF(G32=EH19,EJ19,IF(G32=EH20,EJ20,IF(G32=EH21,EJ21,IF(G32=EH22,EJ22,EJ23)))) -> 1 | EW32: =IF(G32=EH19,EK19,IF(G32=EH20,EK20,IF(G32=EH21,EK21,IF(G32=EH22,EK22,EK23)))) -> 3 | EX32: =IF(G32=EH19,EL19,IF(G32=EH20,EL20,IF(G32=EH21,EL21,IF(G32=EH22,EL22,EL23)))) -> 3 | EY32: =IF(G32=EH19,EM19,IF(G32=EH20,EM20,IF(G32=EH21,EM21,IF(G32=EH22,EM22,EM23)))) -> 3 | EZ32: =IF(G32=EH19,EN19,IF(G32=EH20,EN20,IF(G32=EH21,EN21,IF(G32=EH22,EN22,EN23)))) -> 3 | FA32: =IF(G32=EH19,EO19,IF(G32=EH20,EO20,IF(G32=EH21,EO21,IF(G32=EH22,EO22,EO23)))) -> 3 | FB32: =IF(G32=EH19,EP19,IF(G32=EH20,EP20,IF(G32=EH21,EP21,IF(G32=EH22,EP22,EP23)))) -> 1 | FC32: =IF(G32=EH19,EQ19,IF(G32=EH20,EQ20,IF(G32=EH21,EQ21,IF(G32=EH22,EQ22,EQ23)))) -> 3 | FD32: =IF(G32=EH19,ER19,IF(G32=EH20,ER20,IF(G32=EH21,ER21,IF(G32=EH22,ER22,ER23)))) -> 3 | FO32: =SUM(FE32:FN32) -> 0
F33: Altitude | G33: Between 751-1800 | EH33: Between 4501-6000 | EI33: =Guidelines!C52 -> 2 | EJ33: =Guidelines!D52 -> 2 | EK33: =Guidelines!E52 -> 2 | EL33: =Guidelines!F52 -> 2 | EM33: =Guidelines!G52 -> 2 | EN33: =Guidelines!H52 -> 2 | EO33: =Guidelines!I52 -> 2 | EP33: =Guidelines!J52 -> 2 | ... ER33: =Guidelines!L52 -> 2 | EU33: =IF(G33=EH24,EI24,IF(G33=EH25,EI25,IF(G33=EH26,EI26,EI27))) -> 1 | EV33: =IF(G33=EH24,EJ24,IF(G33=EH25,EJ25,IF(G33=EH26,EJ26,EJ27))) -> 2 | EW33: =IF(G33=EH24,EK24,IF(G33=EH25,EK25,IF(G33=EH26,EK26,EK27))) -> 2 | EX33: =IF(G33=EH24,EL24,IF(G33=EH25,EL25,IF(G33=EH26,EL26,EL27))) -> 3 | EY33: =IF(G33=EH24,EM24,IF(G33=EH25,EM25,IF(G33=EH26,EM26,EM27))) -> 3 | EZ33: =IF(G33=EH24,EN24,IF(G33=EH25,EN25,IF(G33=EH26,EN26,EN27))) -> 2 | FA33: =IF(G33=EH24,EO24,IF(G33=EH25,EO25,IF(G33=EH26,EO26,EO27))) -> 2 | FB33: =IF(G33=EH24,EP24,IF(G33=EH25,EP25,IF(G33=EH26,EP26,EP27))) -> 2 | FC33: =IF(G33=EH24,EQ24,IF(G33=EH25,EQ25,IF(G33=EH26,EQ26,EQ27))) -> 3 | FD33: =IF(G33=EH24,ER24,IF(G33=EH25,ER25,IF(G33=EH26,ER26,ER27))) -> 1 | FO33: =SUM(FE33:FN33) -> 0
F34: Proximity to Major River | G34: <2000 | H34: HIGH | U34: HIGH | EH34: >6000 | EI34: =Guidelines!C53 -> 3 | EJ34: =Guidelines!D53 -> 1 | EK34: =Guidelines!E53 -> 3 | EL34: =Guidelines!F53 -> 1 | EM34: =Guidelines!G53 -> 1 | EN34: =Guidelines!H53 -> 1 | EO34: =Guidelines!I53 -> 1 | EP34: =Guidelines!J53 -> 3 | ... ER34: =Guidelines!L53 -> 1 | EU34: =IF(G34=EH28,EI28,IF(G34=EH29,EI29,IF(G34=EH30,EI30,EI31))) -> 2 | EV34: =IF(G34=EH28,EJ28,IF(G34=EH29,EJ29,IF(G34=EH30,EJ30,EJ31))) -> 3 | EW34: =IF(G34=EH28,EK28,IF(G34=EH29,EK29,IF(G34=EH30,EK30,EK31))) -> 1 | EX34: =IF(G34=EH28,EL28,IF(G34=EH29,EL29,IF(G34=EH30,EL30,EL31))) -> 2 | EY34: =IF(G34=EH28,EM28,IF(G34=EH29,EM29,IF(G34=EH30,EM30,EM31))) -> 2 | EZ34: =IF(G34=EH28,EN28,IF(G34=EH29,EN29,IF(G34=EH30,EN30,EN31))) -> 2 | FA34: =IF(G34=EH28,EO28,IF(G34=EH29,EO29,IF(G34=EH30,EO30,EO31))) -> 2 | FB34: =IF(G34=EH28,EP28,IF(G34=EH29,EP29,IF(G34=EH30,EP30,EP31))) -> 2 | FC34: =IF(G34=EH28,EQ28,IF(G34=EH29,EQ29,IF(G34=EH30,EP30,EQ31))) -> 3 | FD34: =IF(G34=EH28,ER28,IF(G34=EH29,ER29,IF(G34=EH30,ER30,ER31))) -> 3 | FO34: =SUM(FE34:FN34) -> 0
F35: Proximity to Flood Plain | G35: <4500 | EH35: Select here | EI35: =Guidelines!C54 -> 0 | EJ35: =Guidelines!D54 -> 0 | EK35: =Guidelines!E54 -> 0 | EL35: =Guidelines!F54 -> 0 | EM35: =Guidelines!G54 -> 0 | EN35: =Guidelines!H54 -> 0 | EO35: =Guidelines!I54 -> 0 | EP35: =Guidelines!J54 -> 0 | ... ER35: =Guidelines!L54 -> 0 | EU35: =IF(G35=EH32,EI32,IF(G35=EH33,EI33,IF(G35=EH34,EI34,EI35))) -> 1 | EV35: =IF(G35=EH32,EJ32,IF(G35=EH33,EJ33,IF(G35=EH34,EJ34,EJ35))) -> 2 | EW35: =IF(G35=EH32,EK32,IF(G35=EH33,EK33,IF(G35=EH34,EK34,EK35))) -> 1 | EX35: =IF(G35=EH32,EL32,IF(G35=EH33,EL33,IF(G35=EH34,EL34,EL35))) -> 2 | EY35: =IF(G35=EH32,EM32,IF(G35=EH33,EM33,IF(G35=EH34,EM34,EM35))) -> 2 | EZ35: =IF(G35=EH32,EN32,IF(G35=EH33,EN33,IF(G35=EH34,EN34,EN35))) -> 2 | FA35: =IF(G35=EH32,EO32,IF(G35=EH33,EO33,IF(G35=EH34,EO34,EO35))) -> 2 | FB35: =IF(G35=EH32,EP32,IF(G35=EH33,EP33,IF(G35=EH34,EP34,EP35))) -> 1 | FC35: =IF(G35=EH32,EQ32,IF(G35=EH33,EQ33,IF(G35=EH34,EQ34,EQ35))) -> 3 | FD35: =IF(G35=EH32,ER32,IF(G35=EH33,ER33,IF(G35=EH34,ER34,ER35))) -> 3 | FO35: =SUM(FE35:FN35) -> 0
A36: County Code | B36: County | C36: Settlement | D36: Latitude | E36: Longitude | F36: Main Attributes | G36: Attributes | H36: LEGEND | I36: Temperature | J36: Rainfall | K36: Drought | L36: Soil Erotion | M36: Land Slide | N36: Food Insecuriy | O36: Pollution | P36: Moisture Content | Q36: Flash Floods | R36: Flooding | T36: Total Score | U36: LEGEND | FO36: =SUM(FE36:FN36) -> 0
A37: 023 | B37: Turkana | C37: Town Chini | D37: 2.381195° | E37: 35.648435° | F37: Climate Region | G37: BWh> Arid | H37: LOW | I37: =FE37 -> 11 | J37: =FF37 -> 15 | K37: =FG37 -> 11 | L37: =FH37 -> 12 | M37: =FI37 -> 12 | N37: =FJ37 -> 11 | O37: =FK37 -> 13 | P37: =FL37 -> 11 | ... R37: =FN37 -> 14 | T37: =$FO$37 -> 124 | U37: LOW | EU37: =IF(G37=EH2,EI2,IF(G37=EH3,EI3,IF(G37=EH4,EI4,IF(G37=EH5,EI5,IF(G37=EH6,EI6,IF(G37=EH7,EI7,IF(G37=EH8,EI8,IF(G37=EH9,EI9,IF(G37=EH10,EI10,IF(G37=EH11,EI11,IF(G37=EH12,EI12,EI13))))))))))) -> 3 | EV37: =IF(G37=EH2,EJ2,IF(G37=EH3,EJ3,IF(G37=EH4,EJ4,IF(G37=EH5,EJ5,IF(G37=EH6,EJ6,IF(G37=EH7,EJ7,IF(G37=EH8,EJ8,IF(G37=EH9,EJ9,IF(G37=EH10,EJ10,IF(G37=EH11,EJ11,IF(G37=EH12,EJ12,EJ13))))))))))) -> 1 | EW37: =IF(G37=EH2,EK2,IF(G37=EH3,EK3,IF(G37=EH4,EK4,IF(G37=EH5,EK5,IF(G37=EH6,EK6,IF(G37=EH7,EK7,IF(G37=EH8,EK8,IF(G37=EH9,EK9,IF(G37=EH10,EK10,IF(G37=EH11,EK11,IF(G37=EH12,EK12,EK13))))))))))) -> 3 | EX37: =IF(G37=EH2,EL2,IF(G37=EH3,EL3,IF(G37=EH4,EL4,IF(G37=EH5,EL5,IF(G37=EH6,EL6,IF(G37=EH7,EL7,IF(G37=EH8,EL8,IF(G37=EH9,EL9,IF(G37=EH10,EL10,IF(G37=EH11,EL11,IF(G37=EH12,EL12,EL13))))))))))) -> 2 | EY37: =IF(G37=EH2,EM2,IF(G37=EH3,EM3,IF(G37=EH4,EM4,IF(G37=EH5,EM5,IF(G37=EH6,EM6,IF(G37=EH7,EM7,IF(G37=EH8,EM8,IF(G37=EH9,EM9,IF(G37=EH10,EM10,IF(G37=EH11,EM11,IF(G37=EH12,EM12,EM13))))))))))) -> 2 | EZ37: =IF(G37=EH2,EN2,IF(G37=EH3,EN3,IF(G37=EH4,EN4,IF(G37=EH5,EN5,IF(G37=EH6,EN6,IF(G37=EH7,EN7,IF(G37=EH8,EN8,IF(G37=EH9,EN9,IF(G37=EH10,EN10,IF(G37=EH11,EN11,IF(G37=EH12,EN12,EN13))))))))))) -> 2 | FA37: =IF(G37=EH2,EO2,IF(G37=EH3,EO3,IF(G37=EH4,EO4,IF(G37=EH5,EO5,IF(G37=EH6,EO6,IF(G37=EH7,EO7,IF(G37=EH8,EO8,IF(G37=EH9,EO9,IF(G37=EH10,EO10,IF(G37=EH11,EO11,IF(G37=EH12,EO12,EO13))))))))))) -> 2 | FB37: =IF(G37=EH2,EP2,IF(G37=EH3,EP3,IF(G37=EH4,EP4,IF(G37=EH5,EP5,IF(G37=EH6,EP6,IF(G37=EH7,EP7,IF(G37=EH8,EP8,IF(G37=EH9,EP9,IF(G37=EH10,EP10,IF(G37=EH11,EP11,IF(G37=EH12,EP12,EP13))))))))))) -> 2 | FC37: =IF(G37=EH2,EQ2,IF(G37=EH3,EQ3,IF(G37=EH4,EQ4,IF(G37=EH5,EQ5,IF(G37=EH6,EQ6,IF(G37=EH7,EQ7,IF(G37=EH8,EQ8,IF(G37=EH9,EQ9,IF(G37=EH10,EQ10,IF(G37=EH11,EQ11,IF(G37=EH12,EQ12,EQ13))))))))))) -> 1 | FD37: =IF(G37=EH2,ER2,IF(G37=EH3,ER3,IF(G37=EH4,ER4,IF(G37=EH5,ER5,IF(G37=EH6,ER6,IF(G37=EH7,ER7,IF(G37=EH8,ER8,IF(G37=EH9,ER9,IF(G37=EH10,ER10,IF(G37=EH11,ER11,IF(G37=EH12,ER12,ER13))))))))))) -> 1 | FE37: =EU37+EU38+EU39+EU40+EU41+EU42 -> 11 | FF37: =EV37+EV38+EV39+EV40+EV41+EV42 -> 15 | FG37: =EW37+EW38+EW39+EW40+EW41+EW42 -> 11 | FH37: =EX37+EX38+EX39+EX40+EX41+EX42 -> 12 | FI37: =EY37+EY38+EY39+EY40+EY41+EY42 -> 12 | FJ37: =EZ37+EZ38+EZ39+EZ40+EZ41+EZ42 -> 11 | FK37: =FA37+FA38+FA39+FA40+FA41+FA42 -> 13 | FL37: =FB37+FB38+FB39+FB40+FB41+FB42 -> 11 | ... FN37: =FD37+FD38+FD39+FD40+FD41+FD42 -> 14 | FO37: =SUM(FE37:FN37) -> 124
F38: Soil Type | G38: Clay | EU38: =IF(G38=EH14,EI14,IF(G38=EH15,EI15,IF(G38=EH16,EI16,IF(G38=EH17,EI17,EI18)))) -> 2 | EV38: =IF(G38=EH14,EJ14,IF(G38=EH15,EJ15,IF(G38=EH16,EJ16,IF(G38=EH17,EJ17,EJ18)))) -> 3 | EW38: =IF(G38=EH14,EK14,IF(G38=EH15,EK15,IF(G38=EH16,EK16,IF(G38=EH17,EK17,EK18)))) -> 2 | EX38: =IF(G38=EH14,EL14,IF(G38=EH15,EL15,IF(G38=EH16,EL16,IF(G38=EH17,EL17,EL18)))) -> 3 | EY38: =IF(G38=EH14,EM14,IF(G38=EH15,EM15,IF(G38=EH16,EM16,IF(G38=EH17,EM17,EM18)))) -> 3 | EZ38: =IF(G38=EH14,EN14,IF(G38=EH15,EN15,IF(G38=EH16,EN16,IF(G38=EH17,EN17,EN18)))) -> 2 | FA38: =IF(G38=EH14,EO14,IF(G38=EH15,EO15,IF(G38=EH16,EO16,IF(G38=EH17,EO17,EO18)))) -> 2 | FB38: =IF(G38=EH14,EP14,IF(G38=EH15,EP15,IF(G38=EH16,EP16,IF(G38=EH17,EP17,EP18)))) -> 1 | FC38: =IF(G38=EH14,EQ14,IF(G38=EH15,EQ15,IF(G38=EH16,EQ16,IF(G38=EH17,EQ17,EQ18)))) -> 3 | FD38: =IF(G38=EH14,ER14,IF(G38=EH15,ER15,IF(G38=EH16,ER16,IF(G38=EH17,ER17,ER18)))) -> 3 | FO38: =SUM(FE38:FN38) -> 0
F39: Land Cover | G39: Natural Terrestrial Vegetation | H39: MEDIUM | U39: MEDIUM | EU39: =IF(G39=EH19,EI19,IF(G39=EH20,EI20,IF(G39=EH21,EI21,IF(G39=EH22,EI22,EI23)))) -> 1 | EV39: =IF(G39=EH19,EJ19,IF(G39=EH20,EJ20,IF(G39=EH21,EJ21,IF(G39=EH22,EJ22,EJ23)))) -> 3 | EW39: =IF(G39=EH19,EK19,IF(G39=EH20,EK20,IF(G39=EH21,EK21,IF(G39=EH22,EK22,EK23)))) -> 1 | EX39: =IF(G39=EH19,EL19,IF(G39=EH20,EL20,IF(G39=EH21,EL21,IF(G39=EH22,EL22,EL23)))) -> 1 | EY39: =IF(G39=EH19,EM19,IF(G39=EH20,EM20,IF(G39=EH21,EM21,IF(G39=EH22,EM22,EM23)))) -> 1 | EZ39: =IF(G39=EH19,EN19,IF(G39=EH20,EN20,IF(G39=EH21,EN21,IF(G39=EH22,EN22,EN23)))) -> 1 | FA39: =IF(G39=EH19,EO19,IF(G39=EH20,EO20,IF(G39=EH21,EO21,IF(G39=EH22,EO22,EO23)))) -> 2 | FB39: =IF(G39=EH19,EP19,IF(G39=EH20,EP20,IF(G39=EH21,EP21,IF(G39=EH22,EP22,EP23)))) -> 3 | FC39: =IF(G39=EH19,EQ19,IF(G39=EH20,EQ20,IF(G39=EH21,EQ21,IF(G39=EH22,EQ22,EQ23)))) -> 1 | FD39: =IF(G39=EH19,ER19,IF(G39=EH20,ER20,IF(G39=EH21,ER21,IF(G39=EH22,ER22,ER23)))) -> 1 | FO39: =SUM(FE39:FN39) -> 0
F40: Altitude | G40: <750 | EU40: =IF(G40=EH24,EI24,IF(G40=EH25,EI25,IF(G40=EH26,EI26,EI27))) -> 2 | EV40: =IF(G40=EH24,EJ24,IF(G40=EH25,EJ25,IF(G40=EH26,EJ26,EJ27))) -> 3 | EW40: =IF(G40=EH24,EK24,IF(G40=EH25,EK25,IF(G40=EH26,EK26,EK27))) -> 3 | EX40: =IF(G40=EH24,EL24,IF(G40=EH25,EL25,IF(G40=EH26,EL26,EL27))) -> 2 | EY40: =IF(G40=EH24,EM24,IF(G40=EH25,EM25,IF(G40=EH26,EM26,EM27))) -> 2 | EZ40: =IF(G40=EH24,EN24,IF(G40=EH25,EN25,IF(G40=EH26,EN26,EN27))) -> 2 | FA40: =IF(G40=EH24,EO24,IF(G40=EH25,EO25,IF(G40=EH26,EO26,EO27))) -> 3 | FB40: =IF(G40=EH24,EP24,IF(G40=EH25,EP25,IF(G40=EH26,EP26,EP27))) -> 2 | FC40: =IF(G40=EH24,EQ24,IF(G40=EH25,EQ25,IF(G40=EH26,EQ26,EQ27))) -> 3 | FD40: =IF(G40=EH24,ER24,IF(G40=EH25,ER25,IF(G40=EH26,ER26,ER27))) -> 3 | FO40: =SUM(FE40:FN40) -> 0
...
