Workbook

Sheet SUMMARY
B3: SUMMARY OF PDOs
A4: INDICATOR | B4: Planned | C4: Achieved
A5: Roads (Km) | B5: ='KISUMU KAKAMEGA'!E28+'PHASE 1 NAKURUNAIROBI+CLUSTER 1'!E50+'CLUSTER 3'!E38+'CLUSTER 4'!E40+'CLUSTER 5'!E25+'PHASE 1 KILIFI + CLUSTER 2 '!E51 -> 131.02292 | C5: ='KISUMU KAKAMEGA'!F28+'PHASE 1 NAKURUNAIROBI+CLUSTER 1'!F50+'PHASE 1 KILIFI + CLUSTER 2 '!F51+'CLUSTER 3'!F38+'CLUSTER 4'!F40+'CLUSTER 5'!F25 -> 97.011463
A6: Foothpath (Km) | B6: ='KISUMU KAKAMEGA'!Y28+'PHASE 1 NAKURUNAIROBI+CLUSTER 1'!U50+'PHASE 1 KILIFI + CLUSTER 2 '!U51+'CLUSTER 3'!U38+'CLUSTER 4'!U40+'CLUSTER 5'!U25 -> 133.692 | C6: ='KISUMU KAKAMEGA'!Z28+'PHASE 1 NAKURUNAIROBI+CLUSTER 1'!V50+'PHASE 1 KILIFI + CLUSTER 2 '!V51+'CLUSTER 3'!V38+'CLUSTER 4'!V40+'CLUSTER 5'!V25 -> 64.648
A7: Stormwater Drainage (Km) | B7: ='KISUMU KAKAMEGA'!G28+'PHASE 1 NAKURUNAIROBI+CLUSTER 1'!G50+'PHASE 1 KILIFI + CLUSTER 2 '!G51+'CLUSTER 3'!G38+'CLUSTER 4'!G40+'CLUSTER 5'!G25 -> 176.51884 | C7: ='KISUMU KAKAMEGA'!H28+'PHASE 1 NAKURUNAIROBI+CLUSTER 1'!H50+'PHASE 1 KILIFI + CLUSTER 2 '!H51+'CLUSTER 3'!H38+'CLUSTER 4'!H40+'CLUSTER 5'!H25 -> 116.15349
A8: Water Supply Pipeline (Km) | B8: ='KISUMU KAKAMEGA'!I28+'PHASE 1 NAKURUNAIROBI+CLUSTER 1'!I50+'PHASE 1 KILIFI + CLUSTER 2 '!I51+'CLUSTER 3'!I38+'CLUSTER 4'!I40+'CLUSTER 5'!I25 -> 71.656 | C8: ='KISUMU KAKAMEGA'!J28+'PHASE 1 NAKURUNAIROBI+CLUSTER 1'!J50+'PHASE 1 KILIFI + CLUSTER 2 '!J51+'CLUSTER 3'!J38+'CLUSTER 4'!J40+'CLUSTER 5'!J25 -> 46.755
A9: Water Connnections (Nos) | B9: ='KISUMU KAKAMEGA'!K28+'PHASE 1 NAKURUNAIROBI+CLUSTER 1'!K50+'PHASE 1 KILIFI + CLUSTER 2 '!K51+'CLUSTER 3'!K38+'CLUSTER 4'!K40+'CLUSTER 5'!K25 -> 6086 | C9: ='KISUMU KAKAMEGA'!L28+'PHASE 1 NAKURUNAIROBI+CLUSTER 1'!L50+'PHASE 1 KILIFI + CLUSTER 2 '!L51+'CLUSTER 3'!L38+'CLUSTER 4'!L40+'CLUSTER 5'!L25 -> 1281
A10: Sewer Supply Pipeline (Km) | B10: ='PHASE 1 NAKURUNAIROBI+CLUSTER 1'!W50+'PHASE 1 KILIFI + CLUSTER 2 '!W51+'CLUSTER 3'!W38+'CLUSTER 4'!W40+'CLUSTER 5'!W25 -> 6.246 | C10: ='PHASE 1 NAKURUNAIROBI+CLUSTER 1'!X50+'PHASE 1 KILIFI + CLUSTER 2 '!X51+'CLUSTER 3'!X38+'CLUSTER 4'!X40+'CLUSTER 5'!X25 -> 1.341
A11: Sewer Connnections (Nos) | B11: ='KISUMU KAKAMEGA'!U28+'PHASE 1 NAKURUNAIROBI+CLUSTER 1'!Y50+'PHASE 1 KILIFI + CLUSTER 2 '!Y51+'CLUSTER 3'!Y38+'CLUSTER 4'!Y40+'CLUSTER 5'!Y25 -> 807 | C11: ='KISUMU KAKAMEGA'!V28+'PHASE 1 NAKURUNAIROBI+CLUSTER 1'!Z50+'PHASE 1 KILIFI + CLUSTER 2 '!Z51+'CLUSTER 3'!Z38+'CLUSTER 4'!Z40+'CLUSTER 5'!Z25 -> 0
A12: Vending Platforms (Nos) | B12: ='KISUMU KAKAMEGA'!S28+'PHASE 1 NAKURUNAIROBI+CLUSTER 1'!S50+'PHASE 1 KILIFI + CLUSTER 2 '!S51+'CLUSTER 3'!S38+'CLUSTER 4'!S40+'CLUSTER 5'!S25 -> 395 | C12: ='KISUMU KAKAMEGA'!T28+'PHASE 1 NAKURUNAIROBI+CLUSTER 1'!T50+'PHASE 1 KILIFI + CLUSTER 2 '!T51+'CLUSTER 3'!T38+'CLUSTER 4'!T40+'CLUSTER 5'!T25 -> 389
A13: Streetlights (Nos) | B13: ='KISUMU KAKAMEGA'!Q28+'PHASE 1 NAKURUNAIROBI+CLUSTER 1'!Q50+'PHASE 1 KILIFI + CLUSTER 2 '!Q51+'CLUSTER 3'!Q38+'CLUSTER 4'!Q40+'CLUSTER 5'!Q25 -> 4870 | C13: ='KISUMU KAKAMEGA'!R28+'PHASE 1 NAKURUNAIROBI+CLUSTER 1'!R50+'PHASE 1 KILIFI + CLUSTER 2 '!R51+'CLUSTER 3'!R38+'CLUSTER 4'!R40+'CLUSTER 5'!R25 -> 2445
A14: Highmast Lights (Nos) | B14: ='KISUMU KAKAMEGA'!O28+'PHASE 1 NAKURUNAIROBI+CLUSTER 1'!O50+'PHASE 1 KILIFI + CLUSTER 2 '!O51+'CLUSTER 3'!O38+'CLUSTER 4'!O40+'CLUSTER 5'!O25 -> 189 | C14: ='KISUMU KAKAMEGA'!P28+'PHASE 1 NAKURUNAIROBI+CLUSTER 1'!P50+'PHASE 1 KILIFI + CLUSTER 2 '!P51+'CLUSTER 3'!P38+'CLUSTER 4'!P40+'CLUSTER 5'!P25 -> 116
A15: Ablution Blocks | B15: ='KISUMU KAKAMEGA'!M28+'PHASE 1 NAKURUNAIROBI+CLUSTER 1'!M50+'PHASE 1 KILIFI + CLUSTER 2 '!M51+'CLUSTER 3'!M38+'CLUSTER 4'!M40+'CLUSTER 5'!M25 -> 267 | C15: ='KISUMU KAKAMEGA'!N28+'PHASE 1 NAKURUNAIROBI+CLUSTER 1'!N50+'PHASE 1 KILIFI + CLUSTER 2 '!N51+'CLUSTER 3'!N38+'CLUSTER 4'!N40+'CLUSTER 5'!N25 -> 229

Sheet KISUMU KAKAMEGA
A1: KISIP 2 PHASE 1 KISUMU AND KAKAMEGA PDOs
A2: County | B2: Contract | C2: Financier | D2: Settlement | E2: Roads (km) | G2: Drainage (km) | I2: Water Supply Pipelines (Km) | K2: Water Connections | M2: Toilets / Ablution | O2: High Masts Lighting | Q2: Street Lighting | S2: Vending Platforms | U2: Sewer Connections (No) | W2: Water Kiosks | Y2: Footpaths (km)
E3: Planned | F3: Achieved | G3: Planned | H3: Achieved | I3: Planned | J3: Achieved | K3: Planned | L3: Achieved | M3: Planned | N3: Achieved | O3: Planned | P3: Achieved | Q3: Planned | R3: Achieved | S3: Planned | T3: Achieved | U3: Planned | V3: Achieved | W3: Planned | X3: Achieved | Y3: Planned | Z3: Achieved
A4: Kisumu | B4: Kisumu Lot 1 Phase 1 RFB | C4: IDA | D4: Bandani | E4: 2.584 | F4: 0.93 | G4: 5.368 | H4: 5.368 | I4: 0 | J4: 0 | K4: 0 | L4: 0 | M4: 0 | N4: 0 | O4: 0 | P4: 0 | Q4: 0 | R4: 0 | S4: 0 | T4: 0 | U4: 0 | V4: 0 | W4: 0 | X4: 0 | Y4: 5.168 | Z4: 0
D5: Nyawita | E5: 0.869 | F5: 0.8 | G5: 0.869 | H5: 0.75 | I5: 0 | J5: 0 | K5: 0 | L5: 0 | M5: 0 | N5: 0 | O5: 0 | P5: 0 | Q5: 0 | R5: 0 | S5: 0 | T5: 0 | U5: 0 | V5: 0 | W5: 0 | X5: 0 | Y5: 0.869 | Z5: 0
D6: Migosi | E6: 0 | F6: 0 | G6: 4.043 | H6: 1.875 | I6: 0 | J6: 0 | K6: 0 | L6: 0 | M6: 0 | N6: 0 | O6: 3 | P6: 0 | Q6: 0 | R6: 0 | S6: 0 | T6: 0 | U6: 40 | V6: 0 | W6: 0 | X6: 0 | Y6: 0 | Z6: 0
D7: Manyatta A | E7: 2.498 | F7: 2.498 | G7: =1.368+1.776+0.966+0.443 -> 4.553 | H7: 2.95 | I7: 0 | J7: 0 | K7: 0 | L7: 0 | M7: 0 | N7: 0 | O7: 6 | P7: 0 | Q7: 0 | R7: 0 | S7: 0 | T7: 0 | U7: 0 | V7: 0 | W7: 0 | X7: 0 | Y7: 4.553 | Z7: 0
D8: Manyatta B | E8: 4.091 | F8: 4.091 | G8: =0.463+1.806+0.654+2.62+1.522 -> 7.065 | H8: 4.105 | I8: 1.44 | J8: 0 | K8: 46 | L8: 0 | M8: 0 | N8: 0 | O8: 0 | P8: 0 | Q8: 0 | R8: 0 | S8: 0 | T8: 0 | U8: 200 | V8: 0 | W8: 2 | X8: 0 | Y8: 7.065 | Z8: 0.975
B9: Kisumu Lot 2 Phase 1 RFB | C9: AFD | D9: Kibuye | E9: 0.681 | F9: 0.681 | G9: =0.57+0.79 -> 1.36 | H9: 1.36 | I9: 0.89 | J9: 0 | K9: 3 | L9: 0 | M9: 1 | N9: 0 | O9: 0 | P9: 0 | Q9: 0 | R9: 0 | S9: 0 | T9: 0 | U9: 0 | V9: 0 | W9: 1 | X9: 0 | Y9: 1.362 | Z9: 1.362
D10: Shauri Moyo | E10: 0 | F10: 0 | G10: 0 | H10: 0 | I10: 1.71 | J10: 1.07 | K10: 55 | L10: 4 | M10: 0 | N10: 0 | O10: 1 | P10: 0 | Q10: 0 | R10: 0 | S10: 0 | T10: 0 | U10: 0 | V10: 0 | W10: 2 | X10: 0 | Y10: 0 | Z10: 0
D11: Shauri Yako | E11: 1.069 | F11: 0 | G11: =0.55+1.8 -> 2.35 | H11: 0 | I11: 0 | J11: 0 | K11: 0 | L11: 0 | M11: 0 | N11: 0 | O11: 0 | P11: 0 | Q11: 0 | R11: 0 | S11: 0 | T11: 0 | U11: 0 | V11: 0 | W11: 0 | X11: 0 | Y11: 2.138
D12: Swahili/ Sangoro | E12: 0 | F12: 0 | G12: 0 | H12: 0 | I12: 0.8 | J12: 0.5 | K12: 107 | L12: 7 | M12: 0 | N12: 0 | O12: 0 | P12: 0 | Q12: 0 | R12: 0 | S12: 0 | T12: 0 | U12: 0 | V12: 0 | W12: 1 | X12: 0 | Y12: 0 | Z12: 0
D13: Bondeni | E13: 0 | F13: 0 | G13: =1.449 -> 1.449 | H13: 0.748 | I13: 0 | J13: 0 | K13: 0 | L13: 0 | M13: 0 | N13: 0 | O13: 1 | P13: 0 | Q13: 0 | R13: 0 | S13: 0 | T13: 0 | U13: 0 | V13: 0 | W13: 0 | X13: 0 | Y13: 0 | Z13: 0
B14: Phase 1 RFQ | C14: IDA | D14: Bandani | E14: 0 | F14: 0 | G14: 0 | H14: 0 | I14: 0 | J14: 0 | K14: 0 | L14: 0 | M14: 0 | N14: 0 | O14: 0 | P14: 0 | Q14: 0 | R14: 0 | S14: 37 | T14: 37 | U14: 0 | V14: 0 | W14: 0 | X14: 0 | Y14: 0 | Z14: 0
D15: Manyatta A | E15: 0 | F15: 0 | G15: 0 | H15: 0 | I15: 0 | J15: 0 | K15: 0 | L15: 0 | M15: 0 | N15: 0 | O15: 0 | P15: 0 | Q15: 0 | R15: 0 | S15: 37 | T15: 37 | U15: 0 | V15: 0 | W15: 0 | X15: 0 | Y15: 0 | Z15: 0
D16: Manyatta B | E16: 0 | F16: 0 | G16: 0 | H16: 0 | I16: 0 | J16: 0 | K16: 0 | L16: 0 | M16: 0 | N16: 0 | O16: 0 | P16: 0 | Q16: 0 | R16: 0 | S16: 37 | T16: 37 | U16: 0 | V16: 0 | W16: 0 | X16: 0 | Y16: 0 | Z16: 0
D17: Total | E17: =SUM(E4:E16) -> 11.792 | F17: =SUM(F4:F16) -> 9 | G17: =SUM(G4:G16) -> 27.057 | H17: =SUM(H4:H16) -> 17.156 | I17: =SUM(I4:I16) -> 4.84 | J17: =SUM(J4:J16) -> 1.57 | K17: =SUM(K4:K16) -> 211 | L17: =SUM(L4:L16) -> 11 | ... W17: =SUM(W4:W16) -> 6 | X17: 0 | Y17: =SUM(Y4:Y16) -> 21.155 | Z17: =SUM(Z4:Z16) -> 2.337
A18: Kakamega | B18: Kakamega Lot 1 Phase 1 RFB | C18: IDA | D18: Shibale | E18: 0.523 | F18: 0 | G18: 2.846 | H18: 0.193 | I18: 0 | J18: 0 | K18: 70 | L18: 0 | M18: 0 | N18: 0 | O18: 1 | P18: 0 | Q18: 0 | R18: 0 | S18: 0 | T18: 0 | U18: 0 | V18: 0 | W18: 5 | X18: 0 | Y18: 0.823 | Z18: 0
D19: Mjini | E19: 0.472 | F19: 0 | G19: 0.944 | H19: 0 | I19: 2.376 | J19: 1.785 | K19: 85 | L19: 0 | M19: 0 | N19: 0 | O19: 0 | P19: 0 | Q19: 26 | R19: 0 | S19: 0 | T19: 0 | U19: 0 | V19: 0 | W19: 0 | X19: 0 | Y19: 0.944 | Z19: 0
D20: Lukoye | E20: 0.88 | F20: 0 | G20: 2.21 | H20: 0 | I20: 0 | J20: 0 | K20: 0 | L20: 0 | M20: 0 | N20: 0 | O20: 0 | P20: 0 | Q20: 0 | R20: 0 | S20: 0 | T20: 0 | U20: 0 | V20: 0 | W20: 0 | X20: 0 | Y20: 0 | Z20: 0
B21: Kakamega Lot 2 Phase 1 RFB | C21: AFD | D21: Amalemba | E21: 0.848 | F21: 0.777 | G21: 1.696 | H21: 1.4 | I21: 0 | J21: 0 | K21: 0 | L21: 0 | M21: 0 | N21: 0 | O21: 1 | P21: 1 | Q21: 25 | R21: 23 | S21: 0 | T21: 0 | U21: 80 | V21: 0 | W21: 0 | X21: 0 | Y21: 1.696 | Z21: 0.85
D22: Kambi Somali | E22: 0.19 | F22: 0 | G22: 0.38 | H22: 0.265 | I22: 0 | J22: 0 | K22: 0 | L22: 0 | M22: 0 | N22: 0 | O22: 0 | P22: 0 | Q22: 0 | R22: 0 | S22: 0 | T22: 0 | U22: 20 | V22: 0 | W22: 0 | X22: 0 | Y22: 0 | Z22: 0
B23: Phase 1 RFQ | C23: IDA | D23: Mjini | E23: 0 | F23: 0 | G23: 0 | H23: 0 | I23: 0 | J23: 0 | K23: 0 | L23: 0 | M23: 0 | N23: 0 | O23: 1 | P23: 0 | R23: 0 | S23: 0 | T23: 0 | U23: 0 | V23: 0 | W23: 0 | X23: 0 | Y23: 0 | Z23: 0
D24: Lukoye | E24: 0 | F24: 0 | G24: 0 | H24: 0 | I24: 0 | J24: 0 | K24: 0 | L24: 0 | M24: 0 | N24: 0 | O24: 1 | P24: 0 | Q24: 25 | R24: 0 | S24: 0 | T24: 0 | U24: 0 | V24: 0 | W24: 0 | X24: 0 | Y24: 0 | Z24: 0
D25: Amalemba | E25: 0 | F25: 0 | G25: 0 | H25: 0 | I25: 0 | J25: 0 | K25: 0 | L25: 0 | M25: 0 | N25: 0 | O25: 0 | P25: 0 | Q25: 7 | R25: 0 | S25: 0 | T25: 0 | U25: 0 | V25: 0 | W25: 0 | X25: 0 | Y25: 0 | Z25: 0
D26: Kambi Somali | E26: 0 | F26: 0 | G26: 0 | H26: 0 | I26: 0 | J26: 0 | K26: 0 | L26: 0 | M26: 0 | N26: 0 | O26: 0 | P26: 0 | Q26: 1 | R26: 0 | S26: 0 | T26: 0 | U26: 0 | V26: 0 | W26: 0 | X26: 0 | Y26: 0 | Z26: 0
D27: Total | E27: =SUM(E18:E26) -> 2.913 | F27: =SUM(F18:F26) -> 0.777 | G27: =SUM(G18:G26) -> 8.076 | H27: =SUM(H18:H26) -> 1.858 | I27: =SUM(I18:I26) -> 2.376 | J27: =SUM(J18:J26) -> 1.785 | K27: =SUM(K18:K26) -> 155 | L27: =SUM(L18:L26) -> 0 | ... W27: =SUM(W18:W26) -> 5 | X27: 0 | Y27: =SUM(Y18:Y26) -> 3.463 | Z27: =SUM(Z18:Z26) -> 0.85
A28: TOTAL | E28: =SUM(E17,E27) -> 14.705 | F28: =SUM(F17,F27) -> 9.777 | G28: =SUM(G17,G27) -> 35.133 | H28: =SUM(H17,H27) -> 19.014 | I28: =SUM(I17,I27) -> 7.216 | J28: =SUM(J17,J27) -> 3.355 | K28: =SUM(K17,K27) -> 366 | L28: =SUM(L17,L27) -> 11 | ... V28: =SUM(V17,V27) -> 0 | W28: =W17+W27 -> 11 | X28: 0 | Y28: =SUM(Y17,Y27) -> 24.618 | Z28: =SUM(Z17,Z27) -> 3.187
Y51: =SUM(Y17,Y30,Y42,Y45,Y50) -> 21.155 | Z51: =SUM(Z17,Z30,Z42,Z45,Z50) -> 2.337

Sheet PHASE 1 NAKURUNAIROBI+CLUSTER 1
A1: KISIP 2 PHASE 1 NAKURU/NAIROBI AND PHASE 2 CLUSTER 1 PDOs
A2: County | B2: Contract | C2: Financier | D2: Settlement | E2: Roads (km) | G2: Drainage (km) | I2: Water Supply Pipelines(km) | K2: Water Connections | M2: Toilets / Ablution | O2: High Masts Lighting | Q2: Street Lighting | S2: Vending Platforms | U2: Footpaths (km) | W2: Sewer Pipelines (km) | Y2: Sewer Connections (No)
E3: Planned | F3: Achieved | G3: Planned | H3: Achieved | I3: Planned | J3: Achieved | K3: Planned | L3: Achieved | M3: Planned | N3: Achieved | O3: Planned | P3: Achieved | Q3: Planned | R3: Achieved | S3: Planned | T3: Achieved | U3: Planned | V3: Achieved | W3: Planned | X3: Achieved | Y3: Planned | Z3: Achieved
A4: Nakuru | B4: RFB Phase 1 Lot 1 | C4: IDA | D4: Kwa Murogi | E4: 1.045 | F4: 1.045 | G4: 1.045 | H4: ='[1]NAKURUNAIROBI CLUSTER 1'!H4 -> 1.045 | I4: 0 | J4: 0 | K4: 0 | L4: 0 | M4: 0 | N4: 0 | O4: 4 | P4: 0 | Q4: 0 | R4: 0 | S4: 0 | T4: 0 | U4: 1.045 | V4: 1.045 | W4: 0 | X4: 0 | Y4: 0 | Z4: 0
D5: London Hilton | E5: 1.292 | F5: 1.292 | G5: 1.292 | H5: ='[1]NAKURUNAIROBI CLUSTER 1'!H5 -> 1.292 | I5: 0 | J5: 0 | K5: 0 | L5: 0 | M5: 0 | N5: 0 | O5: 4 | P5: 0 | Q5: 0 | R5: 0 | S5: 0 | T5: 0 | U5: 1.292 | V5: 1.292 | W5: 0.28 | X5: 0.28 | Y5: 114 | Z5: 0
D6: Lakeview | E6: 0.95 | F6: 0.95 | G6: 0.95 | H6: ='[1]NAKURUNAIROBI CLUSTER 1'!H6 -> 0.95 | I6: 0 | J6: 0 | K6: 0 | L6: 0 | M6: 0 | N6: 0 | O6: 3 | P6: 0 | Q6: 0 | R6: 0 | S6: 0 | T6: 0 | U6: 0.95 | V6: 0.95 | W6: 0 | X6: 0 | Y6: 0 | Z6: 0
B7: RFB Phase 1 Lot 2 | C7: IDA | D7: Karagita | E7: 0 | F7: 0 | G7: 0 | H7: 0 | I7: 7.8 | J7: 7.8 | K7: 0 | L7: 0 | M7: 0 | N7: 0 | O7: 0 | P7: 0 | Q7: 0 | R7: 0 | S7: 0 | T7: 0 | U7: 0 | V7: 0 | W7: 0 | X7: 0 | Y7: 0 | Z7: 0
B8: RFQ | C8: IDA | D8: Kwa Murogi | E8: 0 | F8: 0 | H8: 0 | I8: 0 | J8: 0 | K8: 0 | M8: 0 | N8: 0 | O8: 3 | P8: 3 | Q8: 15 | R8: 15 | S8: 18 | T8: 18 | U8: 0 | V8: 0 | W8: 0 | X8: 0 | Y8: 0 | Z8: 0
D9: London Hilton | E9: 0 | F9: 0 | I9: 0 | J9: 0 | K9: 0 | M9: 0 | N9: 0 | O9: 4 | P9: 3 | Q9: 15 | R9: 15 | S9: 12 | T9: 12 | U9: 0 | V9: 0 | W9: 0 | X9: 0 | Y9: 0 | Z9: 0
D10: Lakeview | E10: 0 | F10: 0 | H10: 0 | J10: 0 | N10: 0 | O10: 3 | P10: 3 | Q10: 10 | R10: 10 | S10: 10 | T10: 10 | U10: 0 | V10: 0 | W10: 0 | X10: 0 | Y10: 0 | Z10: 0
E11: =SUM(E4:E10) -> 3.287 | F11: =SUM(F4:F10) -> 3.287 | G11: =SUM(G4:G10) -> 3.287 | H11: =SUM(H4:H10) -> 3.287 | I11: =SUM(I4:I10) -> 7.8 | J11: =SUM(J4:J10) -> 7.8 | K11: =SUM(K4:K10) -> 0 | L11: =SUM(L4:L10) -> 0 | ... Z11: =SUM(Z4:Z10) -> 0
A12: Nairobi | B12: Phase 1 Lot 1 | C12: IDA | D12: Kahawa Soweto | E12: 0.545 | F12: 0 | G12: 0.83 | H12: 0.82 | I12: 0 | J12: 0 | K12: 0 | L12: 0 | M12: 0 | N12: 0 | O12: 0 | P12: 0 | Q12: 43 | R12: 0 | S12: 0 | T12: 0 | U12: 0.545 | V12: 0 | W12: 1.27 | X12: 0.28 | Y12: 0 | Z12: 0
D13: Kayole Soweto | E13: 3.347 | F13: 0 | G13: 3.6 | H13: 0.59 | I13: 0 | J13: 0 | K13: 0 | L13: 0 | M13: 0 | N13: 0 | O13: 0 | P13: 0 | Q13: 147 | R13: 0 | S13: 0 | T13: 0 | U13: 3.25 | V13: 0 | W13: 0 | X13: 0 | Y13: 0 | Z13: 0
D14: Embakasi | E14: 0.555 | F14: 0 | G14: 0.705 | H14: 0.83 | I14: 0 | J14: 0 | K14: 0 | L14: 0 | M14: 0 | N14: 0 | O14: 0 | P14: 0 | Q14: 28 | R14: 0 | S14: 0 | T14: 0 | U14: 0.455 | V14: 0 | W14: 0.26 | X14: 0.35 | Y14: 0 | Z14: 0
B15: Phase 1 Lot 2 | C15: AFD | D15: Kambi Moto | E15: 0.55 | F15: 0.55 | G15: 0.55 | H15: 0.55 | I15: 0 | J15: 0 | K15: 0 | L15: 0 | M15: 0 | O15: 0 | P15: 0 | Q15: 14 | R15: 0 | S15: 0 | T15: 0 | U15: 0.55 | V15: 0.55 | W15: 0.431 | X15: 0.431 | Y15: 0 | Z15: 0
D16: Total | E16: =SUM(E12:E15) -> 4.997 | F16: =SUM(F12:F15) -> 0.55 | G16: =SUM(G12:G15) -> 5.685 | H16: =SUM(H12:H15) -> 2.79 | I16: =SUM(I12:I15) -> 0 | J16: =SUM(J12:J15) -> 0 | K16: =SUM(K12:K15) -> 0 | L16: =SUM(L12:L15) -> 0 | ... Z16: =SUM(Z12:Z15) -> 0
A17: Nyandarua | B17: Phase 2 RFB | C17: IDA | D17: Njabini | E17: 1.282 | F17: 0.511 | G17: 1.282 | H17: 1.05 | I17: 0 | J17: 0 | K17: 0 | L17: 0 | M17: 0 | N17: 0 | O17: 0 | Q17: 81 | R17: 0 | S17: 0 | T17: 0 | U17: 1.282 | V17: 1 | W17: 0 | X17: 0 | Y17: 0 | Z17: =SUM(Z4:Z16) -> 0
D18: Huruma | E18: 1.812 | F18: 0 | G18: 1.812 | H18: 1.7 | I18: 0 | J18: 0 | K18: 0 | L18: 0 | M18: 0 | N18: 0 | O18: 0 | P18: 0 | Q18: 93 | R18: 0 | S18: 0 | T18: 0 | U18: 1.812 | V18: 0 | W18: 0 | X18: 0 | Y18: ` | Z18: 0
B19: RFQ | C19: IDA | D19: Njabini | E19: 0 | F19: 0 | G19: 0 | H19: 0 | I19: 0 | J19: 0 | K19: 0 | L19: 0 | M19: 0 | N19: 0 | O19: 2 | P19: 2 | Q19: 0 | R19: =SUM(R17:R18) -> 0 | S19: 0 | T19: 0 | U19: 0 | V19: 0 | W19: 0 | X19: 0 | Y19: 0 | Z19: 0
D20: Huruma | E20: 0 | F20: 0 | G20: 0 | H20: 0 | I20: 0 | J20: 0 | K20: 0 | L20: 0 | M20: 0 | N20: 0 | O20: 3 | P20: 3 | Q20: 0 | R20: 0 | S20: 34 | T20: 34 | U20: 0 | V20: 0 | W20: 0 | X20: 0 | Y20: 0 | Z20: 0
D21: Total | E21: =SUM(E17:E20) -> 3.094 | F21: =SUM(F17:F20) -> 0.511 | G21: =SUM(G17:G20) -> 3.094 | H21: =SUM(H17:H20) -> 2.75 | I21: =SUM(I17:I20) -> 0 | J21: =SUM(J17:J20) -> 0 | K21: =SUM(K17:K20) -> 0 | L21: =SUM(L17:L20) -> 0 | ... Z21: =SUM(Z17:Z20) -> 0
A22: Kiambu | B22: Phase 2 RFB | C22: AFD | D22: Umoja | E22: 0.65 | F22: 0.65 | G22: 0.65 | H22: 0.65 | I22: 0 | J22: 0 | K22: 0 | L22: 0 | M22: 0 | N22: 0 | O22: 0 | P22: 0 | Q22: 65 | R22: 0 | S22: 0 | T22: 0 | U22: 0.429 | V22: 0.429 | W22: 0 | X22: 0 | Y22: 0 | Z22: 0
D23: Fort Jesus | E23: 1.83 | F23: 1.83 | G23: 1.83 | H23: 1.8 | I23: 0 | J23: 0 | K23: 0 | L23: 0 | M23: 0 | N23: 0 | O23: 0 | Q23: 98 | R23: 1 | S23: 0 | T23: 0 | U23: 1.83 | V23: 0 | W23: 0 | X23: 0 | Y23: 0 | Z23: 0
D24: Kiangombe | E24: 1.77 | F24: 1.74 | G24: 1.77 | H24: 1.77 | I24: 0 | J24: 0 | K24: 0 | L24: 0 | N24: 0 | O24: 0 | P24: 0 | Q24: 95 | R24: 0 | S24: 0 | T24: 0 | U24: 1.77 | V24: 0 | W24: 0 | X24: 0 | Y24: 0 | Z24: 0
D25: Misri | E25: 1.16 | F25: 1.16 | G25: 1.16 | H25: 1.16 | I25: 0 | J25: 0 | K25: 0 | L25: 0 | M25: 0 | N25: 0 | O25: 0 | P25: 0 | Q25: 90 | R25: 0 | S25: 0 | T25: 0 | U25: 1.15 | V25: 0 | W25: 0 | X25: 0 | Y25: 0 | Z25: 0
D26: Bosnia | E26: 1.6 | F26: 0 | G26: 1.6 | H26: 0 | I26: 0 | J26: 0 | K26: 0 | L26: 0 | M26: 0 | N26: 0 | O26: 0 | P26: 0 | Q26: 47 | R26: 0 | S26: 0 | T26: 0 | U26: 1.6 | V26: 0 | W26: 0 | X26: 0 | Y26: 0 | Z26: 0
B27: RFQ | C27: IDA | D27: Umoja | E27: 0 | F27: 0 | G27: 0 | H27: 0 | I27: 0 | J27: 0 | K27: 0 | L27: 0 | M27: 0 | N27: 0 | O27: 0 | P27: 0 | Q27: 40 | R27: 40 | S27: 0 | T27: 0 | U27: 0 | V27: 0 | W27: 0 | X27: 0 | Y27: 0 | Z27: 0
D28: Fort Jesus | E28: 0 | F28: 0 | G28: 0 | H28: 0 | I28: 0 | J28: 0 | K28: 0 | L28: 0 | M28: 0 | N28: 0 | O28: 0 | P28: 0 | Q28: 35 | R28: 35 | S28: 0 | T28: 0 | U28: 0 | W28: 0 | X28: 0 | Y28: 0 | Z28: 0
D29: Kiangombe | E29: 0 | F29: 0 | G29: 0 | H29: 0 | I29: 0 | J29: 0 | K29: 0 | L29: 0 | M29: 0 | N29: 0 | O29: 0 | P29: 0 | Q29: 65 | R29: 65 | S29: 0 | T29: 0 | U29: 0 | Y29: 0
D30: Misri | E30: 0 | F30: 0 | G30: 0 | H30: 0 | I30: 0 | J30: 0 | K30: 0 | L30: 0 | M30: 0 | N30: 0 | O30: 0 | P30: 0 | Q30: 30 | R30: 30 | S30: 0 | T30: 0 | U30: 0 | V30: 0 | W30: 0 | X30: 0 | Y30: 0 | Z30: 0
D31: Bosnia | E31: 0 | F31: 0 | G31: 0 | H31: 0 | I31: 0 | J31: 0 | K31: 0 | L31: 0 | M31: 0 | N31: 0 | O31: 0 | P31: 0 | Q31: 25 | R31: 25 | S31: 0 | U31: 0
D32: Total | E32: =SUM(E22:E31) -> 7.01 | F32: =SUM(F22:F31) -> 5.38 | G32: =SUM(G22:G31) -> 7.01 | H32: =SUM(H22:H31) -> 5.38 | I32: =SUM(I22:I31) -> 0 | J32: =SUM(J22:J31) -> 0 | K32: =SUM(K22:K31) -> 0 | L32: =SUM(L22:L31) -> 0 | ... Z32: =SUM(Z22:Z31) -> 0
A33: Kajiado | B33: Phase 2 RFB | C33: AFD | D33: Gichagi | E33: 1.17 | F33: 1.01 | G33: 1.483 | H33: 1.01 | I33: 0 | J33: 0 | K33: 0 | L33: 0 | M33: 0 | N33: 0 | O33: 0 | P33: 0 | Q33: 63 | R33: 0 | S33: 0 | T33: 0 | U33: 1.17 | V33: 1.01
D34: Majengo | E34: 1.269 | F34: 1.209 | G34: 1.415 | H34: 1.209 | I34: 0 | J34: 0 | K34: 0 | L34: 0 | M34: 0 | N34: 0 | O34: 0 | P34: 0 | Q34: 63 | R34: 0 | S34: 0 | T34: 0 | U34: 1.2 | V34: 1.209
B35: RFQ | C35: IDA | D35: Gichagi | E35: 0 | F35: 0 | G35: 0 | H35: 0 | I35: 0 | J35: 0 | K35: 0 | L35: 0 | M35: 0 | O35: 3 | P35: 3 | Q35: 0 | R35: 0 | S35: 0 | T35: 0 | U35: 0 | V35: 0
D36: Majengo | E36: 0 | F36: 0 | G36: 0 | H36: 0 | I36: 0 | J36: 0 | K36: 0 | L36: 0 | M36: 0 | N36: 0 | O36: 3 | P36: 3 | Q36: 0 | R36: 0 | S36: 0 | T36: 0 | U36: 0 | V36: 0
D37: Total | E37: =SUM(E33:E36) -> 2.439 | F37: =SUM(F33:F36) -> 2.219 | G37: =SUM(G33:G36) -> 2.898 | H37: =SUM(H33:H36) -> 2.219 | I37: =SUM(I33:I36) -> 0 | J37: =SUM(J33:J36) -> 0 | K37: =SUM(K33:K36) -> 0 | L37: =SUM(L33:L36) -> 0 | ... Z37: =SUM(Z33:Z36) -> 0
A38: Nairobi | B38: Phase 2 RFB | C38: AFD | D38: Matopeni | E38: 1.817 | F38: 0 | G38: 0.805 | H38: 0 | I38: 0 | J38: 0 | K38: 0 | L38: 0 | M38: 0 | N38: 0 | P38: 0 | Q38: 110 | R38: 0 | S38: 0 | T38: 0 | U38: 1.81 | V38: 0
D39: Spring Valley | E39: 1.177 | F39: 0 | G39: 0.345 | H39: 0 | I39: 0 | J39: 0 | K39: 0 | L39: 0 | M39: 0 | N39: 0 | O39: 0 | P39: 0 | Q39: 66 | R39: 0 | S39: 0 | T39: 0 | U39: 1.15
D40: Mathare Fire Victims | E40: 0.248 | F40: 0 | G40: 0.106 | H40: 0 | I40: 0 | J40: 0 | K40: 0 | L40: 0 | M40: 0 | N40: 0 | O40: 0 | P40: 0 | Q40: 24 | R40: 0 | S40: 0 | T40: 0 | U40: 0.22 | V40: 0
...

Sheet PHASE 1 KILIFI + CLUSTER 2 
A1: KISIP 2 PHASE 2 CLUSTER 2 PDOs
A2: County | B2: Contract | C2: Financier | D2: Settlement | E2: Roads (km) | G2: Drainage (km) | I2: Water Supply Pipelines (km) | K2: Water Connections | M2: Toilets / Ablution | O2: High Masts Lighting | Q2: Street Lighting | S2: Vending Platforms | U2: Footpaths (km) | W2: Sewer Pipelines (km) | Y2: Sewer Connections (No)
E3: Planned | F3: Achieved | G3: Planned | H3: Achieved | I3: Planned | J3: Achieved | K3: Planned | L3: Achieved | M3: Planned | N3: Achieved | O3: Planned | P3: Achieved | Q3: Planned | R3: Achieved | S3: Planned | T3: Achieved | U3: Planned | V3: Achieved | W3: Planned | X3: Achieved | Y3: Planned | Z3: Achieved
A4: Kilifi | B4: Phase 1 Lot 1 | C4: IDA | D4: Kibaoni | E4: 0.904 | F4: 0.928 | G4: 0.904 | H4: 1.141 | I4: 0 | J4: 0 | K4: 600 | L4: 270 | M4: 0 | N4: 0 | O4: 0 | P4: 0 | Q4: 0 | R4: 10 | S4: 0 | T4: 0 | U4: 0 | V4: 0 | W4: 0 | X4: 0 | Y4: 0 | Z4: 0
D5: Kalolo | E5: 1.343 | F5: 1.404 | G5: 1.343 | H5: 1.543 | I5: 0 | J5: 0 | K5: 400 | L5: 193 | M5: 0 | N5: 0 | O5: 0 | P5: 0 | Q5: 0 | R5: 0 | S5: 0 | T5: 0 | U5: 0 | V5: 0 | W5: 0 | X5: 0 | Y5: 0 | Z5: 0
D6: Baya Magonzi | E6: 1.47 | F6: 2.172 | G6: 1.47 | H6: 1.696 | I6: 0 | J6: 0 | K6: 500 | L6: 237 | M6: 0 | N6: 0 | O6: 0 | P6: 0 | Q6: 0 | R6: 0 | S6: 0 | T6: 0 | U6: 0 | V6: 0 | W6: 0 | X6: 0 | Y6: 0 | Z6: 0
D7: Mtaani | E7: 1.306 | F7: 0.857 | G7: 1.306 | H7: 0.817 | I7: 0 | J7: 0 | K7: 0 | L7: 0 | M7: 0 | N7: 0 | O7: 0 | P7: 0 | Q7: 39 | R7: 29 | S7: 0 | T7: 0 | U7: 0 | V7: 0 | W7: 0 | X7: 0 | Y7: 0 | Z7: 0
B8: Phase 1 Lot 2 | C8: AFD | D8: Kisumu Ngogo | E8: 0.803 | G8: 0.803 | H8: 0.803 | I8: 0 | J8: 0 | K8: 0 | L8: 0 | M8: 0 | N8: 0 | O8: 0 | P8: 0 | Q8: 29 | R8: 0 | S8: 0 | T8: 0 | U8: 0 | V8: 0 | W8: 0 | X8: 0 | Y8: 0 | Z8: 0
D9: Muyeye | E9: 4.591 | F9: 4.229 | G9: 2.225 | H9: 1.41 | I9: 0 | J9: 0 | K9: 0 | L9: 0 | M9: 0 | N9: 0 | O9: 0 | P9: 0 | Q9: 0 | R9: 0 | S9: 0 | T9: 0 | U9: 0 | V9: 0 | W9: 0 | X9: 0 | Y9: 0 | Z9: 0
B10: Phase 1 Lot 3 | C10: IDA | D10: Muyeye | E10: 0 | F10: 0 | G10: 0 | H10: 0 | I10: 0 | J10: 0 | K10: 0 | L10: 0 | M10: 250 | N10: 220 | O10: 0 | P10: 0 | Q10: 0 | R10: 0 | S10: 0 | T10: 0 | U10: 0 | V10: 0 | W10: 0 | X10: 0 | Y10: 0 | Z10: 0
B11: Phase 2 RFB | C11: IDA | D11: Kibokoni M17E | E11: 2.204 | F11: 2.204 | G11: 2.372 | H11: 2.372 | I11: 0 | J11: 0 | K11: 0 | L11: 0 | M11: 0 | N11: 0 | O11: 4 | P11: 4 | Q11: 0 | R11: 0 | S11: 0 | T11: 0 | U11: 0 | V11: 0 | W11: 0 | X11: 0 | Y11: 0 | Z11: 0
B12: Phase 2 RFQ | C12: IDA | D12: Mtaani | E12: 0 | F12: 0 | G12: 0 | H12: 0 | I12: 0 | J12: 0 | K12: 0 | L12: 0 | M12: 0 | N12: 0 | O12: 0 | P12: 0 | Q12: 0 | R12: 0 | S12: =3*6 -> 18 | T12: 18 | U12: 0 | V12: 0 | W12: 0 | X12: 0 | Y12: 0 | Z12: 0
D13: Kisumu Ndogo | E13: 0 | F13: 0 | G13: 0 | H13: 0 | I13: 0 | J13: 0 | K13: 0 | L13: 0 | M13: 0 | N13: 0 | O13: 0 | P13: 0 | Q13: 0 | R13: 0 | S13: =(1+1)*6 -> 12 | T13: 12 | U13: 0 | V13: 0 | W13: 0 | X13: 0 | Y13: 0 | Z13: 0
D14: Kibaoni | E14: 0 | F14: 0 | G14: 0 | H14: 0 | I14: 0 | J14: 0 | K14: 0 | L14: 0 | M14: 0 | N14: 0 | O14: 0 | P14: 0 | Q14: 0 | R14: 0 | S14: =(2+2)*6 -> 24 | T14: =4*6 -> 24 | U14: 0 | V14: 0 | W14: 0 | X14: 0 | Y14: 0 | Z14: 0
D15: Kalolo | E15: 0 | F15: 0 | G15: 0 | H15: 0 | I15: 0 | J15: 0 | K15: 0 | L15: 0 | M15: 0 | N15: 0 | O15: 0 | P15: 0 | Q15: 0 | R15: 0 | S15: =(5-2)*6 -> 18 | T15: =3*6 -> 18 | U15: 0 | V15: 0 | W15: 0 | X15: 0 | Y15: 0 | Z15: 0
D16: Muyeye 1 | E16: 0 | F16: 0 | G16: 0 | H16: 0 | I16: 0 | J16: 0 | K16: 0 | L16: 0 | M16: 0 | N16: 0 | O16: 0 | P16: 0 | Q16: 0 | R16: 0 | S16: =(2+2)*6 -> 24 | T16: 24 | U16: 0 | V16: 0 | W16: 0 | X16: 0 | Y16: 0 | Z16: 0
D17: Total | E17: =SUM(E4:E16) -> 12.621 | F17: =SUM(F4:F16) -> 11.794 | G17: =SUM(G4:G16) -> 10.423 | H17: =SUM(H4:H16) -> 9.782 | I17: =SUM(I4:I16) -> 0 | J17: =SUM(J4:J16) -> 0 | K17: =SUM(K4:K16) -> 1500 | L17: =SUM(L4:L16) -> 700 | ... Z17: =SUM(Z4:Z16) -> 0
A18: Mombasa | B18: Phase 2 RFB | C18: IDA | D18: Likoni 203, | E18: 3.256 | F18: 3.256 | G18: ='[2]KILIFI PHASE 1 + CLUSTER 2 '!I18 -> 3.256 | H18: 0.676 | I18: 9.219 | J18: 0 | K18: 1200 | L18: 0 | M18: 0 | N18: 0 | O18: 5 | P18: 0 | Q18: 0 | R18: 0 | S18: 0 | T18: 0 | U18: 0 | V18: 0 | W18: 0 | X18: 0 | Y18: 0 | Z18: 0
D19: Kidunguni, | E19: 0.56308 | F19: 0.19012 | G19: 1.35 | H19: 0.525 | I19: 0 | J19: 0 | K19: 0 | L19: 0 | M19: 0 | N19: 0 | O19: 3 | P19: 0 | Q19: 0 | R19: 0 | S19: 0 | T19: 0 | U19: 0 | V19: 0 | W19: 0 | X19: 0 | Y19: 0 | Z19: 0
D20: Chaani, | E20: 0.61749 | F20: 0.61749 | G20: ='[2]KILIFI PHASE 1 + CLUSTER 2 '!I20 -> 0.61749 | H20: =G20 -> 0.61749 | I20: 4.886 | J20: 0 | K20: 860 | L20: 0 | M20: 0 | N20: 0 | O20: 3 | P20: 0 | Q20: 0 | R20: 0 | S20: 0 | T20: 0 | U20: 0 | V20: 0 | W20: 0 | X20: 0 | Y20: 0 | Z20: 0
D21: Misufini, | E21: 1.40935 | F21: 0 | G21: ='[2]KILIFI PHASE 1 + CLUSTER 2 '!I21 -> 1.40935 | H21: 0 | I21: 5.636 | J21: 0 | K21: 591 | L21: 0 | M21: 0 | N21: 0 | O21: 4 | P21: 0 | Q21: 0 | R21: 0 | S21: 0 | T21: 0 | U21: 0 | V21: 0 | W21: 0 | X21: 0 | Y21: 0 | Z21: 0
D22: Kisumu Ndogo | E22: 1.219 | F22: 1.115 | G22: 3.449 | H22: 1.214 | I22: 0 | J22: 0 | K22: 0 | L22: 0 | M22: 0 | N22: 0 | O22: 4 | P22: 0 | Q22: 0 | R22: 0 | S22: 0 | T22: 0 | U22: 0 | V22: 0 | W22: 0 | X22: 0 | Y22: 0 | Z22: 0
D23: Majaoni | E23: 3.879 | F23: 0.9308531 | G23: ='[2]KILIFI PHASE 1 + CLUSTER 2 '!I23 -> 3.879 | H23: 0.308 | I23: 0 | J23: 0 | K23: 0 | L23: 0 | M23: 0 | N23: 0 | O23: 3 | P23: 0 | Q23: 0 | R23: 0 | S23: 0 | T23: 0 | U23: 0 | V23: 0 | W23: 0 | X23: 0 | Y23: 0 | Z23: 0
B24: Phase 2 RFQ | C24: IDA | D24: Likoni 203, | E24: 0 | F24: 0 | G24: 0 | H24: 0 | I24: 0 | J24: 0 | K24: 0 | L24: 0 | M24: 0 | N24: 0 | O24: 0 | P24: 0 | Q24: 200 | R24: =Q24 -> 200 | S24: 0 | T24: 0 | U24: 0 | V24: 0 | W24: 0 | X24: 0 | Y24: 0 | Z24: 0
D25: Kidunguni, | E25: 0 | F25: 0 | G25: 0 | H25: 0 | I25: 0 | J25: 0 | K25: 0 | L25: 0 | M25: 0 | N25: 0 | O25: 0 | P25: 0 | Q25: 200 | R25: =Q25 -> 200 | S25: 0 | T25: 0 | U25: 0 | V25: 0 | W25: 0 | X25: 0 | Y25: 0 | Z25: 0
D26: Chaani, | E26: 0 | F26: 0 | G26: 0 | H26: 0 | I26: 0 | J26: 0 | K26: 0 | L26: 0 | M26: 0 | N26: 0 | O26: 0 | P26: 0 | Q26: 200 | R26: =Q26 -> 200 | S26: 0 | T26: 0 | U26: 0 | V26: 0 | W26: 0 | X26: 0 | Y26: 0 | Z26: 0
D27: Misufini, | E27: 0 | F27: 0 | G27: 0 | H27: 0 | I27: 0 | J27: 0 | K27: 0 | L27: 0 | M27: 0 | N27: 0 | O27: 0 | P27: 0 | Q27: 200 | R27: =Q27 -> 200 | S27: 0 | T27: 0 | U27: 0 | V27: 0 | W27: 0 | X27: 0 | Y27: 0 | Z27: 0
D28: Kisumu Ndogo | E28: 0 | F28: 0 | G28: 0 | H28: 0 | I28: 0 | J28: 0 | K28: 0 | L28: 0 | M28: 0 | N28: 0 | O28: 0 | P28: 0 | Q28: 300 | R28: =Q28 -> 300 | S28: 0 | T28: 0 | U28: 0 | W28: 0 | X28: 0 | Y28: 0 | Z28: 0
D29: Majaoni | E29: 0 | F29: 0 | G29: 0 | H29: 0 | I29: 0 | J29: 0 | K29: 0 | L29: 0 | M29: 0 | N29: 0 | O29: 0 | P29: 0 | Q29: 300 | R29: =Q29 -> 300 | S29: 0 | T29: 0 | Y29: 0
D30: Total | E30: =SUM(E18:E29) -> 10.94392 | F30: =SUM(F18:F29) -> 6.1094631 | G30: =SUM(G18:G29) -> 13.96084 | H30: =SUM(H18:H29) -> 3.34049 | I30: =SUM(I18:I29) -> 19.741 | J30: =SUM(J18:J29) -> 0 | K30: =SUM(K18:K29) -> 2651 | L30: =SUM(L18:L29) -> 0 | ... Z30: =SUM(Z18:Z29) -> 0
A31: Lamu | B31: Phase 2 Lot 1 | C31: IDA | D31: Matondoni | G31: 0.816 | H31: =G31 -> 0.816 | I31: 0 | J31: 0 | K31: 0 | L31: 0 | M31: 0 | N31: 0 | O31: 1 | P31: =O31 -> 1 | Q31: 0 | R31: 0 | S31: 0 | T31: 0 | U31: 0.812 | V31: 0.812
B32: Phase 2 Lot 2 | C32: AFD | D32: Witu | G32: =E32+0.146 -> 0.146 | H32: 0.146 | I32: 0 | J32: 0 | K32: 0 | L32: 0 | M32: 0 | N32: 0 | O32: 1 | P32: =O32 -> 1 | Q32: 0 | R32: 0 | S32: 0 | T32: 0 | U32: 0.854 | V32: 0.854
D33: Mokowe | E33: 1.033 | F33: =E33 -> 1.033 | G33: =C33+0.73+0.251+0.246 -> 1.227 | H33: =G33 -> 1.227 | I33: 0 | J33: 0 | K33: 0 | L33: 0 | M33: 0 | N33: 0 | O33: 1 | P33: =O33 -> 1 | Q33: 0 | R33: 0 | S33: 0 | T33: 0
D34: Wiyoni | G34: 1.013 | H34: =G34 -> 1.013 | I34: 0 | J34: 0 | K34: 0 | L34: 0 | M34: 0 | N34: 0 | O34: 1 | P34: =O34 -> 1 | Q34: 0 | R34: 0 | S34: 0 | T34: 0 | U34: 1.013 | V34: =U34 -> 1.013
B35: Phase 2 Lot 3 | C35: AFD | D35: Faza | G35: 1.823 | H35: =G35 -> 1.823 | I35: 0 | J35: 0 | K35: 0 | L35: 0 | M35: 0 | N35: 0 | O35: 1 | P35: 1 | Q35: 0 | R35: 0 | S35: 0 | T35: 0 | U35: 1.823 | V35: 1.823
D36: Kiunga | E36: 1.15 | F36: 0 | G36: 1.15 | H36: 0 | I36: 0 | J36: 0 | K36: 0 | L36: 0 | M36: 0 | N36: 0 | O36: 2 | P36: 0 | Q36: 0 | R36: 0 | S36: 0 | T36: 0
B37: Phase 2 RFQ | C37: IDA | D37: Faza, | E37: 0 | F37: 0 | G37: 0 | H37: 0 | I37: 0 | J37: 0 | K37: 0 | L37: 0 | M37: 0 | N37: 0 | O37: 1 | P37: 1 | Q37: 0 | R37: 0 | S37: 0 | T37: 0
D38: Matondoni | E38: 0 | F38: 0 | G38: 0 | H38: 0 | I38: 0 | J38: 0 | K38: 0 | L38: 0 | M38: 0 | N38: 0 | O38: 1 | P38: 1 | Q38: 0 | R38: 0 | S38: 0 | T38: 0
D39: Mokowe | E39: 0 | F39: 0 | G39: 0 | H39: 0 | I39: 0 | J39: 0 | K39: 0 | L39: 0 | M39: 0 | N39: 0 | O39: 1 | P39: 1 | Q39: 0 | R39: 0 | S39: 0 | T39: 0
D40: Witu | E40: 0 | F40: 0 | G40: 0 | H40: 0 | I40: 0 | J40: 0 | K40: 0 | L40: 0 | M40: 0 | N40: 0 | O40: 1 | P40: 1 | Q40: 0 | R40: 0 | S40: 0 | T40: 0
...

Sheet CLUSTER 3
A1: KISIP 2 PHASE 2 CLUSTER 3 PDOs
A2: County | B2: Contract | C2: Financier | D2: Settlement | E2: Roads (km) | G2: Drainage (km) | I2: Water Pipelines (Km) | K2: Water Connections | M2: Toilets / Ablution | O2: High Masts Lighting | Q2: Street Lighting | S2: Vending Platforms | U2: Footpaths (km) | W2: Sewer Pipelines (km) | Y2: Sewer Connections (No)
E3: Planned | F3: Achieved | G3: Planned | H3: Achieved | I3: Planned | J3: Achieved | K3: Planned | L3: Achieved | M3: Planned | N3: Achieved | O3: Planned | P3: Achieved | Q3: Planned | R3: Achieved | S3: Planned | T3: Achieved | U3: Planned | V3: Achieved | W3: Planned | X3: Achieved | Y3: Planned | Z3: Achieved
A4: Homa Bay | B4: Phase 2 Lot 1 RFB | C4: IDA | D4: 1000 Street | E4: 1.46 | F4: 0 | G4: 2.093 | H4: 0 | I4: 0 | J4: 0 | K4: 0 | L4: 0 | M4: 0 | N4: 0 | O4: 2 | P4: 0 | Q4: 62 | R4: 0 | S4: 0 | T4: 0 | U4: 0 | V4: 0 | W4: 0 | X4: 0 | Y4: 0 | Z4: 0
D5: Makongeni | E5: 2.218 | F5: 0 | G5: 3.96 | H5: 0 | I5: 0 | J5: 0 | K5: 0 | L5: 0 | M5: 0 | N5: 0 | O5: 1 | P5: 0 | Q5: 80 | R5: 0 | S5: 0 | T5: 0 | U5: 0 | V5: 0 | W5: 0 | X5: 0 | Y5: 0 | Z5: 0
D6: Shauri Yako | E6: 1.502 | F6: 1.502 | G6: =F6 -> 1.502 | H6: =G6 -> 1.502 | I6: 0 | J6: 0 | K6: 0 | L6: 0 | M6: 0 | N6: 0 | O6: 3 | P6: 0 | Q6: 56 | R6: 0 | S6: 0 | T6: 0 | U6: 0 | V6: 0 | W6: 0 | X6: 0 | Y6: 0 | Z6: 0
D7: Sofia | E7: 1.84 | F7: 1.5 | G7: 3.36 | H7: 0 | I7: 0 | J7: 0 | K7: 0 | L7: 0 | M7: 0 | N7: 0 | O7: 1 | P7: 0 | Q7: 73 | R7: 0 | S7: 0 | T7: 0 | U7: 0 | V7: 0 | W7: 0 | X7: 0 | Y7: 0 | Z7: 0
D8: Rusinga | E8: 1.915 | F8: 1.915 | G8: 3.052 | H8: 0 | I8: 0 | J8: 0 | K8: 0 | L8: 0 | M8: 0 | N8: 0 | O8: 1 | P8: 0 | Q8: 75 | R8: 0 | S8: 0 | T8: 0 | U8: 0 | V8: 0 | W8: 0 | X8: 0 | Y8: 0 | Z8: 0
D9: Nyandiwa | E9: 2.485 | F9: 2.485 | G9: 4.97 | H9: 0 | I9: 0 | J9: 0 | K9: 0 | L9: 0 | M9: 1 | N9: 0 | O9: 0 | P9: 0 | Q9: 90 | R9: 0 | S9: 1 | T9: 1 | U9: 0 | V9: 0 | W9: 0 | X9: 0 | Y9: 0 | Z9: 0
B10: Phase 2 Lot 2 RFB | C10: AFD | D10: 1000 Street | E10: 0 | F10: 0 | G10: 0 | H10: 0 | I10: 0 | J10: 0 | K10: 0 | L10: 0 | M10: 0 | N10: 0 | O10: 2 | P10: 0 | Q10: 58 | R10: 0 | S10: 0 | T10: 0 | U10: 2.093 | V10: 0 | W10: 0 | X10: 0 | Y10: 0 | Z10: 0
D11: Makongeni | E11: 0 | F11: 0 | G11: 0 | H11: 0 | I11: 0 | J11: 0 | K11: 0 | L11: 0 | M11: 0 | N11: 0 | O11: 1 | P11: 0 | Q11: 79 | R11: 0 | S11: 0 | T11: 0 | U11: 3.96 | V11: 0 | W11: 0 | X11: 0 | Y11: 0 | Z11: 0
D12: Shauri Yako | E12: 0 | F12: 0 | G12: 2.006 | H12: 0 | I12: 0 | J12: 0 | K12: 0 | L12: 0 | M12: 2 | N12: 0 | O12: 3 | P12: 0 | Q12: 56 | R12: 0 | S12: 1 | T12: 0 | U12: 4.63 | V12: 0 | W12: 0 | X12: 0 | Y12: 0 | Z12: 0
D13: Sofia | E13: 0 | F13: 0 | G13: 0 | H13: 0 | I13: 0 | J13: 0 | K13: 0 | L13: 0 | M13: 0 | N13: 0 | O13: 1 | P13: 0 | Q13: 66 | R13: 0 | S13: 0 | T13: 0 | U13: 3.36 | V13: 0 | W13: 0 | X13: 0 | Y13: 0 | Z13: 0
D14: Rusinga | E14: 0 | F14: 0 | G14: 0 | H14: 0 | I14: 0.708 | J14: 0 | K14: 0 | L14: 0 | M14: 1 | N14: 0 | O14: 2 | P14: 0 | Q14: 71 | R14: 0 | S14: 0 | T14: 0 | U14: 3.052 | V14: 0 | W14: 0 | X14: 0 | Y14: 0 | Z14: 0
D15: Nyandiwa | E15: 0 | F15: 0 | G15: 0 | H15: 0 | I15: 0 | J15: 0 | K15: 0 | L15: 0 | M15: 0 | N15: 0 | O15: 3 | P15: 0 | Q15: 90 | R15: 0 | S15: 1 | T15: 0 | U15: 4.97 | V15: 0 | W15: 0 | X15: 0 | Y15: 0 | Z15: 0
B16: Phase 2 RFQ | C16: IDA | D16: Rusinga | E16: 0 | F16: 0 | G16: 0 | H16: 0 | I16: 0 | J16: 0 | K16: 0 | L16: 0 | M16: 0 | N16: 0 | O16: 1 | P16: 1 | Q16: 0 | R16: =Q16 -> 0 | S16: 0 | T16: 0 | U16: 0 | V16: 0 | W16: 0 | X16: 0 | Y16: 0 | Z16: 0
D17: Makongeni | E17: 0 | F17: 0 | G17: 0 | H17: 0 | I17: 0 | J17: 0 | K17: 0 | L17: 0 | M17: 0 | N17: 0 | O17: 1 | P17: 1 | Q17: 0 | R17: 0 | S17: 0 | T17: 0 | U17: 0 | V17: 0 | W17: 0 | X17: 0 | Y17: 0 | Z17: 0
D18: Nyandiwa | E18: 0 | F18: 0 | G18: 0 | H18: 0 | I18: 0 | J18: 0 | K18: 0 | L18: 0 | M18: 0 | N18: 0 | O18: 1 | P18: 1 | Q18: 0 | R18: 0 | S18: 0 | T18: 0 | U18: 0 | V18: 0 | W18: 0 | X18: 0 | Y18: 0 | Z18: 0
D19: 1000 Street | E19: 0 | F19: 0 | G19: 0 | H19: 0 | I19: 0 | J19: 0 | K19: 0 | L19: 0 | M19: 0 | N19: 0 | O19: 1 | P19: 1 | Q19: 0 | R19: 0 | S19: 0 | T19: 0 | U19: 0 | V19: 0 | W19: 0 | X19: 0 | Y19: 0 | Z19: 0
D20: Total | E20: =SUM(E4:E19) -> 11.42 | F20: =SUM(F4:F19) -> 7.402 | G20: =SUM(G4:G19) -> 20.943 | H20: =SUM(H4:H19) -> 1.502 | I20: =SUM(I4:I19) -> 0.708 | J20: =SUM(J4:J19) -> 0 | K20: =SUM(K4:K19) -> 0 | L20: =SUM(L4:L19) -> 0 | ... Z20: =SUM(Z4:Z19) -> 0
A21: Nandi | B21: Phase 2 RFB | C21: IDA | D21: Mosoriot | E21: 2.4 | F21: 2.4 | G21: 3.9 | H21: 3.9 | I21: 0 | J21: 0 | K21: 0 | L21: 0 | M21: 1 | N21: 1 | O21: 2 | P21: 2 | Q21: 32 | R21: 0 | S21: 0 | T21: 0 | U21: 3.5 | V21: 3.5 | W21: 0 | X21: 0 | Y21: 0 | Z21: 0
B22: Phase 2 RFQ | C22: IDA | D22: Mosoriot | E22: 0 | F22: 0 | G22: 0 | H22: 0 | I22: 0 | J22: 0 | K22: 0 | L22: 0 | M22: 0 | N22: 0 | O22: 3 | P22: 3 | Q22: 0 | R22: =Q22 -> 0 | S22: 35 | T22: 35 | U22: 0 | V22: 0 | W22: 0 | X22: 0 | Y22: 0 | Z22: 0
D23: Total | E23: =SUM(E21:E22) -> 2.4 | F23: =SUM(F21:F22) -> 2.4 | G23: =SUM(G21:G22) -> 3.9 | H23: =SUM(H21:H22) -> 3.9 | I23: =SUM(I21:I22) -> 0 | J23: =SUM(J21:J22) -> 0 | K23: =SUM(K21:K22) -> 0 | L23: =SUM(L21:L22) -> 0 | ... Z23: =SUM(Z21:Z22) -> 0
A24: Nyamira | B24: Phase 2 RFB | C24: IDA | D24: Keroka Block 'B' | E24: 1.515 | F24: 1.515 | G24: 2.3 | H24: 1.68 | I24: 0.93 | J24: 0 | K24: 63 | L24: 0 | M24: 1 | N24: 1 | O24: 2 | P24: 0 | Q24: 0 | R24: 0 | S24: 2 | T24: 0 | U24: 2.3 | V24: 1.5 | W24: 0 | X24: 0 | Y24: 0 | Z24: 0
B25: Phase 2 RFQ | C25: IDA | D25: Keroka Block 'B' | E25: 0 | F25: 0 | G25: 0 | H25: 0 | I25: 0 | J25: 0 | K25: 0 | L25: 0 | M25: 0 | N25: 0 | O25: 0 | P25: 0 | Q25: 25 | R25: 19 | S25: 2 | T25: 0 | U25: 0 | V25: 0 | W25: 0 | X25: 0 | Y25: 0 | Z25: 0
D26: Total | E26: =SUM(E24:E25) -> 1.515 | F26: =SUM(F24:F25) -> 1.515 | G26: =SUM(G24:G25) -> 2.3 | H26: =SUM(H24:H25) -> 1.68 | I26: =SUM(I24:I25) -> 0.93 | J26: =SUM(J24:J25) -> 0 | K26: =SUM(K24:K25) -> 63 | L26: =SUM(L24:L25) -> 0 | ... Z26: =SUM(Z24:Z25) -> 0
A27: Uasin Gishu | B27: Phase 2 RFB | C27: IDA | D27: Maili Nne | E27: 3.88 | F27: 3.88 | G27: 5.918 | H27: 5.918 | I27: 0 | J27: 0 | K27: 0 | L27: 0 | M27: 0 | N27: 0 | O27: 1 | P27: 0 | Q27: 0 | R27: 0 | S27: 0 | T27: 0 | U27: 5.918 | V27: 5.918
D28: Mwanzo | E28: 3.5 | F28: 3.5 | G28: 6.7 | H28: 6.7 | I28: 0 | J28: 0 | K28: 0 | L28: 0 | M28: 1 | N28: 1 | O28: 1 | P28: 1 | Q28: 0 | R28: 0 | S28: 0 | T28: 0 | U28: 6.7 | V28: 6.7
D29: Kipkaren | E29: 2.55 | F29: 2.55 | G29: 4.451 | H29: 4.451 | I29: 0 | J29: 0 | K29: 0 | L29: 0 | M29: 2 | N29: 2 | O29: 3 | P29: 3 | Q29: 0 | S29: 0 | T29: 0 | U29: 4.451 | V29: 4.451
D30: Shauri | E30: 1.23 | F30: 1.23 | G30: 1.56 | H30: 1.56 | I30: 0 | J30: 0 | K30: 0 | L30: 0 | M30: 1 | N30: 1 | O30: 0 | P30: 0 | Q30: 30 | R30: 26 | S30: 0 | T30: 0 | U30: 1.56 | V30: 1.56
D31: Segero | E31: 0.97 | F31: 0.97 | G31: 1.532 | H31: 1.94 | I31: 0 | J31: 0 | K31: 0 | L31: 0 | M31: 0 | N31: 0 | O31: 0 | P31: 0 | Q31: 40 | R31: 25 | S31: 0 | T31: 0 | U31: 1.6 | V31: 1.6
D32: KK | E32: 0.39 | F32: 0.39 | G32: 0.776 | H32: 0.78 | I32: 0 | J32: 0 | K32: 0 | L32: 0 | M32: 1 | N32: 0 | O32: 0 | P32: 1 | Q32: 0 | R32: 14 | S32: 0 | T32: 0 | U32: 0.66 | V32: 0.66
D33: Kasarani | E33: 0.8 | F33: 0.8 | G33: 1.6 | H33: 1.6 | I33: 0 | J33: 0 | K33: 0 | L33: 0 | M33: 0 | N33: 0 | O33: 0 | P33: 0 | Q33: 0 | R33: 14 | S33: 0 | T33: 0 | U33: 1.6 | V33: 1.6
B34: Phase 2 RFQ | C34: IDA | D34: Maili Nne | E34: 0 | F34: 0 | G34: 0 | H34: 0 | I34: 0 | J34: 0 | K34: 0 | L34: 0 | M34: 0 | N34: 0 | O34: 3 | P34: 3 | Q34: 0 | R34: 0 | S34: 0 | T34: 0
D35: Mwanzo | E35: 0 | F35: 0 | G35: 0 | H35: 0 | I35: 0 | J35: 0 | K35: 0 | L35: 0 | M35: 0 | N35: 0 | O35: 2 | P35: 2 | Q35: 0 | R35: 0 | S35: 0 | T35: 0
D36: Kipkaren | E36: 0 | F36: 0 | G36: 0 | H36: 0 | I36: 0 | J36: 0 | K36: 0 | L36: 0 | M36: 0 | N36: 0 | O36: 2 | P36: 2 | Q36: 0 | R36: 0 | S36: 0 | T36: 0
D37: Total | E37: =SUM(E27:E36) -> 13.32 | F37: =SUM(F27:F36) -> 13.32 | G37: =SUM(G27:G36) -> 22.537 | H37: =SUM(H27:H36) -> 22.949 | I37: =SUM(I27:I36) -> 0 | J37: =SUM(J27:J36) -> 0 | K37: =SUM(K27:K36) -> 0 | L37: =SUM(L27:L36) -> 0 | ... V37: =SUM(V27:V36) -> 22.489
A38: TOTAL | E38: =E20+E23+E26+E37 -> 28.655 | F38: =F20+F23+F26+F37 -> 24.637 | G38: =G20+G23+G26+G37 -> 49.68 | H38: =H20+H23+H26+H37 -> 30.031 | I38: =I20+I23+I26+I37 -> 1.638 | J38: =J20+J23+J26+J37 -> 0 | K38: =K20+K23+K26+K37 -> 63 | L38: =L20+L23+L26+L37 -> 0 | ... Z38: =Z20+Z23+Z26+Z37 -> 0

Sheet CLUSTER 4
A1: KISIP 2 PHASE 2 CLUSTER 4 PDOs
A2: County | B2: Contract | C2: Financier | D2: Settlement | E2: Roads (km) | G2: Drainage (km) | I2: Water Supply Pipelines (Km) | K2: Water Connections | M2: Toilets / Ablution | O2: High Masts Lighting | Q2: Street Lighting | S2: Vending Platforms | U2: Footpaths (km) | W2: Sewer Pipelines (km) | Y2: Sewer Connections (No)
E3: Planned | F3: Achieved | G3: Planned | H3: Achieved | I3: Planned | J3: Achieved | K3: Planned | L3: Achieved | M3: Planned | N3: Achieved | O3: Planned | P3: Achieved | Q3: Planned | R3: Achieved | S3: Planned | T3: Achieved | U3: Planned | V3: Achieved | W3: Planned | X3: Achieved | Y3: Planned | Z3: Achieved
A4: Nyeri | B4: Phase 2 RFB | C4: AFD | D4: Chorongi | E4: 1 | F4: 0.99 | G4: 1.132 | H4: 0.86 | I4: 1.2 | J4: 1.2 | K4: 33 | L4: 0 | M4: 0 | N4: 0 | O4: 0 | P4: 0 | Q4: 40 | R4: 33 | S4: 0 | T4: 0 | U4: 1 | V4: 0.3 | W4: 0 | X4: 0 | Z4: 0
D5: Kiamwathi | E5: 0.42 | F5: 0.42 | G5: 0.775 | H5: 0.38 | I5: 0 | J5: 0 | K5: 0 | L5: 0 | M5: 0 | N5: 0 | O5: 0 | P5: 0 | Q5: 15 | R5: 13 | S5: 0 | T5: 0 | U5: 0.42 | W5: 0 | X5: 0 | Z5: 0
D6: Kiawara | E6: 1.3 | F6: 0.425 | G6: 2.1 | H6: 0.281 | I6: 0 | J6: 0 | K6: 0 | L6: 0 | M6: 0 | N6: 0 | O6: 1 | P6: 1 | Q6: 45 | R6: 0 | S6: 0 | T6: 0 | U6: 1.3 | W6: 1.9 | X6: 0 | Y6: 350 | Z6: 0
D7: Ihwagi | E7: 0 | F7: 0 | G7: 0 | H7: 0 | I7: 2.997 | J7: 2.45 | K7: 103 | L7: 0 | M7: 1 | N7: 0 | O7: 1 | P7: 0 | Q7: 0 | R7: 0 | S7: 0 | T7: 0 | U7: 0 | W7: 0 | X7: 0 | Z7: 0
D8: Mweiga | E8: 0.935 | F8: 0.935 | G8: 1.235 | H8: 0.8 | I8: 8.079 | J8: 7.63 | K8: 450 | L8: 0 | M8: 0 | N8: 0 | O8: 0 | P8: 0 | Q8: 34 | R8: 0 | S8: 0 | T8: 0 | U8: 0.935 | V8: 0.34 | W8: 0 | X8: 0 | Z8: 0
B9: Phase 2 RFQ | C9: IDA | D9: Chorongi | E9: 0 | F9: 0 | G9: 0 | H9: 0 | I9: 0 | J9: 0 | K9: 0 | L9: 0 | M9: 0 | N9: 0 | O9: 1 | P9: 1 | Q9: 0 | R9: 0 | S9: 0 | T9: 0 | W9: 0 | X9: 0 | Y9: 0 | Z9: 0
D10: Kiamwathi | E10: 0 | F10: 0 | G10: 0 | H10: 0 | I10: 0 | J10: 0 | K10: 0 | L10: 0 | M10: 0 | N10: 0 | O10: 1 | P10: 1 | Q10: 0 | R10: 0 | S10: 0 | T10: 0 | W10: 0 | X10: 0 | Y10: 0 | Z10: 0
D11: Kiawara | E11: 0 | F11: 0 | G11: 0 | H11: 0 | I11: 0 | J11: 0 | K11: 0 | L11: 0 | M11: 0 | N11: 0 | O11: 1 | P11: 1 | Q11: 0 | R11: 0 | S11: 0 | T11: 0 | W11: 0 | X11: 0 | Y11: 0 | Z11: 0
D12: Ihwagi | E12: 0 | F12: 0 | G12: 0 | H12: 0 | I12: 0 | J12: 0 | K12: 0 | L12: 0 | M12: 0 | N12: 0 | O12: 1 | P12: 1 | Q12: 0 | R12: 0 | S12: 0 | T12: 0 | W12: 0 | X12: 0 | Y12: 0 | Z12: 0
D13: Mweiga | E13: 0 | F13: 0 | G13: 0 | H13: 0 | I13: 0 | J13: 0 | K13: 0 | L13: 0 | M13: 0 | N13: 0 | O13: 1 | P13: 1 | Q13: 0 | R13: 0 | S13: 0 | T13: 0 | W13: 0 | X13: 0 | Y13: 0 | Z13: 0
D14: Total | E14: =SUM(E4:E13) -> 3.655 | F14: =SUM(F4:F13) -> 2.77 | G14: =SUM(G4:G13) -> 5.242 | H14: =SUM(H4:H13) -> 2.321 | I14: =SUM(I4:I13) -> 12.276 | J14: =SUM(J4:J13) -> 11.28 | K14: =SUM(K4:K13) -> 586 | L14: =SUM(L4:L13) -> 0 | ... Z14: =SUM(Z4:Z13) -> 0
A15: Meru | B15: Phase 2 RFB | C15: IDA | D15: Majengo | E15: 0.492 | F15: 0.492 | G15: =E15 -> 0.492 | H15: 0.492 | I15: 0.61 | J15: 0.45 | K15: 60 | L15: 0 | M15: 0 | N15: 0 | O15: 1 | P15: 1 | Q15: 19 | R15: 16 | S15: 0 | T15: 0 | U15: 0.45 | V15: 0.45 | W15: 0 | X15: 0 | Y15: 2 | Z15: 0
D16: Mjini | E16: 0.389 | F16: 0.389 | G16: =E16 -> 0.389 | H16: 0.389 | I16: 0.715 | J16: 0.28 | K16: 12 | L16: 0 | M16: 1 | N16: 1 | O16: 1 | P16: 1 | Q16: 15 | R16: 12 | S16: 0 | T16: 0 | U16: 0.389 | V16: 0.389 | W16: 0 | X16: 0 | Y16: 0 | Z16: 0
D17: Salama | E17: 0.29 | F17: 0.29 | G17: =E17 -> 0.29 | H17: 0.29 | I17: 0.29 | J17: 0.27 | K17: 12 | L17: 0 | M17: 0 | N17: 0 | O17: 1 | P17: 1 | Q17: 12 | R17: 12 | S17: 0 | T17: 0 | U17: 0.29 | V17: 0.29 | W17: 0 | X17: 0 | Y17: 0 | Z17: 0
B18: Phase 2 RFQ | C18: IDA | D18: Majengo | E18: 0 | F18: 0 | G18: 0 | H18: 0 | I18: 0 | J18: 0 | K18: 0 | L18: 0 | M18: 0 | N18: 0 | O18: 3 | P18: 3 | Q18: 0 | R18: =Q18 -> 0 | S18: 0 | T18: 0 | W18: 0 | X18: 0 | Y18: 0 | Z18: 0
D19: Mjini | E19: 0 | F19: 0 | G19: 0 | H19: 0 | I19: 0 | J19: 0 | K19: 0 | L19: 0 | M19: 0 | N19: 0 | O19: 2 | P19: 2 | Q19: 0 | R19: =Q19 -> 0 | S19: 0 | T19: 0 | W19: 0 | X19: 0 | Y19: 0 | Z19: 0
D20: Salama | E20: 0 | F20: 0 | G20: 0 | H20: 0 | I20: 0 | J20: 0 | K20: 0 | L20: 0 | M20: 0 | N20: 0 | O20: 1 | P20: 1 | Q20: 0 | R20: =Q20 -> 0 | S20: 0 | T20: 0 | W20: 0 | X20: 0 | Y20: 0 | Z20: 0
D21: Total | E21: =SUM(E15:E20) -> 1.171 | F21: =SUM(F15:F20) -> 1.171 | G21: =SUM(G15:G20) -> 1.171 | H21: =SUM(H15:H20) -> 1.171 | I21: =SUM(I15:I20) -> 1.615 | J21: =SUM(J15:J20) -> 1 | K21: =SUM(K15:K20) -> 84 | L21: =SUM(L15:L20) -> 0 | ... Z21: =SUM(Z15:Z20) -> 0
A22: Tharaka Nithi | B22: Phase 2 RFB | C22: IDA | D22: Kathwana | E22: 0.194 | F22: 0.194 | G22: 0.194 | H22: 0.194 | I22: 7.5 | J22: 9.35 | K22: 150 | L22: 140 | M22: 1 | N22: 1 | O22: 0 | P22: 0 | Q22: 8 | R22: 8 | S22: 0 | T22: 0 | U22: 0.194 | V22: 0.194 | W22: 0 | X22: 0 | Y22: 0 | Z22: 0
D23: Marimanti | E23: 0.773 | F23: 0.773 | G23: 0.773 | H23: 0.773 | I23: 3.3 | J23: 3.4 | K23: 150 | L23: 150 | M23: 1 | N23: 0 | O23: 0 | P23: 0 | Q23: 41 | R23: 38 | S23: 0 | T23: 0 | U23: 0.773 | V23: 0.773 | W23: 0 | X23: 0 | Y23: 0 | Z23: 0
B24: Phase 2 RFQ | C24: IDA | D24: Kathwana | E24: 0 | F24: 0 | G24: 0 | H24: 0 | I24: 0 | J24: 0 | K24: 0 | L24: 0 | M24: 0 | N24: 0 | O24: 3 | P24: 3 | Q24: 0 | R24: 0 | S24: 0 | T24: 0 | U24: 0 | V24: 0 | W24: 0 | X24: 0 | Y24: 0 | Z24: 0
D25: Marimanti | E25: 0 | F25: 0 | G25: 0 | H25: 0 | I25: 0 | J25: 0 | K25: 0 | L25: 0 | M25: 0 | N25: 0 | O25: 3 | P25: 3 | Q25: 0 | R25: 0 | S25: 0 | T25: 0 | U25: 0 | V25: 0 | W25: 0 | X25: 0 | Y25: 0 | Z25: 0
D26: Total | E26: =SUM(E22:E25) -> 0.967 | F26: =SUM(F22:F25) -> 0.967 | G26: =SUM(G22:G25) -> 0.967 | H26: =SUM(H22:H25) -> 0.967 | I26: =SUM(I22:I25) -> 10.8 | J26: =SUM(J22:J25) -> 12.75 | K26: =SUM(K22:K25) -> 300 | L26: =SUM(L22:L25) -> 290 | ... Z26: =SUM(Z22:Z25) -> 0
A27: Wajir | B27: Phase 2 RFB | C27: AFD | D27: Halane | E27: 0.92 | F27: 0.92 | G27: 0.92 | H27: 0.92 | I27: 0 | J27: 0 | K27: 0 | L27: 0 | M27: 0 | N27: 0 | O27: 1 | P27: 1 | Q27: 46 | R27: 33 | S27: 0 | T27: 0 | U27: 0.92 | V27: 0.92 | W27: 0 | X27: 0 | Y27: 0 | Z27: 0
D28: Wagberi | E28: 1.565 | F28: 1.565 | G28: 1.565 | H28: 1.565 | I28: 0 | J28: 0 | K28: 0 | L28: 0 | M28: 0 | N28: 0 | O28: 1 | P28: 1 | Q28: 78 | R28: 56 | S28: 0 | T28: 0 | U28: 1.565 | V28: 1.565 | W28: 0 | X28: 0 | Y28: 0 | Z28: 0
D29: Hodhan | E29: 1.354 | F29: 1.54 | G29: 1.354 | H29: 1.16 | I29: 0 | J29: 0 | K29: 0 | L29: 0 | M29: 0 | N29: 0 | O29: 0 | P29: 0 | Q29: 68 | R29: 53 | S29: 0 | T29: 0 | U29: 1.354 | V29: 1.16 | W29: 0 | X29: 0 | Y29: 0 | Z29: 0
D30: Jogoo | E30: 1.4 | F30: 1.4 | G30: 1.4 | H30: 1.12 | I30: 0 | J30: 0 | K30: 0 | L30: 0 | M30: 0 | N30: 0 | O30: 0 | P30: 0 | Q30: 64 | R30: 52 | S30: 0 | T30: 0 | U30: 1.4 | V30: 1.4 | W30: 0 | X30: 0 | Y30: 0 | Z30: 0
D31: Barwaqo | E31: 1.96 | F31: 2.02 | G31: 1.96 | H31: 2.02 | I31: 0 | J31: 0 | K31: 0 | L31: 0 | M31: 0 | N31: 0 | O31: 0 | P31: 0 | Q31: 98 | R31: 90 | S31: 0 | T31: 0 | U31: 1.96 | V31: 2.02 | W31: 0 | X31: 0 | Y31: 0 | Z31: 0
D32: Shalletey | E32: 1.2 | F32: 1.28 | G32: 1.2 | H32: 1.28 | I32: 0 | J32: 0 | K32: 0 | L32: 0 | M32: 0 | N32: 0 | O32: 0 | P32: 0 | Q32: 66 | R32: 41 | S32: 0 | T32: 0 | U32: 1.2 | V32: 1.2 | W32: 0 | X32: 0 | Y32: 0 | Z32: 0
B33: Phase 2 RFQ | C33: IDA | D33: Halane | E33: 0 | F33: 0 | G33: 0 | H33: 0 | I33: 0 | J33: 0 | K33: 0 | L33: 0 | M33: 0 | N33: 0 | O33: 0 | P33: 0 | Q33: 0 | R33: 0 | S33: 0 | T33: 0 | W33: 0 | X33: 0 | Y33: 0 | Z33: 0
D34: Wagberi | E34: 0 | F34: 0 | G34: 0 | H34: 0 | I34: 0 | J34: 0 | K34: 0 | L34: 0 | M34: 0 | N34: 0 | O34: 0 | P34: 0 | Q34: 0 | R34: 0 | S34: 0 | T34: 0 | W34: 0 | X34: 0 | Y34: 0 | Z34: 0
D35: Hodhan | E35: 0 | F35: 0 | G35: 0 | H35: 0 | I35: 0 | J35: 0 | K35: 0 | L35: 0 | M35: 0 | N35: 0 | O35: 0 | P35: 0 | Q35: 0 | R35: 0 | S35: 0 | T35: 0 | W35: 0 | X35: 0 | Y35: 0 | Z35: 0
D36: Jogoo | E36: 0 | F36: 0 | G36: 0 | H36: 0 | I36: 0 | J36: 0 | K36: 0 | L36: 0 | M36: 0 | N36: 0 | O36: 1 | P36: 1 | Q36: 0 | R36: 0 | S36: 0 | T36: 0 | W36: 0 | X36: 0 | Y36: 0 | Z36: 0
D37: Barwaqo | E37: 0 | F37: 0 | G37: 0 | H37: 0 | I37: 0 | J37: 0 | K37: 0 | L37: 0 | M37: 0 | N37: 0 | O37: 1 | P37: 1 | Q37: 0 | R37: 0 | S37: 0 | T37: 0 | W37: 0 | X37: 0 | Y37: 0 | Z37: 0
D38: Shalletey | E38: 0 | F38: 0 | G38: 0 | H38: 0 | I38: 0 | J38: 0 | K38: 0 | L38: 0 | M38: 0 | N38: 0 | O38: 1 | P38: 1 | Q38: 0 | R38: 0 | S38: 0 | T38: 0 | W38: 0 | X38: 0 | Y38: 0 | Z38: 0
D39: Total | E39: =SUM(E27:E33) -> 8.399 | F39: =SUM(F27:F33) -> 8.725 | G39: =SUM(G27:G33) -> 8.399 | H39: =SUM(H27:H33) -> 8.065 | I39: =SUM(I27:I38) -> 0 | J39: =SUM(J27:J33) -> 0 | K39: =SUM(K27:K38) -> 0 | L39: =SUM(L27:L33) -> 0 | M39: =SUM(M27:M38) -> 0 | N39: =SUM(N27:N33) -> 0 | O39: =SUM(O27:O38) -> 5 | P39: =SUM(P27:P38) -> 5 | Q39: =SUM(Q27:Q33) -> 420 | R39: =SUM(R27:R33) -> 325 | S39: =SUM(S27:S33) -> 0 | T39: =SUM(T27:T33) -> 0 | U39: =SUM(U27:U33) -> 8.399 | V39: =SUM(V27:V33) -> 8.265 | W39: =SUM(W27:W33) -> 0 | X39: =SUM(X27:X33) -> 0 | ... Z39: =SUM(Z27:Z33) -> 0
A40: TOTAL | E40: =SUM(E14,E21,E26,E39) -> 14.192 | F40: =SUM(F14,F21,F26,F39) -> 13.633 | G40: =SUM(G14,G21,G26,G39) -> 15.779 | H40: =SUM(H14,H21,H26,H39) -> 12.524 | I40: =SUM(I14,I21,I26,I39) -> 24.691 | J40: =SUM(J14,J21,J26,J39) -> 25.03 | K40: =SUM(K14,K21,K26,K39) -> 970 | L40: =SUM(L14,L21,L26,L39) -> 290 | ... Z40: =SUM(Z14,Z21,Z26,Z39) -> 0

Sheet CLUSTER 5
A1: KISIP 2 PHASE 2 CLUSTER 5 PDOs
A2: County | B2: Contract | C2: Financier | D2: Settlement | E2: Roads (km) | G2: Drainage (km) | I2: Water supply Pipelines (Km) | K2: Water Connections | M2: Toilets / Ablution | O2: High Masts Lighting | Q2: Street Lighting | S2: Vending Platforms | U2: Footpaths (km) | W2: Sewer Pipelines (km) | Y2: Sewer Connections (No)
E3: Planned | F3: Achieved | G3: Planned | H3: Achieved | I3: Planned | J3: Achieved | K3: Planned | L3: Achieved | M3: Planned | N3: Achieved | O3: Planned | P3: Achieved | Q3: Planned | R3: Achieved | S3: Planned | T3: Achieved | U3: Planned | V3: Achieved | W3: Planned | X3: Achieved | Y3: Planned | Z3: Achieved
A4: Trans Nzoia | B4: Phase 2 Lot 1 | C4: IDA | D4: Matisi | E4: 2.973 | F4: 2.973 | G4: 2.973 | H4: 2.973 | I4: 2.998 | J4: 2.998 | K4: 100 | L4: 82 | O4: 1 | P4: 1 | Q4: 20 | R4: 20 | U4: 2.95 | V4: 2.95 | W4: 0 | X4: 0 | Y4: 0 | Z4: 0
B5: Phase 2 RFQ | C5: AFD | D5: Matisi | O5: 1 | P5: 1 | V5: 0 | W5: 0 | X5: 0 | Y5: 0 | Z5: 0
B6: Phase 2 Lot 1 | C6: IDA | D6: Mitume | E6: 2.761 | F6: 2.761 | G6: 2.761 | H6: 2.761 | I6: 2.332 | J6: 2.332 | K6: 100 | L6: 68 | O6: 1 | P6: 1 | Q6: 25 | R6: 25 | U6: 2.76 | V6: 2.76 | W6: 0 | X6: 0 | Y6: 0 | Z6: 0
B7: Phase 2 RFQ | C7: AFD | D7: Mitume | O7: 1 | P7: 1 | V7: 0 | W7: 0 | X7: 0 | Y7: 0 | Z7: 0
B8: Phase 2 Lot 1 | C8: IDA | D8: Tuwani | E8: 2.204 | F8: 2.204 | G8: 2.204 | H8: 2.204 | I8: 1.76 | J8: 1.76 | K8: 100 | L8: 65 | Q8: 20 | R8: 20 | U8: 2.204 | V8: 2.204 | W8: 0 | X8: 0 | Y8: 0 | Z8: 0
B9: Phase 2 RFQ | C9: AFD | D9: Tuwani | O9: 1 | P9: 1 | V9: 0 | W9: 0 | X9: 0 | Y9: 0 | Z9: 0
B10: Phase 2 Lot 1 | C10: IDA | D10: Shanti | E10: 2.023 | F10: 2.023 | G10: 2.023 | H10: 2.023 | I10: 1.962 | J10: 1.962 | K10: 100 | L10: 65 | O10: 1 | P10: 1 | Q10: 20 | R10: 20 | U10: 1.95 | V10: 1.95 | W10: 0 | X10: 0 | Y10: 0 | Z10: 0
B11: Phase 2 RFQ | C11: AFD | D11: Shanti | O11: 1 | P11: 1 | V11: 0 | W11: 0 | X11: 0 | Y11: 0 | Z11: 0
B12: Phase 2 Lot 1 | C12: IDA | D12: Kipsongo | M12: 1 | N12: 1 | P12: 0 | U12: 0 | V12: 0 | W12: 0 | X12: 0 | Y12: 0 | Z12: 0
B13: Phase 2 RFQ | C13: AFD | D13: Kipsongo | O13: 1 | P13: 1 | V13: 0 | W13: 0 | X13: 0 | Y13: 0 | Z13: 0
D14: Total | E14: =SUM(E4:E13) -> 9.961 | F14: =SUM(F4:F13) -> 9.961 | G14: =SUM(G4:G13) -> 9.961 | H14: =SUM(H4:H13) -> 9.961 | I14: =SUM(I4:I13) -> 9.052 | J14: =SUM(J4:J13) -> 9.052 | K14: =SUM(K4:K13) -> 400 | L14: =SUM(L4:L13) -> 280 | ... Z14: =SUM(Z4:Z13) -> 0
A15: Bungoma | B15: Phase 2 Lot 1 | C15: IDA | D15: Mjini | E15: 1.588 | F15: 0 | G15: 1.588 | H15: 1.248 | I15: 1.518 | J15: 1.518 | K15: 136 | L15: 0 | M15: 0 | N15: 0 | O15: 1 | P15: 1 | Q15: 9 | R15: 0 | S15: 0 | T15: 0 | U15: 1.588 | V15: 0 | W15: 1.1 | X15: 0 | Y15: 0 | Z15: 0
B16: Phase 2 RFQ | C16: AFD | D16: Mjini | O16: 2 | P16: 2 | U16: 0 | V16: 0 | W16: 0 | X16: 0 | Y16: 0 | Z16: 0
B17: Phase 2 Lot 1 | C17: IDA | D17: Landi Matope | E17: 2.246 | F17: 0 | G17: 2.246 | H17: 2.246 | I17: 0 | J17: 0 | K17: 0 | L17: 0 | M17: 0 | N17: 0 | Q17: 22 | R17: 0 | U17: 2.246 | V17: 0 | W17: 0 | X17: 0 | Y17: 0 | Z17: 0
B18: Phase 2 RFQ | C18: AFD | D18: Landi Matope | O18: 3 | P18: 3 | U18: 0 | V18: 0 | W18: 0 | X18: 0 | Y18: 0 | Z18: 0
D19: Total | E19: =SUM(E15:E18) -> 3.834 | F19: =SUM(F15:F18) -> 0 | G19: =SUM(G15:G18) -> 3.834 | H19: =SUM(H15:H18) -> 3.494 | I19: =SUM(I15:I18) -> 1.518 | J19: =SUM(J15:J18) -> 1.518 | K19: =SUM(K15:K18) -> 136 | L19: =SUM(L15:L18) -> 0 | ... Z19: =SUM(Z15:Z18) -> 0
A20: Elgeyo Marakwet | B20: Phase 2 Lot 1 | C20: IDA | D20: Cheptongei | E20: 2.084 | F20: 2.084 | G20: 2.211 | H20: 2.211 | O20: 1 | P20: 1 | Q20: 12 | R20: 12 | U20: 0.65 | V20: 0.65 | W20: 0 | X20: 0 | Y20: 0 | Z20: 0
B21: Phase 2 RFQ | C21: AFD | D21: Cheptongei | O21: 1 | P21: 1 | S21: 36 | T21: 36 | U21: 0 | V21: 0 | W21: 0 | X21: 0 | Y21: 0 | Z21: 0
B22: Phase 2 Lot 1 | C22: IDA | D22: Chebiemit | E22: 1.461 | F22: 1.461 | G22: 1.461 | H22: 1.461 | O22: 1 | P22: 1 | Q22: 25 | R22: 25 | U22: 0.47 | V22: 0.47 | W22: 0 | X22: 0 | Y22: 0 | Z22: 0
B23: Phase 2 RFQ | C23: AFD | D23: Chebiemit | O23: 1 | P23: 1 | S23: 36 | T23: 36 | U23: 0 | V23: 0 | W23: 0 | X23: 0 | Y23: 0 | Z23: 0
D24: Total | E24: =SUM(E20:E23) -> 3.545 | F24: =SUM(F20:F23) -> 3.545 | G24: =SUM(G20:G23) -> 3.672 | H24: =SUM(H20:H23) -> 3.672 | I24: =SUM(I20:I23) -> 0 | J24: =SUM(J20:J23) -> 0 | K24: =SUM(K20:K23) -> 0 | L24: =SUM(L20:L23) -> 0 | ... Z24: =SUM(Z20:Z23) -> 0
A25: TOTAL | E25: =SUM(E14,E19,E24) -> 17.34 | F25: =SUM(F14,F19,F24) -> 13.506 | G25: =SUM(G14,G19,G24) -> 17.467 | H25: =SUM(H14,H19,H24) -> 17.127 | I25: =SUM(I14,I19,I24) -> 10.57 | J25: =SUM(J14,J19,J24) -> 10.57 | K25: =SUM(K14,K19,K24) -> 536 | L25: =SUM(L14,L19,L24) -> 280 | ... Z25: =SUM(Z14,Z19,Z24) -> 0
